Workbook

Sheet Mapping
A1: nace_level | B1: nace_code | C1: nace_label_original | D1: nace_code_agg | E1: nace_label_agg | F1: mapped_uniq_ets_cnt | G1: cleaning_action | H1: ets_activity_code | I1: ets_activity_name_original | J1: ets_activity_code_agg | K1: ets_activity_name_agg | L1: mapped_uniq_nace_cnt | M1: mapping_quality | N1: exclusivity_note
A2: =_xlfn.XLOOKUP(C2,'NACE Rev. All Levels'!$C:$C,'NACE Rev. All Levels'!A:A) -> 3 | B2: =_xlfn.XLOOKUP(C2,'NACE Rev. All Levels'!$C:$C,'NACE Rev. All Levels'!B:B) -> 171 | C2: Manufacture of pulp, paper and paperboard | D2: {=_xlfn.TEXTJOIN(", ",TRUE,_xlfn.UNIQUE(_xlfn._xlws.FILTER(B:B,E:E=E2)))} -> 171 | E2: Manufacture of pulp, paper and paperboard | F2: {=IF(I2="",0,COUNTA(_xlfn.UNIQUE(_xlfn._xlws.FILTER(K:K,E:E=E2))))} -> 1 | G2: Combine ETS activities | H2: =_xlfn.XLOOKUP(I2,'ETS activities'!B:B,'ETS activities'!A:A) -> 35 | I2: Production of pulp | J2: {=_xlfn.TEXTJOIN(", ",TRUE,_xlfn.UNIQUE(_xlfn._xlws.FILTER(H:H,K:K=K2)))} -> 35, 36 | K2: Production of pulp, paper and cardboard | L2: {=COUNTA(_xlfn.UNIQUE(_xlfn._xlws.FILTER(E:E,K:K=K2)))} -> 1 | M2: broad combined | N2: Same NACE level-3 code intentionally reused; aggregate ETS rows to this NACE code before regression
A3: =_xlfn.XLOOKUP(C3,'NACE Rev. All Levels'!$C:$C,'NACE Rev. All Levels'!A:A) -> 3 | B3: =_xlfn.XLOOKUP(C3,'NACE Rev. All Levels'!$C:$C,'NACE Rev. All Levels'!B:B) -> 171 | C3: Manufacture of pulp, paper and paperboard | D3: {=_xlfn.TEXTJOIN(", ",TRUE,_xlfn.UNIQUE(_xlfn._xlws.FILTER(B:B,E:E=E3)))} -> 171 | E3: Manufacture of pulp, paper and paperboard | F3: {=IF(I3="",0,COUNTA(_xlfn.UNIQUE(_xlfn._xlws.FILTER(K:K,E:E=E3))))} -> 1 | G3: Combine ETS activities | H3: =_xlfn.XLOOKUP(I3,'ETS activities'!B:B,'ETS activities'!A:A) -> 36 | I3: Production of paper or cardboard | J3: {=_xlfn.TEXTJOIN(", ",TRUE,_xlfn.UNIQUE(_xlfn._xlws.FILTER(H:H,K:K=K3)))} -> 35, 36 | K3: Production of pulp, paper and cardboard | L3: {=COUNTA(_xlfn.UNIQUE(_xlfn._xlws.FILTER(E:E,K:K=K3)))} -> 1 | M3: broad combined | N3: Same NACE level-3 code intentionally reused; aggregate ETS rows to this NACE code before regression
A4: =_xlfn.XLOOKUP(C4,'NACE Rev. All Levels'!$C:$C,'NACE Rev. All Levels'!A:A) -> 3 | B4: =_xlfn.XLOOKUP(C4,'NACE Rev. All Levels'!$C:$C,'NACE Rev. All Levels'!B:B) -> 191 | C4: Manufacture of coke oven products | D4: {=_xlfn.TEXTJOIN(", ",TRUE,_xlfn.UNIQUE(_xlfn._xlws.FILTER(B:B,E:E=E4)))} -> 191 | E4: Manufacture of coke oven products | F4: {=IF(I4="",0,COUNTA(_xlfn.UNIQUE(_xlfn._xlws.FILTER(K:K,E:E=E4))))} -> 1 | G4: None | H4: =_xlfn.XLOOKUP(I4,'ETS activities'!B:B,'ETS activities'!A:A) -> 22 | I4: Production of coke | J4: {=_xlfn.TEXTJOIN(", ",TRUE,_xlfn.UNIQUE(_xlfn._xlws.FILTER(H:H,K:K=K4)))} -> 22 | K4: Production of coke | L4: {=COUNTA(_xlfn.UNIQUE(_xlfn._xlws.FILTER(E:E,K:K=K4)))} -> 1 | M4: exact | N4: Exclusive NACE level-1-3 code; no selected parent/child overlap
A5: =_xlfn.XLOOKUP(C5,'NACE Rev. All Levels'!$C:$C,'NACE Rev. All Levels'!A:A) -> 3 | B5: =_xlfn.XLOOKUP(C5,'NACE Rev. All Levels'!$C:$C,'NACE Rev. All Levels'!B:B) -> 192 | C5: Manufacture of refined petroleum products | D5: {=_xlfn.TEXTJOIN(", ",TRUE,_xlfn.UNIQUE(_xlfn._xlws.FILTER(B:B,E:E=E5)))} -> 192 | E5: Manufacture of refined petroleum products | F5: {=IF(I5="",0,COUNTA(_xlfn.UNIQUE(_xlfn._xlws.FILTER(K:K,E:E=E5))))} -> 1 | G5: None | H5: =_xlfn.XLOOKUP(I5,'ETS activities'!B:B,'ETS activities'!A:A) -> 21 | I5: Refining of mineral oil | J5: {=_xlfn.TEXTJOIN(", ",TRUE,_xlfn.UNIQUE(_xlfn._xlws.FILTER(H:H,K:K=K5)))} -> 21 | K5: Refining of mineral oil | L5: {=COUNTA(_xlfn.UNIQUE(_xlfn._xlws.FILTER(E:E,K:K=K5)))} -> 1 | M5: exact | N5: Exclusive NACE level-1-3 code; no selected parent/child overlap
A6: =_xlfn.XLOOKUP(C6,'NACE Rev. All Levels'!$C:$C,'NACE Rev. All Levels'!A:A) -> 3 | B6: =_xlfn.XLOOKUP(C6,'NACE Rev. All Levels'!$C:$C,'NACE Rev. All Levels'!B:B) -> 201 | C6: Manufacture of basic chemicals, fertilisers and nitrogen compounds, plastics and synthetic rubber in primary forms | D6: {=_xlfn.TEXTJOIN(", ",TRUE,_xlfn.UNIQUE(_xlfn._xlws.FILTER(B:B,E:E=E6)))} -> 201 | E6: Manufacture of basic chemicals, fertilisers and nitrogen compounds, plastics and synthetic rubber in primary forms | F6: {=IF(I6="",0,COUNTA(_xlfn.UNIQUE(_xlfn._xlws.FILTER(K:K,E:E=E6))))} -> 1 | G6: Combine ETS activities | H6: =_xlfn.XLOOKUP(I6,'ETS activities'!B:B,'ETS activities'!A:A) -> 37 | I6: Production of carbon black | J6: {=_xlfn.TEXTJOIN(", ",TRUE,_xlfn.UNIQUE(_xlfn._xlws.FILTER(H:H,K:K=K6)))} -> 37, 38, 39, 40, 41, 42, 43, 44 | K6: Production of carbon black, nitric acid, adipic acid, glyoxal and glyoxylic acid, ammonia, bulk chemicals, hydrogen and synthesis gas, soda ash and sodium bicarbonate | L6: {=COUNTA(_xlfn.UNIQUE(_xlfn._xlws.FILTER(E:E,K:K=K6)))} -> 1 | M6: broad combined | N6: Same NACE level-3 code intentionally reused; aggregate ETS rows to this NACE code before regression
A7: =_xlfn.XLOOKUP(C7,'NACE Rev. All Levels'!$C:$C,'NACE Rev. All Levels'!A:A) -> 3 | B7: =_xlfn.XLOOKUP(C7,'NACE Rev. All Levels'!$C:$C,'NACE Rev. All Levels'!B:B) -> 201 | C7: Manufacture of basic chemicals, fertilisers and nitrogen compounds, plastics and synthetic rubber in primary forms | D7: {=_xlfn.TEXTJOIN(", ",TRUE,_xlfn.UNIQUE(_xlfn._xlws.FILTER(B:B,E:E=E7)))} -> 201 | E7: Manufacture of basic chemicals, fertilisers and nitrogen compounds, plastics and synthetic rubber in primary forms | F7: {=IF(I7="",0,COUNTA(_xlfn.UNIQUE(_xlfn._xlws.FILTER(K:K,E:E=E7))))} -> 1 | G7: Combine ETS activities | H7: =_xlfn.XLOOKUP(I7,'ETS activities'!B:B,'ETS activities'!A:A) -> 38 | I7: Production of nitric acid | J7: {=_xlfn.TEXTJOIN(", ",TRUE,_xlfn.UNIQUE(_xlfn._xlws.FILTER(H:H,K:K=K7)))} -> 37, 38, 39, 40, 41, 42, 43, 44 | K7: Production of carbon black, nitric acid, adipic acid, glyoxal and glyoxylic acid, ammonia, bulk chemicals, hydrogen and synthesis gas, soda ash and sodium bicarbonate | L7: {=COUNTA(_xlfn.UNIQUE(_xlfn._xlws.FILTER(E:E,K:K=K7)))} -> 1 | M7: broad combined | N7: Same NACE level-3 code intentionally reused; aggregate ETS rows to this NACE code before regression
A8: =_xlfn.XLOOKUP(C8,'NACE Rev. All Levels'!$C:$C,'NACE Rev. All Levels'!A:A) -> 3 | B8: =_xlfn.XLOOKUP(C8,'NACE Rev. All Levels'!$C:$C,'NACE Rev. All Levels'!B:B) -> 201 | C8: Manufacture of basic chemicals, fertilisers and nitrogen compounds, plastics and synthetic rubber in primary forms | D8: {=_xlfn.TEXTJOIN(", ",TRUE,_xlfn.UNIQUE(_xlfn._xlws.FILTER(B:B,E:E=E8)))} -> 201 | E8: Manufacture of basic chemicals, fertilisers and nitrogen compounds, plastics and synthetic rubber in primary forms | F8: {=IF(I8="",0,COUNTA(_xlfn.UNIQUE(_xlfn._xlws.FILTER(K:K,E:E=E8))))} -> 1 | G8: Combine ETS activities | H8: =_xlfn.XLOOKUP(I8,'ETS activities'!B:B,'ETS activities'!A:A) -> 39 | I8: Production of adipic acid | J8: {=_xlfn.TEXTJOIN(", ",TRUE,_xlfn.UNIQUE(_xlfn._xlws.FILTER(H:H,K:K=K8)))} -> 37, 38, 39, 40, 41, 42, 43, 44 | K8: Production of carbon black, nitric acid, adipic acid, glyoxal and glyoxylic acid, ammonia, bulk chemicals, hydrogen and synthesis gas, soda ash and sodium bicarbonate | L8: {=COUNTA(_xlfn.UNIQUE(_xlfn._xlws.FILTER(E:E,K:K=K8)))} -> 1 | M8: broad combined | N8: Same NACE level-3 code intentionally reused; aggregate ETS rows to this NACE code before regression
A9: =_xlfn.XLOOKUP(C9,'NACE Rev. All Levels'!$C:$C,'NACE Rev. All Levels'!A:A) -> 3 | B9: =_xlfn.XLOOKUP(C9,'NACE Rev. All Levels'!$C:$C,'NACE Rev. All Levels'!B:B) -> 201 | C9: Manufacture of basic chemicals, fertilisers and nitrogen compounds, plastics and synthetic rubber in primary forms | D9: {=_xlfn.TEXTJOIN(", ",TRUE,_xlfn.UNIQUE(_xlfn._xlws.FILTER(B:B,E:E=E9)))} -> 201 | E9: Manufacture of basic chemicals, fertilisers and nitrogen compounds, plastics and synthetic rubber in primary forms | F9: {=IF(I9="",0,COUNTA(_xlfn.UNIQUE(_xlfn._xlws.FILTER(K:K,E:E=E9))))} -> 1 | G9: Combine ETS activities | H9: =_xlfn.XLOOKUP(I9,'ETS activities'!B:B,'ETS activities'!A:A) -> 40 | I9: Production of glyoxal and glyoxylic acid | J9: {=_xlfn.TEXTJOIN(", ",TRUE,_xlfn.UNIQUE(_xlfn._xlws.FILTER(H:H,K:K=K9)))} -> 37, 38, 39, 40, 41, 42, 43, 44 | K9: Production of carbon black, nitric acid, adipic acid, glyoxal and glyoxylic acid, ammonia, bulk chemicals, hydrogen and synthesis gas, soda ash and sodium bicarbonate | L9: {=COUNTA(_xlfn.UNIQUE(_xlfn._xlws.FILTER(E:E,K:K=K9)))} -> 1 | M9: broad combined | N9: Same NACE level-3 code intentionally reused; aggregate ETS rows to this NACE code before regression
A10: =_xlfn.XLOOKUP(C10,'NACE Rev. All Levels'!$C:$C,'NACE Rev. All Levels'!A:A) -> 3 | B10: =_xlfn.XLOOKUP(C10,'NACE Rev. All Levels'!$C:$C,'NACE Rev. All Levels'!B:B) -> 201 | C10: Manufacture of basic chemicals, fertilisers and nitrogen compounds, plastics and synthetic rubber in primary forms | D10: {=_xlfn.TEXTJOIN(", ",TRUE,_xlfn.UNIQUE(_xlfn._xlws.FILTER(B:B,E:E=E10)))} -> 201 | E10: Manufacture of basic chemicals, fertilisers and nitrogen compounds, plastics and synthetic rubber in primary forms | F10: {=IF(I10="",0,COUNTA(_xlfn.UNIQUE(_xlfn._xlws.FILTER(K:K,E:E=E10))))} -> 1 | G10: Combine ETS activities | H10: =_xlfn.XLOOKUP(I10,'ETS activities'!B:B,'ETS activities'!A:A) -> 41 | I10: Production of ammonia | J10: {=_xlfn.TEXTJOIN(", ",TRUE,_xlfn.UNIQUE(_xlfn._xlws.FILTER(H:H,K:K=K10)))} -> 37, 38, 39, 40, 41, 42, 43, 44 | K10: Production of carbon black, nitric acid, adipic acid, glyoxal and glyoxylic acid, ammonia, bulk chemicals, hydrogen and synthesis gas, soda ash and sodium bicarbonate | L10: {=COUNTA(_xlfn.UNIQUE(_xlfn._xlws.FILTER(E:E,K:K=K10)))} -> 1 | M10: broad combined | N10: Same NACE level-3 code intentionally reused; aggregate ETS rows to this NACE code before regression
A11: =_xlfn.XLOOKUP(C11,'NACE Rev. All Levels'!$C:$C,'NACE Rev. All Levels'!A:A) -> 3 | B11: =_xlfn.XLOOKUP(C11,'NACE Rev. All Levels'!$C:$C,'NACE Rev. All Levels'!B:B) -> 201 | C11: Manufacture of basic chemicals, fertilisers and nitrogen compounds, plastics and synthetic rubber in primary forms | D11: {=_xlfn.TEXTJOIN(", ",TRUE,_xlfn.UNIQUE(_xlfn._xlws.FILTER(B:B,E:E=E11)))} -> 201 | E11: Manufacture of basic chemicals, fertilisers and nitrogen compounds, plastics and synthetic rubber in primary forms | F11: {=IF(I11="",0,COUNTA(_xlfn.UNIQUE(_xlfn._xlws.FILTER(K:K,E:E=E11))))} -> 1 | G11: Combine ETS activities | H11: =_xlfn.XLOOKUP(I11,'ETS activities'!B:B,'ETS activities'!A:A) -> 42 | I11: Production of bulk chemicals | J11: {=_xlfn.TEXTJOIN(", ",TRUE,_xlfn.UNIQUE(_xlfn._xlws.FILTER(H:H,K:K=K11)))} -> 37, 38, 39, 40, 41, 42, 43, 44 | K11: Production of carbon black, nitric acid, adipic acid, glyoxal and glyoxylic acid, ammonia, bulk chemicals, hydrogen and synthesis gas, soda ash and sodium bicarbonate | L11: {=COUNTA(_xlfn.UNIQUE(_xlfn._xlws.FILTER(E:E,K:K=K11)))} -> 1 | M11: broad combined | N11: Same NACE level-3 code intentionally reused; aggregate ETS rows to this NACE code before regression
A12: =_xlfn.XLOOKUP(C12,'NACE Rev. All Levels'!$C:$C,'NACE Rev. All Levels'!A:A) -> 3 | B12: =_xlfn.XLOOKUP(C12,'NACE Rev. All Levels'!$C:$C,'NACE Rev. All Levels'!B:B) -> 201 | C12: Manufacture of basic chemicals, fertilisers and nitrogen compounds, plastics and synthetic rubber in primary forms | D12: {=_xlfn.TEXTJOIN(", ",TRUE,_xlfn.UNIQUE(_xlfn._xlws.FILTER(B:B,E:E=E12)))} -> 201 | E12: Manufacture of basic chemicals, fertilisers and nitrogen compounds, plastics and synthetic rubber in primary forms | F12: {=IF(I12="",0,COUNTA(_xlfn.UNIQUE(_xlfn._xlws.FILTER(K:K,E:E=E12))))} -> 1 | G12: Combine ETS activities | H12: =_xlfn.XLOOKUP(I12,'ETS activities'!B:B,'ETS activities'!A:A) -> 43 | I12: Production of hydrogen and synthesis gas | J12: {=_xlfn.TEXTJOIN(", ",TRUE,_xlfn.UNIQUE(_xlfn._xlws.FILTER(H:H,K:K=K12)))} -> 37, 38, 39, 40, 41, 42, 43, 44 | K12: Production of carbon black, nitric acid, adipic acid, glyoxal and glyoxylic acid, ammonia, bulk chemicals, hydrogen and synthesis gas, soda ash and sodium bicarbonate | L12: {=COUNTA(_xlfn.UNIQUE(_xlfn._xlws.FILTER(E:E,K:K=K12)))} -> 1 | M12: broad combined | N12: Same NACE level-3 code intentionally reused; aggregate ETS rows to this NACE code before regression
A13: =_xlfn.XLOOKUP(C13,'NACE Rev. All Levels'!$C:$C,'NACE Rev. All Levels'!A:A) -> 3 | B13: =_xlfn.XLOOKUP(C13,'NACE Rev. All Levels'!$C:$C,'NACE Rev. All Levels'!B:B) -> 201 | C13: Manufacture of basic chemicals, fertilisers and nitrogen compounds, plastics and synthetic rubber in primary forms | D13: {=_xlfn.TEXTJOIN(", ",TRUE,_xlfn.UNIQUE(_xlfn._xlws.FILTER(B:B,E:E=E13)))} -> 201 | E13: Manufacture of basic chemicals, fertilisers and nitrogen compounds, plastics and synthetic rubber in primary forms | F13: {=IF(I13="",0,COUNTA(_xlfn.UNIQUE(_xlfn._xlws.FILTER(K:K,E:E=E13))))} -> 1 | G13: Combine ETS activities | H13: =_xlfn.XLOOKUP(I13,'ETS activities'!B:B,'ETS activities'!A:A) -> 44 | I13: Production of soda ash and sodium bicarbonate | J13: {=_xlfn.TEXTJOIN(", ",TRUE,_xlfn.UNIQUE(_xlfn._xlws.FILTER(H:H,K:K=K13)))} -> 37, 38, 39, 40, 41, 42, 43, 44 | K13: Production of carbon black, nitric acid, adipic acid, glyoxal and glyoxylic acid, ammonia, bulk chemicals, hydrogen and synthesis gas, soda ash and sodium bicarbonate | L13: {=COUNTA(_xlfn.UNIQUE(_xlfn._xlws.FILTER(E:E,K:K=K13)))} -> 1 | M13: broad combined | N13: Same NACE level-3 code intentionally reused; aggregate ETS rows to this NACE code before regression
... A34: =_xlfn.XLOOKUP(C34,'NACE Rev. All Levels'!$C:$C,'NACE Rev. All Levels'!A:A) -> 3 | B34: =_xlfn.XLOOKUP(C34,'NACE Rev. All Levels'!$C:$C,'NACE Rev. All Levels'!B:B) -> 512 | C34: Freight air transport and space transport | D34: {=_xlfn.TEXTJOIN(", ",TRUE,_xlfn.UNIQUE(_xlfn._xlws.FILTER(B:B,E:E=E34)))} -> 511, 512 | E34: Passenger air transport, Freight air transport and space transport | F34: {=IF(I34="",0,COUNTA(_xlfn.UNIQUE(_xlfn._xlws.FILTER(K:K,E:E=E34))))} -> 1 | G34: Combine NACE cat | H34: =_xlfn.XLOOKUP(I34,'ETS activities'!B:B,'ETS activities'!A:A) -> 10 | I34: Aviation | J34: {=_xlfn.TEXTJOIN(", ",TRUE,_xlfn.UNIQUE(_xlfn._xlws.FILTER(H:H,K:K=K34)))} -> 10 | K34: Aviation | L34: {=COUNTA(_xlfn.UNIQUE(_xlfn._xlws.FILTER(E:E,K:K=K34)))} -> 1 | M34: good | N34: ETS activity is broader than selected NACE level-3 categories; sum NACE rows before regression

Sheet NACE Rev. All Levels
A1: level | B1: ID | C1: name_clean | D1: label_original | E1: parent_code | F1: uri
A2: 2 | B2: 01 | C2: =IF(A2=1,RIGHT(D2,LEN(D2)-2),IF(A2=2,RIGHT(D2,LEN(D2)-3),IF(A2=3,RIGHT(D2,LEN(D2)-5),RIGHT(D2,LEN(D2)-6)))) -> Crop and animal production, hunting and related service activities | D2: 01 Crop and animal production, hunting and related service activities | E2: A | F2: http://data.europa.eu/ux2/nace2/01
A3: 3 | B3: 011 | C3: =IF(A3=1,RIGHT(D3,LEN(D3)-2),IF(A3=2,RIGHT(D3,LEN(D3)-3),IF(A3=3,RIGHT(D3,LEN(D3)-5),RIGHT(D3,LEN(D3)-6)))) -> Growing of non-perennial crops | D3: 01.1 Growing of non-perennial crops | E3: 01 | F3: http://data.europa.eu/ux2/nace2/011
A4: 4 | B4: 0111 | C4: =IF(A4=1,RIGHT(D4,LEN(D4)-2),IF(A4=2,RIGHT(D4,LEN(D4)-3),IF(A4=3,RIGHT(D4,LEN(D4)-5),RIGHT(D4,LEN(D4)-6)))) -> Growing of cereals (except rice), leguminous crops and oil seeds | D4: 01.11 Growing of cereals (except rice), leguminous crops and oil seeds | E4: 011 | F4: http://data.europa.eu/ux2/nace2/0111
A5: 4 | B5: 0112 | C5: =IF(A5=1,RIGHT(D5,LEN(D5)-2),IF(A5=2,RIGHT(D5,LEN(D5)-3),IF(A5=3,RIGHT(D5,LEN(D5)-5),RIGHT(D5,LEN(D5)-6)))) -> Growing of rice | D5: 01.12 Growing of rice | E5: 011 | F5: http://data.europa.eu/ux2/nace2/0112
A6: 4 | B6: 0113 | C6: =IF(A6=1,RIGHT(D6,LEN(D6)-2),IF(A6=2,RIGHT(D6,LEN(D6)-3),IF(A6=3,RIGHT(D6,LEN(D6)-5),RIGHT(D6,LEN(D6)-6)))) -> Growing of vegetables and melons, roots and tubers | D6: 01.13 Growing of vegetables and melons, roots and tubers | E6: 011 | F6: http://data.europa.eu/ux2/nace2/0113
A7: 4 | B7: 0114 | C7: =IF(A7=1,RIGHT(D7,LEN(D7)-2),IF(A7=2,RIGHT(D7,LEN(D7)-3),IF(A7=3,RIGHT(D7,LEN(D7)-5),RIGHT(D7,LEN(D7)-6)))) -> Growing of sugar cane | D7: 01.14 Growing of sugar cane | E7: 011 | F7: http://data.europa.eu/ux2/nace2/0114
A8: 4 | B8: 0115 | C8: =IF(A8=1,RIGHT(D8,LEN(D8)-2),IF(A8=2,RIGHT(D8,LEN(D8)-3),IF(A8=3,RIGHT(D8,LEN(D8)-5),RIGHT(D8,LEN(D8)-6)))) -> Growing of tobacco | D8: 01.15 Growing of tobacco | E8: 011 | F8: http://data.europa.eu/ux2/nace2/0115
A9: 4 | B9: 0116 | C9: =IF(A9=1,RIGHT(D9,LEN(D9)-2),IF(A9=2,RIGHT(D9,LEN(D9)-3),IF(A9=3,RIGHT(D9,LEN(D9)-5),RIGHT(D9,LEN(D9)-6)))) -> Growing of fibre crops | D9: 01.16 Growing of fibre crops | E9: 011 | F9: http://data.europa.eu/ux2/nace2/0116
A10: 4 | B10: 0119 | C10: =IF(A10=1,RIGHT(D10,LEN(D10)-2),IF(A10=2,RIGHT(D10,LEN(D10)-3),IF(A10=3,RIGHT(D10,LEN(D10)-5),RIGHT(D10,LEN(D10)-6)))) -> Growing of other non-perennial crops | D10: 01.19 Growing of other non-perennial crops | E10: 011 | F10: http://data.europa.eu/ux2/nace2/0119
A11: 3 | B11: 012 | C11: =IF(A11=1,RIGHT(D11,LEN(D11)-2),IF(A11=2,RIGHT(D11,LEN(D11)-3),IF(A11=3,RIGHT(D11,LEN(D11)-5),RIGHT(D11,LEN(D11)-6)))) -> Growing of perennial crops | D11: 01.2 Growing of perennial crops | E11: 01 | F11: http://data.europa.eu/ux2/nace2/012
A12: 4 | B12: 0121 | C12: =IF(A12=1,RIGHT(D12,LEN(D12)-2),IF(A12=2,RIGHT(D12,LEN(D12)-3),IF(A12=3,RIGHT(D12,LEN(D12)-5),RIGHT(D12,LEN(D12)-6)))) -> Growing of grapes | D12: 01.21 Growing of grapes | E12: 012 | F12: http://data.europa.eu/ux2/nace2/0121
A13: 4 | B13: 0122 | C13: =IF(A13=1,RIGHT(D13,LEN(D13)-2),IF(A13=2,RIGHT(D13,LEN(D13)-3),IF(A13=3,RIGHT(D13,LEN(D13)-5),RIGHT(D13,LEN(D13)-6)))) -> Growing of tropical and subtropical fruits | D13: 01.22 Growing of tropical and subtropical fruits | E13: 012 | F13: http://data.europa.eu/ux2/nace2/0122
... A280: 4 | B280: 2441 | C280: =IF(A280=1,RIGHT(D280,LEN(D280)-2),IF(A280=2,RIGHT(D280,LEN(D280)-3),IF(A280=3,RIGHT(D280,LEN(D280)-5),RIGHT(D280,LEN(D280)-6)))) -> Precious metals production | D280: 24.41 Precious metals production | E280: 244 | F280: http://data.europa.eu/ux2/nace2/2441
A281: 4 | B281: 2442 | C281: Aluminium production | D281: 24.42 Aluminium production | E281: 244 | F281: http://data.europa.eu/ux2/nace2/2442
A282: 4 | B282: 2443 | C282: =IF(A282=1,RIGHT(D282,LEN(D282)-2),IF(A282=2,RIGHT(D282,LEN(D282)-3),IF(A282=3,RIGHT(D282,LEN(D282)-5),RIGHT(D282,LEN(D282)-6)))) -> Lead, zinc and tin production | D282: 24.43 Lead, zinc and tin production | E282: 244 | F282: http://data.europa.eu/ux2/nace2/2443
A283: 4 | B283: 2444 | C283: =IF(A283=1,RIGHT(D283,LEN(D283)-2),IF(A283=2,RIGHT(D283,LEN(D283)-3),IF(A283=3,RIGHT(D283,LEN(D283)-5),RIGHT(D283,LEN(D283)-6)))) -> Copper production | D283: 24.44 Copper production | E283: 244 | F283: http://data.europa.eu/ux2/nace2/2444
A284: 4 | B284: 2445 | C284: =IF(A284=1,RIGHT(D284,LEN(D284)-2),IF(A284=2,RIGHT(D284,LEN(D284)-3),IF(A284=3,RIGHT(D284,LEN(D284)-5),RIGHT(D284,LEN(D284)-6)))) -> Other non-ferrous metal production | D284: 24.45 Other non-ferrous metal production | E284: 244 | F284: http://data.europa.eu/ux2/nace2/2445
A285: 4 | B285: 2446 | C285: =IF(A285=1,RIGHT(D285,LEN(D285)-2),IF(A285=2,RIGHT(D285,LEN(D285)-3),IF(A285=3,RIGHT(D285,LEN(D285)-5),RIGHT(D285,LEN(D285)-6)))) -> Processing of nuclear fuel | D285: 24.46 Processing of nuclear fuel | E285: 244 | F285: http://data.europa.eu/ux2/nace2/2446
A286: 3 | B286: 245 | C286: =IF(A286=1,RIGHT(D286,LEN(D286)-2),IF(A286=2,RIGHT(D286,LEN(D286)-3),IF(A286=3,RIGHT(D286,LEN(D286)-5),RIGHT(D286,LEN(D286)-6)))) -> Casting of metals | D286: 24.5 Casting of metals | E286: 24 | F286: http://data.europa.eu/ux2/nace2/245
A287: 4 | B287: 2451 | C287: =IF(A287=1,RIGHT(D287,LEN(D287)-2),IF(A287=2,RIGHT(D287,LEN(D287)-3),IF(A287=3,RIGHT(D287,LEN(D287)-5),RIGHT(D287,LEN(D287)-6)))) -> Casting of iron | D287: 24.51 Casting of iron | E287: 245 | F287: http://data.europa.eu/ux2/nace2/2451
A288: 4 | B288: 2452 | C288: =IF(A288=1,RIGHT(D288,LEN(D288)-2),IF(A288=2,RIGHT(D288,LEN(D288)-3),IF(A288=3,RIGHT(D288,LEN(D288)-5),RIGHT(D288,LEN(D288)-6)))) -> Casting of steel | D288: 24.52 Casting of steel | E288: 245 | F288: http://data.europa.eu/ux2/nace2/2452
A289: 4 | B289: 2453 | C289: =IF(A289=1,RIGHT(D289,LEN(D289)-2),IF(A289=2,RIGHT(D289,LEN(D289)-3),IF(A289=3,RIGHT(D289,LEN(D289)-5),RIGHT(D289,LEN(D289)-6)))) -> Casting of light metals | D289: 24.53 Casting of light metals | E289: 245 | F289: http://data.europa.eu/ux2/nace2/2453
A290: 4 | B290: 2454 | C290: =IF(A290=1,RIGHT(D290,LEN(D290)-2),IF(A290=2,RIGHT(D290,LEN(D290)-3),IF(A290=3,RIGHT(D290,LEN(D290)-5),RIGHT(D290,LEN(D290)-6)))) -> Casting of other non-ferrous metals | D290: 24.54 Casting of other non-ferrous metals | E290: 245 | F290: http://data.europa.eu/ux2/nace2/2454
A291: 2 | B291: 25 | C291: =IF(A291=1,RIGHT(D291,LEN(D291)-2),IF(A291=2,RIGHT(D291,LEN(D291)-3),IF(A291=3,RIGHT(D291,LEN(D291)-5),RIGHT(D291,LEN(D291)-6)))) -> Manufacture of fabricated metal products, except machinery and equipment | D291: 25 Manufacture of fabricated metal products, except machinery and equipment | E291: C | F291: http://data.europa.eu/ux2/nace2/25
A292: 3 | B292: 251 | C292: =IF(A292=1,RIGHT(D292,LEN(D292)-2),IF(A292=2,RIGHT(D292,LEN(D292)-3),IF(A292=3,RIGHT(D292,LEN(D292)-5),RIGHT(D292,LEN(D292)-6)))) -> Manufacture of structural metal products | D292: 25.1 Manufacture of structural metal products | E292: 25 | F292: http://data.europa.eu/ux2/nace2/251
A293: 4 | B293: 2511 | C293: =IF(A293=1,RIGHT(D293,LEN(D293)-2),IF(A293=2,RIGHT(D293,LEN(D293)-3),IF(A293=3,RIGHT(D293,LEN(D293)-5),RIGHT(D293,LEN(D293)-6)))) -> Manufacture of metal structures and parts of structures | D293: 25.11 Manufacture of metal structures and parts of structures | E293: 251 | F293: http://data.europa.eu/ux2/nace2/2511
... A976: 4 | B976: 9900 | C976: =IF(A976=1,RIGHT(D976,LEN(D976)-2),IF(A976=2,RIGHT(D976,LEN(D976)-3),IF(A976=3,RIGHT(D976,LEN(D976)-5),RIGHT(D976,LEN(D976)-6)))) -> Activities of extraterritorial organisations and bodies | D976: 99.00 Activities of extraterritorial organisations and bodies | E976: 990 | F976: http://data.europa.eu/ux2/nace2/9900
A977: 1 | B977: A | C977: =IF(A977=1,RIGHT(D977,LEN(D977)-2),IF(A977=2,RIGHT(D977,LEN(D977)-3),IF(A977=3,RIGHT(D977,LEN(D977)-5),RIGHT(D977,LEN(D977)-6)))) -> AGRICULTURE, FORESTRY AND FISHING | D977: A AGRICULTURE, FORESTRY AND FISHING | F977: http://data.europa.eu/ux2/nace2/A
A978: 1 | B978: B | C978: =IF(A978=1,RIGHT(D978,LEN(D978)-2),IF(A978=2,RIGHT(D978,LEN(D978)-3),IF(A978=3,RIGHT(D978,LEN(D978)-5),RIGHT(D978,LEN(D978)-6)))) -> MINING AND QUARRYING | D978: B MINING AND QUARRYING | F978: http://data.europa.eu/ux2/nace2/B
A979: 1 | B979: C | C979: =IF(A979=1,RIGHT(D979,LEN(D979)-2),IF(A979=2,RIGHT(D979,LEN(D979)-3),IF(A979=3,RIGHT(D979,LEN(D979)-5),RIGHT(D979,LEN(D979)-6)))) -> MANUFACTURING | D979: C MANUFACTURING | F979: http://data.europa.eu/ux2/nace2/C
A980: 1 | B980: D | C980: =IF(A980=1,RIGHT(D980,LEN(D980)-2),IF(A980=2,RIGHT(D980,LEN(D980)-3),IF(A980=3,RIGHT(D980,LEN(D980)-5),RIGHT(D980,LEN(D980)-6)))) -> ELECTRICITY, GAS, STEAM AND AIR CONDITIONING SUPPLY | D980: D ELECTRICITY, GAS, STEAM AND AIR CONDITIONING SUPPLY | F980: http://data.europa.eu/ux2/nace2/D
A981: 1 | B981: E | C981: =IF(A981=1,RIGHT(D981,LEN(D981)-2),IF(A981=2,RIGHT(D981,LEN(D981)-3),IF(A981=3,RIGHT(D981,LEN(D981)-5),RIGHT(D981,LEN(D981)-6)))) -> WATER SUPPLY; SEWERAGE, WASTE MANAGEMENT AND REMEDIATION ACTIVITIES | D981: E WATER SUPPLY; SEWERAGE, WASTE MANAGEMENT AND REMEDIATION ACTIVITIES | F981: http://data.europa.eu/ux2/nace2/E
A982: 1 | B982: F | C982: =IF(A982=1,RIGHT(D982,LEN(D982)-2),IF(A982=2,RIGHT(D982,LEN(D982)-3),IF(A982=3,RIGHT(D982,LEN(D982)-5),RIGHT(D982,LEN(D982)-6)))) -> CONSTRUCTION | D982: F CONSTRUCTION | F982: http://data.europa.eu/ux2/nace2/F
A983: 1 | B983: G | C983: =IF(A983=1,RIGHT(D983,LEN(D983)-2),IF(A983=2,RIGHT(D983,LEN(D983)-3),IF(A983=3,RIGHT(D983,LEN(D983)-5),RIGHT(D983,LEN(D983)-6)))) -> WHOLESALE AND RETAIL TRADE; REPAIR OF MOTOR VEHICLES AND MOTORCYCLES | D983: G WHOLESALE AND RETAIL TRADE; REPAIR OF MOTOR VEHICLES AND MOTORCYCLES | F983: http://data.europa.eu/ux2/nace2/G
A984: 1 | B984: H | C984: =IF(A984=1,RIGHT(D984,LEN(D984)-2),IF(A984=2,RIGHT(D984,LEN(D984)-3),IF(A984=3,RIGHT(D984,LEN(D984)-5),RIGHT(D984,LEN(D984)-6)))) -> TRANSPORTATION AND STORAGE | D984: H TRANSPORTATION AND STORAGE | F984: http://data.europa.eu/ux2/nace2/H
A985: 1 | B985: I | C985: =IF(A985=1,RIGHT(D985,LEN(D985)-2),IF(A985=2,RIGHT(D985,LEN(D985)-3),IF(A985=3,RIGHT(D985,LEN(D985)-5),RIGHT(D985,LEN(D985)-6)))) -> ACCOMMODATION AND FOOD SERVICE ACTIVITIES | D985: I ACCOMMODATION AND FOOD SERVICE ACTIVITIES | F985: http://data.europa.eu/ux2/nace2/I
A986: 1 | B986: J | C986: =IF(A986=1,RIGHT(D986,LEN(D986)-2),IF(A986=2,RIGHT(D986,LEN(D986)-3),IF(A986=3,RIGHT(D986,LEN(D986)-5),RIGHT(D986,LEN(D986)-6)))) -> INFORMATION AND COMMUNICATION | D986: J INFORMATION AND COMMUNICATION | F986: http://data.europa.eu/ux2/nace2/J
A987: 1 | B987: K | C987: =IF(A987=1,RIGHT(D987,LEN(D987)-2),IF(A987=2,RIGHT(D987,LEN(D987)-3),IF(A987=3,RIGHT(D987,LEN(D987)-5),RIGHT(D987,LEN(D987)-6)))) -> FINANCIAL AND INSURANCE ACTIVITIES | D987: K FINANCIAL AND INSURANCE ACTIVITIES | F987: http://data.europa.eu/ux2/nace2/K
A988: 1 | B988: L | C988: =IF(A988=1,RIGHT(D988,LEN(D988)-2),IF(A988=2,RIGHT(D988,LEN(D988)-3),IF(A988=3,RIGHT(D988,LEN(D988)-5),RIGHT(D988,LEN(D988)-6)))) -> REAL ESTATE ACTIVITIES | D988: L REAL ESTATE ACTIVITIES | F988: http://data.europa.eu/ux2/nace2/L
...

Sheet ETS activities
A1: ets_activity_code | B1: ets_activity_name | C1: mapped
A2: 10 | B2: Aviation | C2: =_xlfn.IFNA(IF(_xlfn.XLOOKUP(A2,#REF!,#REF!)<>"",1,0),0) -> #REF!
A3: 20 | B3: Combustion of fuels | C3: =_xlfn.IFNA(IF(_xlfn.XLOOKUP(A3,#REF!,#REF!)<>"",1,0),0) -> #REF!
A4: 20-99 | B4: All stationary installations | C4: =_xlfn.IFNA(IF(_xlfn.XLOOKUP(A4,#REF!,#REF!)<>"",1,0),0) -> #REF!
A5: 21 | B5: Refining of mineral oil | C5: =_xlfn.IFNA(IF(_xlfn.XLOOKUP(A5,#REF!,#REF!)<>"",1,0),0) -> #REF!
A6: 21-99 | B6: All industrial installations (excl. combustion) | C6: =_xlfn.IFNA(IF(_xlfn.XLOOKUP(A6,#REF!,#REF!)<>"",1,0),0) -> #REF!
A7: 22 | B7: Production of coke | C7: =_xlfn.IFNA(IF(_xlfn.XLOOKUP(A7,#REF!,#REF!)<>"",1,0),0) -> #REF!
A8: 23 | B8: Metal ore roasting or sintering | C8: =_xlfn.IFNA(IF(_xlfn.XLOOKUP(A8,#REF!,#REF!)<>"",1,0),0) -> #REF!
A9: 24 | B9: Production of pig iron or steel | C9: =_xlfn.IFNA(IF(_xlfn.XLOOKUP(A9,#REF!,#REF!)<>"",1,0),0) -> #REF!
A10: 25 | B10: Production or processing of ferrous metals | C10: =_xlfn.IFNA(IF(_xlfn.XLOOKUP(A10,#REF!,#REF!)<>"",1,0),0) -> #REF!
A11: 26 | B11: Production of primary aluminium | C11: =_xlfn.IFNA(IF(_xlfn.XLOOKUP(A11,#REF!,#REF!)<>"",1,0),0) -> #REF!
A12: 27 | B12: Production of secondary aluminium | C12: =_xlfn.IFNA(IF(_xlfn.XLOOKUP(A12,#REF!,#REF!)<>"",1,0),0) -> #REF!
A13: 28 | B13: Production or processing of non-ferrous metals | C13: =_xlfn.IFNA(IF(_xlfn.XLOOKUP(A13,#REF!,#REF!)<>"",1,0),0) -> #REF!
... A32: 99 | B32: Other activity opted-in under Art. 24 | C32: =_xlfn.IFNA(IF(_xlfn.XLOOKUP(A32,#REF!,#REF!)<>"",1,0),0) -> #REF!

Sheet NACE Rev. 2 Level 3
A1: ID | B1: Label | C1: is_ets_activity | D1: Original | E1: has_ets_activity
A2: =LEFT(D2,4) -> 01.1 | B2: =SUBSTITUTE(SUBSTITUTE(D2,A2&" ",""),RIGHT(D2,5),"") -> Growing of non-perennial crops | C2: =ISNUMBER(MATCH(A2,#REF!, 0)) -> FALSE | D2: 01.1 Growing of non-perennial crops (en) | E2: =_xlfn.XLOOKUP(B2,Mapping!$C$2:$C$34,Mapping!$C$2:$C$34,FALSE) -> FALSE
A3: =LEFT(D3,4) -> 01.2 | B3: =SUBSTITUTE(SUBSTITUTE(D3,A3&" ",""),RIGHT(D3,5),"") -> Growing of perennial crops | C3: =ISNUMBER(MATCH(A3,#REF!, 0)) -> FALSE | D3: 01.2 Growing of perennial crops (en) | E3: =_xlfn.XLOOKUP(B3,Mapping!$C$2:$C$34,Mapping!$C$2:$C$34,FALSE) -> FALSE
A4: =LEFT(D4,4) -> 01.3 | B4: =SUBSTITUTE(SUBSTITUTE(D4,A4&" ",""),RIGHT(D4,5),"") -> Plant propagation | C4: =ISNUMBER(MATCH(A4,#REF!, 0)) -> FALSE | D4: 01.3 Plant propagation (en) | E4: =_xlfn.XLOOKUP(B4,Mapping!$C$2:$C$34,Mapping!$C$2:$C$34,FALSE) -> FALSE
A5: =LEFT(D5,4) -> 01.4 | B5: =SUBSTITUTE(SUBSTITUTE(D5,A5&" ",""),RIGHT(D5,5),"") -> Animal production | C5: =ISNUMBER(MATCH(A5,#REF!, 0)) -> FALSE | D5: 01.4 Animal production (en) | E5: =_xlfn.XLOOKUP(B5,Mapping!$C$2:$C$34,Mapping!$C$2:$C$34,FALSE) -> FALSE
A6: =LEFT(D6,4) -> 01.5 | B6: =SUBSTITUTE(SUBSTITUTE(D6,A6&" ",""),RIGHT(D6,5),"") -> Mixed farming | C6: =ISNUMBER(MATCH(A6,#REF!, 0)) -> FALSE | D6: 01.5 Mixed farming (en) | E6: =_xlfn.XLOOKUP(B6,Mapping!$C$2:$C$34,Mapping!$C$2:$C$34,FALSE) -> FALSE
A7: =LEFT(D7,4) -> 01.6 | B7: =SUBSTITUTE(SUBSTITUTE(D7,A7&" ",""),RIGHT(D7,5),"") -> Support activities to agriculture and post-harvest crop activities | C7: =ISNUMBER(MATCH(A7,#REF!, 0)) -> FALSE | D7: 01.6 Support activities to agriculture and post-harvest crop activities (en) | E7: =_xlfn.XLOOKUP(B7,Mapping!$C$2:$C$34,Mapping!$C$2:$C$34,FALSE) -> FALSE
A8: =LEFT(D8,4) -> 01.7 | B8: =SUBSTITUTE(SUBSTITUTE(D8,A8&" ",""),RIGHT(D8,5),"") -> Hunting, trapping and related service activities | C8: =ISNUMBER(MATCH(A8,#REF!, 0)) -> FALSE | D8: 01.7 Hunting, trapping and related service activities (en) | E8: =_xlfn.XLOOKUP(B8,Mapping!$C$2:$C$34,Mapping!$C$2:$C$34,FALSE) -> FALSE
A9: =LEFT(D9,4) -> 02.1 | B9: =SUBSTITUTE(SUBSTITUTE(D9,A9&" ",""),RIGHT(D9,5),"") -> Silviculture and other forestry activities | C9: =ISNUMBER(MATCH(A9,#REF!, 0)) -> FALSE | D9: 02.1 Silviculture and other forestry activities (en) | E9: =_xlfn.XLOOKUP(B9,Mapping!$C$2:$C$34,Mapping!$C$2:$C$34,FALSE) -> FALSE
A10: =LEFT(D10,4) -> 02.2 | B10: =SUBSTITUTE(SUBSTITUTE(D10,A10&" ",""),RIGHT(D10,5),"") -> Logging | C10: =ISNUMBER(MATCH(A10,#REF!, 0)) -> FALSE | D10: 02.2 Logging (en) | E10: =_xlfn.XLOOKUP(B10,Mapping!$C$2:$C$34,Mapping!$C$2:$C$34,FALSE) -> FALSE
A11: =LEFT(D11,4) -> 02.3 | B11: =SUBSTITUTE(SUBSTITUTE(D11,A11&" ",""),RIGHT(D11,5),"") -> Gathering of wild growing non-wood products | C11: =ISNUMBER(MATCH(A11,#REF!, 0)) -> FALSE | D11: 02.3 Gathering of wild growing non-wood products (en) | E11: =_xlfn.XLOOKUP(B11,Mapping!$C$2:$C$34,Mapping!$C$2:$C$34,FALSE) -> FALSE
A12: =LEFT(D12,4) -> 02.4 | B12: =SUBSTITUTE(SUBSTITUTE(D12,A12&" ",""),RIGHT(D12,5),"") -> Support services to forestry | C12: =ISNUMBER(MATCH(A12,#REF!, 0)) -> FALSE | D12: 02.4 Support services to forestry (en) | E12: =_xlfn.XLOOKUP(B12,Mapping!$C$2:$C$34,Mapping!$C$2:$C$34,FALSE) -> FALSE
A13: =LEFT(D13,4) -> 03.1 | B13: =SUBSTITUTE(SUBSTITUTE(D13,A13&" ",""),RIGHT(D13,5),"") -> Fishing | C13: =ISNUMBER(MATCH(A13,#REF!, 0)) -> FALSE | D13: 03.1 Fishing (en) | E13: =_xlfn.XLOOKUP(B13,Mapping!$C$2:$C$34,Mapping!$C$2:$C$34,FALSE) -> FALSE
... A273: =LEFT(D273,4) -> 99.0 | B273: =SUBSTITUTE(SUBSTITUTE(D273,A273&" ",""),RIGHT(D273,5),"") -> Activities of extraterritorial organisations and bodies | C273: =ISNUMBER(MATCH(A273,#REF!, 0)) -> FALSE | D273: 99.0 Activities of extraterritorial organisations and bodies (en) | E273: =_xlfn.XLOOKUP(B273,Mapping!$C$2:$C$34,Mapping!$C$2:$C$34,FALSE) -> FALSE

Sheet Mapping All Nace Activities
A1: nace_level | B1: nace_code | C1: nace_label_original | D1: nace_code_agg | E1: nace_label_agg | F1: mapped_uniq_ets_cnt | G1: cleaning_action | H1: ets_activity_code | I1: ets_activity_name_original | J1: ets_activity_code_agg | K1: ets_activity_name_agg | L1: mapped_uniq_nace_cnt | M1: mapping_quality | N1: exclusivity_note
A2: 3 | B2: 171 | C2: Manufacture of pulp, paper and paperboard | D2: 171 | E2: Manufacture of pulp, paper and paperboard | F2: 1 | G2: Combine ETS activities | H2: 35 | I2: Production of pulp | J2: 35, 36 | K2: Production of pulp, paper and cardboard | L2: 1 | M2: broad combined | N2: Same NACE level-3 code intentionally reused; aggregate ETS rows to this NACE code before regression
A3: 3 | B3: 171 | C3: Manufacture of pulp, paper and paperboard | D3: 171 | E3: Manufacture of pulp, paper and paperboard | F3: 1 | G3: Combine ETS activities | H3: 36 | I3: Production of paper or cardboard | J3: 35, 36 | K3: Production of pulp, paper and cardboard | L3: 1 | M3: broad combined | N3: Same NACE level-3 code intentionally reused; aggregate ETS rows to this NACE code before regression
A4: 3 | B4: 191 | C4: Manufacture of coke oven products | D4: 191 | E4: Manufacture of coke oven products | F4: 1 | G4: None | H4: 22 | I4: Production of coke | J4: 22 | K4: Production of coke | L4: 1 | M4: exact | N4: Exclusive NACE level-1-3 code; no selected parent/child overlap
A5: 3 | B5: 192 | C5: Manufacture of refined petroleum products | D5: 192 | E5: Manufacture of refined petroleum products | F5: 1 | G5: None | H5: 21 | I5: Refining of mineral oil | J5: 21 | K5: Refining of mineral oil | L5: 1 | M5: exact | N5: Exclusive NACE level-1-3 code; no selected parent/child overlap
A6: 3 | B6: 201 | C6: Manufacture of basic chemicals, fertilisers and nitrogen compounds, plastics and synthetic rubber in primary forms | D6: 201 | E6: Manufacture of basic chemicals, fertilisers and nitrogen compounds, plastics and synthetic rubber in primary forms | F6: 1 | G6: Combine ETS activities | H6: 37 | I6: Production of carbon black | J6: 37, 38, 39, 40, 41, 42, 43, 44 | K6: Production of carbon black, nitric acid, adipic acid, glyoxal and glyoxylic acid, ammonia, bulk chemicals, hydrogen and synthesis gas, soda ash and sodium bicarbonate | L6: 1 | M6: broad combined | N6: Same NACE level-3 code intentionally reused; aggregate ETS rows to this NACE code before regression
A7: 3 | B7: 201 | C7: Manufacture of basic chemicals, fertilisers and nitrogen compounds, plastics and synthetic rubber in primary forms | D7: 201 | E7: Manufacture of basic chemicals, fertilisers and nitrogen compounds, plastics and synthetic rubber in primary forms | F7: 1 | G7: Combine ETS activities | H7: 38 | I7: Production of nitric acid | J7: 37, 38, 39, 40, 41, 42, 43, 44 | K7: Production of carbon black, nitric acid, adipic acid, glyoxal and glyoxylic acid, ammonia, bulk chemicals, hydrogen and synthesis gas, soda ash and sodium bicarbonate | L7: 1 | M7: broad combined | N7: Same NACE level-3 code intentionally reused; aggregate ETS rows to this NACE code before regression
A8: 3 | B8: 201 | C8: Manufacture of basic chemicals, fertilisers and nitrogen compounds, plastics and synthetic rubber in primary forms | D8: 201 | E8: Manufacture of basic chemicals, fertilisers and nitrogen compounds, plastics and synthetic rubber in primary forms | F8: 1 | G8: Combine ETS activities | H8: 39 | I8: Production of adipic acid | J8: 37, 38, 39, 40, 41, 42, 43, 44 | K8: Production of carbon black, nitric acid, adipic acid, glyoxal and glyoxylic acid, ammonia, bulk chemicals, hydrogen and synthesis gas, soda ash and sodium bicarbonate | L8: 1 | M8: broad combined | N8: Same NACE level-3 code intentionally reused; aggregate ETS rows to this NACE code before regression
A9: 3 | B9: 201 | C9: Manufacture of basic chemicals, fertilisers and nitrogen compounds, plastics and synthetic rubber in primary forms | D9: 201 | E9: Manufacture of basic chemicals, fertilisers and nitrogen compounds, plastics and synthetic rubber in primary forms | F9: 1 | G9: Combine ETS activities | H9: 40 | I9: Production of glyoxal and glyoxylic acid | J9: 37, 38, 39, 40, 41, 42, 43, 44 | K9: Production of carbon black, nitric acid, adipic acid, glyoxal and glyoxylic acid, ammonia, bulk chemicals, hydrogen and synthesis gas, soda ash and sodium bicarbonate | L9: 1 | M9: broad combined | N9: Same NACE level-3 code intentionally reused; aggregate ETS rows to this NACE code before regression
A10: 3 | B10: 201 | C10: Manufacture of basic chemicals, fertilisers and nitrogen compounds, plastics and synthetic rubber in primary forms | D10: 201 | E10: Manufacture of basic chemicals, fertilisers and nitrogen compounds, plastics and synthetic rubber in primary forms | F10: 1 | G10: Combine ETS activities | H10: 41 | I10: Production of ammonia | J10: 37, 38, 39, 40, 41, 42, 43, 44 | K10: Production of carbon black, nitric acid, adipic acid, glyoxal and glyoxylic acid, ammonia, bulk chemicals, hydrogen and synthesis gas, soda ash and sodium bicarbonate | L10: 1 | M10: broad combined | N10: Same NACE level-3 code intentionally reused; aggregate ETS rows to this NACE code before regression
A11: 3 | B11: 201 | C11: Manufacture of basic chemicals, fertilisers and nitrogen compounds, plastics and synthetic rubber in primary forms | D11: 201 | E11: Manufacture of basic chemicals, fertilisers and nitrogen compounds, plastics and synthetic rubber in primary forms | F11: 1 | G11: Combine ETS activities | H11: 42 | I11: Production of bulk chemicals | J11: 37, 38, 39, 40, 41, 42, 43, 44 | K11: Production of carbon black, nitric acid, adipic acid, glyoxal and glyoxylic acid, ammonia, bulk chemicals, hydrogen and synthesis gas, soda ash and sodium bicarbonate | L11: 1 | M11: broad combined | N11: Same NACE level-3 code intentionally reused; aggregate ETS rows to this NACE code before regression
A12: 3 | B12: 201 | C12: Manufacture of basic chemicals, fertilisers and nitrogen compounds, plastics and synthetic rubber in primary forms | D12: 201 | E12: Manufacture of basic chemicals, fertilisers and nitrogen compounds, plastics and synthetic rubber in primary forms | F12: 1 | G12: Combine ETS activities | H12: 43 | I12: Production of hydrogen and synthesis gas | J12: 37, 38, 39, 40, 41, 42, 43, 44 | K12: Production of carbon black, nitric acid, adipic acid, glyoxal and glyoxylic acid, ammonia, bulk chemicals, hydrogen and synthesis gas, soda ash and sodium bicarbonate | L12: 1 | M12: broad combined | N12: Same NACE level-3 code intentionally reused; aggregate ETS rows to this NACE code before regression
A13: 3 | B13: 201 | C13: Manufacture of basic chemicals, fertilisers and nitrogen compounds, plastics and synthetic rubber in primary forms | D13: 201 | E13: Manufacture of basic chemicals, fertilisers and nitrogen compounds, plastics and synthetic rubber in primary forms | F13: 1 | G13: Combine ETS activities | H13: 44 | I13: Production of soda ash and sodium bicarbonate | J13: 37, 38, 39, 40, 41, 42, 43, 44 | K13: Production of carbon black, nitric acid, adipic acid, glyoxal and glyoxylic acid, ammonia, bulk chemicals, hydrogen and synthesis gas, soda ash and sodium bicarbonate | L13: 1 | M13: broad combined | N13: Same NACE level-3 code intentionally reused; aggregate ETS rows to this NACE code before regression
... A34: 3 | B34: 512 | C34: Freight air transport and space transport | D34: 511, 512 | E34: Passenger air transport, Freight air transport and space transport | F34: 1 | G34: Combine NACE cat | H34: 10 | I34: Aviation | J34: 10 | K34: Aviation | L34: 1 | M34: good | N34: ETS activity is broader than selected NACE level-3 categories; sum NACE rows before regression
A35: 2 | B35: 01 | C35: Crop and animal production, hunting and related service activities | D35: 01 | E35: Crop and animal production, hunting and related service activities | F35: 0 | G35: Append unmapped NACE activity | L35: 1 | M35: unmapped NACE-only | N35: Level-2 activity from a section without any mapped NACE activity
A36: 2 | B36: 02 | C36: Forestry and logging | D36: 02 | E36: Forestry and logging | F36: 0 | G36: Append unmapped NACE activity | L36: 1 | M36: unmapped NACE-only | N36: Level-2 activity from a section without any mapped NACE activity
A37: 2 | B37: 03 | C37: Fishing and aquaculture | D37: 03 | E37: Fishing and aquaculture | F37: 0 | G37: Append unmapped NACE activity | L37: 1 | M37: unmapped NACE-only | N37: Level-2 activity from a section without any mapped NACE activity
A38: 2 | B38: 05 | C38: Mining of coal and lignite | D38: 05 | E38: Mining of coal and lignite | F38: 0 | G38: Append unmapped NACE activity | L38: 1 | M38: unmapped NACE-only | N38: Level-2 activity from a section without any mapped NACE activity
A39: 2 | B39: 06 | C39: Extraction of crude petroleum and natural gas | D39: 06 | E39: Extraction of crude petroleum and natural gas | F39: 0 | G39: Append unmapped NACE activity | L39: 1 | M39: unmapped NACE-only | N39: Level-2 activity from a section without any mapped NACE activity
A40: 2 | B40: 07 | C40: Mining of metal ores | D40: 07 | E40: Mining of metal ores | F40: 0 | G40: Append unmapped NACE activity | L40: 1 | M40: unmapped NACE-only | N40: Level-2 activity from a section without any mapped NACE activity
A41: 2 | B41: 08 | C41: Other mining and quarrying | D41: 08 | E41: Other mining and quarrying | F41: 0 | G41: Append unmapped NACE activity | L41: 1 | M41: unmapped NACE-only | N41: Level-2 activity from a section without any mapped NACE activity
A42: 2 | B42: 09 | C42: Mining support service activities | D42: 09 | E42: Mining support service activities | F42: 0 | G42: Append unmapped NACE activity | L42: 1 | M42: unmapped NACE-only | N42: Level-2 activity from a section without any mapped NACE activity
A43: 2 | B43: 36 | C43: Water collection, treatment and supply | D43: 36 | E43: Water collection, treatment and supply | F43: 0 | G43: Append unmapped NACE activity | L43: 1 | M43: unmapped NACE-only | N43: Unmapped sibling at the same level as a mapped NACE activity
A44: 2 | B44: 37 | C44: Sewerage | D44: 37 | E44: Sewerage | F44: 0 | G44: Append unmapped NACE activity | L44: 1 | M44: unmapped NACE-only | N44: Unmapped sibling at the same level as a mapped NACE activity
A45: 2 | B45: 38 | C45: Waste collection, treatment and disposal activities; materials recovery | D45: 38 | E45: Waste collection, treatment and disposal activities; materials recovery | F45: 0 | G45: Append unmapped NACE activity | L45: 1 | M45: unmapped NACE-only | N45: Unmapped sibling at the same level as a mapped NACE activity
A46: 2 | B46: 41 | C46: Construction of buildings | D46: 41 | E46: Construction of buildings | F46: 0 | G46: Append unmapped NACE activity | L46: 1 | M46: unmapped NACE-only | N46: Level-2 activity from a section without any mapped NACE activity
... A182: 3 | B182: 532 | C182: Other postal and courier activities | D182: 532 | E182: Other postal and courier activities | F182: 0 | G182: Append unmapped NACE activity | L182: 1 | M182: unmapped NACE-only | N182: Unmapped sibling at the same level as a mapped NACE activity
