Workbook

Sheet Comparison
A1: Year | B1: ICAP primary market | C1: Secondary market | D1: EEX primary market | G1: EU ETS Zertifikatspreise: Primär- vs. Sekundärmarkt | H1: EU ETS allowance price comparison (annual averages) | I1: EU ETS allowance price comparison (annual averages) | J1: EU ETS allowance price comparison (annual averages) | K1: EU ETS allowance price comparison (annual averages)
A2: 2019 | B2: {=AVERAGE(_xlfn._xlws.FILTER('ETS price ICAP'!$E$3:$E$5000,YEAR('ETS price ICAP'!$A$3:$A$5000)=$A2))} -> 24.723125 | C2: {=AVERAGE(_xlfn._xlws.FILTER('ETS price ICAP'!$F$3:$F$5000,YEAR('ETS price ICAP'!$A$3:$A$5000)=$A2))} -> 24.889412 | D2: {=AVERAGE(_xlfn._xlws.FILTER('ETS price EEX 2019 Spot Primary'!$E$5:$E$220,YEAR('ETS price EEX 2019 Spot Primary'!$A$5:$A$220)=$A2))} -> 24.72338
A3: 2020 | B3: {=AVERAGE(_xlfn._xlws.FILTER('ETS price ICAP'!$E$3:$E$5000,YEAR('ETS price ICAP'!$A$3:$A$5000)=$A3))} -> 24.386603 | C3: {=AVERAGE(_xlfn._xlws.FILTER('ETS price ICAP'!$F$3:$F$5000,YEAR('ETS price ICAP'!$A$3:$A$5000)=$A3))} -> 24.544 | G3: Year | H3: ICAP Primärmarkt | I3: ICAP Sekundärmarkt | J3: EEX Primärmarkt | K3: EEX Sekundärmarkt
A4: =A3+1 -> 2021 | B4: {=AVERAGE(_xlfn._xlws.FILTER('ETS price ICAP'!$E$3:$E$5000,YEAR('ETS price ICAP'!$A$3:$A$5000)=$A4))} -> 54.15157 | C4: {=AVERAGE(_xlfn._xlws.FILTER('ETS price ICAP'!$F$3:$F$5000,YEAR('ETS price ICAP'!$A$3:$A$5000)=$A4))} -> 53.135686 | G4: 2013 | H4: 4.3731 | I4: null | J4: 4.3793 | K4: zum Verkauf
A5: =A4+1 -> 2022 | B5: {=AVERAGE(_xlfn._xlws.FILTER('ETS price ICAP'!$E$3:$E$5000,YEAR('ETS price ICAP'!$A$3:$A$5000)=$A5))} -> 80.184045 | C5: {=AVERAGE(_xlfn._xlws.FILTER('ETS price ICAP'!$F$3:$F$5000,YEAR('ETS price ICAP'!$A$3:$A$5000)=$A5))} -> 81.073462 | D5: {=AVERAGE(_xlfn._xlws.FILTER('ETS price EEX 2022 Spot Primary'!$F$6:$F$250,YEAR('ETS price EEX 2022 Spot Primary'!$A$6:$A$250)=$A5))} -> 80.184045 | G5: 2014 | H5: 5.9123 | I5: null | J5: 5.9123 | K5: zum Verkauf
A6: =A5+1 -> 2023 | B6: {=AVERAGE(_xlfn._xlws.FILTER('ETS price ICAP'!$E$3:$E$5000,YEAR('ETS price ICAP'!$A$3:$A$5000)=$A6))} -> 83.596502 | C6: {=AVERAGE(_xlfn._xlws.FILTER('ETS price ICAP'!$F$3:$F$5000,YEAR('ETS price ICAP'!$A$3:$A$5000)=$A6))} -> 85.384 | G6: 2015 | H6: 7.619 | I6: null | J6: 7.6103 | K6: zum Verkauf
A7: =A6+1 -> 2024 | B7: {=AVERAGE(_xlfn._xlws.FILTER('ETS price ICAP'!$E$3:$E$5000,YEAR('ETS price ICAP'!$A$3:$A$5000)=$A7))} -> 64.757014 | C7: {=AVERAGE(_xlfn._xlws.FILTER('ETS price ICAP'!$F$3:$F$5000,YEAR('ETS price ICAP'!$A$3:$A$5000)=$A7))} -> 66.586538 | G7: 2016 | H7: 5.2475 | I7: null | J7: 5.2475 | K7: zum Verkauf
A8: =A7+1 -> 2025 | B8: {=AVERAGE(_xlfn._xlws.FILTER('ETS price ICAP'!$E$3:$E$5000,YEAR('ETS price ICAP'!$A$3:$A$5000)=$A8))} -> 73.452488 | C8: {=AVERAGE(_xlfn._xlws.FILTER('ETS price ICAP'!$F$3:$F$5000,YEAR('ETS price ICAP'!$A$3:$A$5000)=$A8))} -> 72.686154 | G8: 2017 | H8: 5.7573 | I8: null | J8: 5.7953 | K8: zum Verkauf
A9: =A8+1 -> 2026 | B9: {=AVERAGE(_xlfn._xlws.FILTER('ETS price ICAP'!$E$3:$E$5000,YEAR('ETS price ICAP'!$A$3:$A$5000)=$A9))} -> 74.928636 | C9: {=AVERAGE(_xlfn._xlws.FILTER('ETS price ICAP'!$F$3:$F$5000,YEAR('ETS price ICAP'!$A$3:$A$5000)=$A9))} -> #DIV/0! | G9: 2018 | H9: 15.4771 | I9: null | J9: 15.5615 | K9: zum Verkauf
G10: 2019 | H10: 24.7231 | I10: 24.8894 | J10: 24.7234 | K10: zum Verkauf
G11: 2020 | H11: 24.3866 | I11: 24.544 | J11: 24.37 | K11: zum Verkauf
G12: 2021 | H12: 54.1516 | I12: 53.1357 | J12: 54.1276 | K12: zum Verkauf
G13: 2022 | H13: 80.184 | I13: 81.0735 | J13: 80.184 | K13: zum Verkauf
G14: 2023 | H14: 83.5965 | I14: 85.384 | J14: 83.5965 | K14: zum Verkauf
G15: 2024 | H15: 64.757 | I15: 66.5865 | J15: 64.757 | K15: zum Verkauf
G16: 2025 | H16: 73.4525 | I16: 72.6862 | J16: 73.4525 | K16: zum Verkauf
G17: 2026 | H17: 74.9286 | I17: null | J17: null | K17: zum Verkauf

Sheet ETS price ICAP
B1: European Union Emissions Trading System (from 2019, download)
A2: Date | B2: Exchange rate EUR/EUR | C2: Exchange rate EUR/USD | D2: Market Currency | E2: Primary Market | F2: Secondary Market
A3: 43472 | B3: 1 | C3: 1.1416409 | D3: EUR | E3: 23.01 | F3: 22.39
A4: 43473 | B4: 1 | C4: 1.1416409 | D4: EUR | E4: 22.4
A5: 43475 | B5: 1 | C5: 1.1416409 | D5: EUR | E5: 21.4
A6: 43479 | B6: 1 | C6: 1.1416409 | D6: EUR | E6: 21.95 | F6: 23.42
A7: 43480 | B7: 1 | C7: 1.1416409 | D7: EUR | E7: 22.55
A8: 43481 | B8: 1 | C8: 1.1416409 | D8: EUR | E8: 22.81
A9: 43482 | B9: 1 | C9: 1.1416409 | D9: EUR | E9: 23.55
A10: 43486 | B10: 1 | C10: 1.1416409 | D10: EUR | E10: 24.22 | F10: 24.48
A11: 43487 | B11: 1 | C11: 1.1416409 | D11: EUR | E11: 24.42
A12: 43489 | B12: 1 | C12: 1.1416409 | D12: EUR | E12: 24.6
A13: 43493 | B13: 1 | C13: 1.1416409 | D13: EUR | E13: 23.01 | F13: 22.7
A14: 43494 | B14: 1 | C14: 1.1416409 | D14: EUR | E14: 22.43
A15: 43495 | B15: 1 | C15: 1.1416409 | D15: EUR | E15: 22.91
A16: 43496 | B16: 1 | C16: 1.1416409 | D16: EUR | E16: 22.3
A17: 43497 | B17: 1 | C17: 1.135115 | D17: EUR | E17: 21.38
A18: 43500 | B18: 1 | C18: 1.135115 | D18: EUR | E18: 21.38 | F18: 23.16
A19: 43501 | B19: 1 | C19: 1.135115 | D19: EUR | E19: 22.93
A20: 43503 | B20: 1 | C20: 1.135115 | D20: EUR | E20: 23.8
A21: 43504 | B21: 1 | C21: 1.135115 | D21: EUR | E21: 23.28
A22: 43507 | B22: 1 | C22: 1.135115 | D22: EUR | E22: 21.8 | F22: 20.85
A23: 43508 | B23: 1 | C23: 1.135115 | D23: EUR | E23: 21.71
A24: 43509 | B24: 1 | C24: 1.135115 | D24: EUR | E24: 20.01
A25: 43510 | B25: 1 | C25: 1.135115 | D25: EUR | E25: 20.86
A26: 43511 | B26: 1 | C26: 1.135115 | D26: EUR | E26: 19.99
A27: 43514 | B27: 1 | C27: 1.135115 | D27: EUR | E27: 20.14 | F27: 19.69
A28: 43515 | B28: 1 | C28: 1.135115 | D28: EUR | E28: 20.26
A29: 43517 | B29: 1 | C29: 1.135115 | D29: EUR | E29: 19.85
A30: 43518 | B30: 1 | C30: 1.135115 | D30: EUR | E30: 18.35
A31: 43521 | B31: 1 | C31: 1.135115 | D31: EUR | E31: 18.62 | F31: 20.83
A32: 43522 | B32: 1 | C32: 1.135115 | D32: EUR | E32: 19.6
A33: 43523 | B33: 1 | C33: 1.135115 | D33: EUR | E33: 20.31
A34: 43524 | B34: 1 | C34: 1.135115 | D34: EUR | E34: 20.9
A35: 43525 | B35: 1 | C35: 1.1302476 | D35: EUR | E35: 21.31
A36: 43528 | B36: 1 | C36: 1.1302476 | D36: EUR | E36: 22.12 | F36: 22.9
A37: 43529 | B37: 1 | C37: 1.1302476 | D37: EUR | E37: 22.86
A38: 43531 | B38: 1 | C38: 1.1302476 | D38: EUR | E38: 22.03
A39: 43532 | B39: 1 | C39: 1.1302476 | D39: EUR | E39: 22.88
A40: 43535 | B40: 1 | C40: 1.1302476 | D40: EUR | E40: 22.6 | F40: 22.42
...

Sheet ETS price EEX 2019 Spot Primary
A1: More information
J2: EEX Emissions market / Primary Market Auction
A3: References | E3: Prices | J3: Volumes | U3: Participants | W3: Revenue | Y3: Revenue
A4: Date | B4: Time | C4: Auction Name | D4: Contract | E4: Auction Price €/tCO2 | F4: Minimum Bid €/tCO2 | G4: Maximum Bid €/tCO2 | H4: Mean €/tCO2 | I4: Median €/tCO2 | J4: Auction Volume tCO2 | K4: Total Amount of Bids | L4: Number of bids submitted | M4: Number of successful bids | N4: Average number of bids per bidder | O4: Average bid size | P4: Average volume bid per bidder | Q4: Standard deviation of bid volume per bidder | R4: Average volume won per bidder | S4: Standard deviation of volume won per bidder | T4: Cover Ratio | U4: Total Number of Bidders | V4: Number of Successful Bidders | W4: Total Revenue € | X4: Country | Y4: Austria (AT) | Z4: Belgium (BE) | AA4: Bulgaria (BG) | AB4: Cyprus (CY) | AC4: Czech Republic (CZ) | AD4: Germany (DE) | AE4: Denmark (DK) | AF4: Estonia (EE) | AG4: Greece (EL) | AH4: Spain (ES) | AI4: Finland (FI) | AJ4: France (FR) | AK4: Croatia (HR) | AL4: Hungary (HU) | AM4: Ireland (IE) | AN4: Iceland (IS) | AO4: Italy (IT) | AP4: Liechtenstein (LI) | AQ4: Lithuania (LT) | AR4: Luxembourg (LU) | AS4: Latvia (LV) | AT4: Malta (MT) | AU4: Netherlands (NL) | AV4: Norway (NO) | AW4: Poland (PL) | AX4: Portugal (PT) | AY4: Romania (RO) | AZ4: Sweden (SE) | BA4: Slovenia (SI) | BB4: Slovakia (SK) | BC4: Innovation Fund
A5: 43815 | B5: 43815.459 | C5: Auction 3. Period CAP2-EU | D5: T3PA | E5: 24.21 | F5: 21 | G5: 26 | H5: 24.09 | I5: 24.05 | J5: 3013000 | K5: 5333000 | L5: 92 | M5: 19 | N5: 4.6 | O5: 57967 | P5: 266650 | Q5: 391858 | R5: 273909 | S5: 289081 | T5: 1.77 | U5: 20 | V5: 11 | W5: 72944730 | X5: EU | Y5: 1658385 | Z5: 2590470 | AA5: 3716235 | AB5: 387360 | AC5: 4866210 | AE5: 1319445 | AF5: 1416285 | AG5: 4188330 | AH5: 9163485 | AI5: 1973115 | AJ5: 5616720 | AK5: 883665 | AL5: 1718910 | AM5: 1392075 | AN5: 508410 | AO5: 9357165 | AP5: 0 | AQ5: 798930 | AR5: 169470 | AS5: 484200 | AT5: 133155 | AU5: 3280455 | AV5: 5761980 | AX5: 2336265 | AY5: 5519880 | AZ5: 1125765 | BA5: 714195 | BB5: 1864170
A6: 43812 | B6: 43812.459 | C6: Auction 3. Period DE | D6: T3PA | E6: 25.33 | F6: 24.76 | G6: 30 | H6: 25.34 | I6: 25.28 | J6: 2840000 | K6: 4827000 | L6: 83 | M6: 27 | N6: 4.37 | O6: 58157 | P6: 254053 | Q6: 331093 | R6: 202857 | S6: 276386 | T6: 1.7 | U6: 19 | V6: 14 | W6: 71937200 | X6: DE | AD6: 71937200
A7: 43811 | B7: 43811.459 | C7: Auction 3. Period CAP2-EU | D7: T3PA | E7: 24.62 | F7: 21 | G7: 26 | H7: 24.48 | I7: 24.42 | J7: 2744000 | K7: 6226500 | L7: 97 | M7: 18 | N7: 4.41 | O7: 64191 | P7: 283023 | Q7: 413993 | R7: 274400 | S7: 240189 | T7: 2.27 | U7: 22 | V7: 10 | W7: 67557280 | X7: EU | Y7: 1354100 | Z7: 2634340 | AA7: 3249840 | AB7: 184650 | AC7: 4653180 | AE7: 1231000 | AF7: 1070970 | AG7: 3717620 | AH7: 9072470 | AI7: 1612610 | AJ7: 5268680 | AK7: 529330 | AL7: 1686470 | AM7: 898630 | AN7: 283130 | AO7: 9454080 | AP7: 0 | AQ7: 615500 | AR7: 123100 | AS7: 307750 | AT7: 123100 | AU7: 3225220 | AV7: 5601050 | AX7: 1883430 | AY7: 5539500 | AZ7: 935560 | BA7: 492400 | BB7: 1809570
A8: 43809 | B8: 43809.459 | C8: Auction 3. Period CAP2-EU | D8: T3PA | E8: 24.98 | F8: 23.99 | G8: 27 | H8: 25.08 | I8: 24.96 | J8: 2744000 | K8: 5103000 | L8: 102 | M8: 43 | N8: 4.25 | O8: 50029 | P8: 212625 | Q8: 401348 | R8: 137200 | S8: 253407 | T8: 1.86 | U8: 24 | V8: 20 | W8: 68545120 | X8: EU | Y8: 1373900 | Z8: 2672860 | AA8: 3297360 | AB8: 187350 | AC8: 4721220 | AE8: 1249000 | AF8: 1086630 | AG8: 3771980 | AH8: 9205130 | AI8: 1636190 | AJ8: 5345720 | AK8: 537070 | AL8: 1711130 | AM8: 911770 | AN8: 287270 | AO8: 9592320 | AP8: 0 | AQ8: 624500 | AR8: 124900 | AS8: 312250 | AT8: 124900 | AU8: 3272380 | AV8: 5682950 | AX8: 1910970 | AY8: 5620500 | AZ8: 949240 | BA8: 499600 | BB8: 1836030
A9: 43808 | B9: 43808.459 | C9: Auction 3. Period CAP2-EU | D9: T3PA | E9: 24.4 | F9: 21 | G9: 26 | H9: 24.3 | I9: 24.37 | J9: 2744000 | K9: 5004000 | L9: 72 | M9: 31 | N9: 4.24 | O9: 69500 | P9: 294353 | Q9: 489700 | R9: 182933 | S9: 270365 | T9: 1.82 | U9: 17 | V9: 15 | W9: 66953600 | X9: EU | Y9: 1342000 | Z9: 2610800 | AA9: 3220800 | AB9: 183000 | AC9: 4611600 | AE9: 1220000 | AF9: 1061400 | AG9: 3684400 | AH9: 8991400 | AI9: 1598200 | AJ9: 5221600 | AK9: 524600 | AL9: 1671400 | AM9: 890600 | AN9: 280600 | AO9: 9369600 | AP9: 0 | AQ9: 610000 | AR9: 122000 | AS9: 305000 | AT9: 122000 | AU9: 3196400 | AV9: 5551000 | AX9: 1866600 | AY9: 5490000 | AZ9: 927200 | BA9: 488000 | BB9: 1793400
A10: 43805 | B10: 43805.459 | C10: Auction 3. Period DE | D10: T3PA | E10: 24.7 | F10: 21 | G10: 26 | H10: 24.62 | I10: 24.66 | J10: 2834500 | K10: 4825000 | L10: 84 | M10: 27 | N10: 4.2 | O10: 57440 | P10: 241250 | Q10: 322738 | R10: 188967 | S10: 203612 | T10: 1.7 | U10: 20 | V10: 15 | W10: 70012150 | X10: DE | AD10: 70012150
A11: 43804 | B11: 43804.459 | C11: Auction 3. Period CAP2-EU | D11: T3PA | E11: 24.5 | F11: 21 | G11: 26 | H11: 24.47 | I11: 24.43 | J11: 2744000 | K11: 5354000 | L11: 92 | M11: 29 | N11: 4.38 | O11: 58196 | P11: 254952 | Q11: 396446 | R11: 182933 | S11: 230405 | T11: 1.95 | U11: 21 | V11: 15 | W11: 67228000 | X11: EU | Y11: 1347500 | Z11: 2621500 | AA11: 3234000 | AB11: 183750 | AC11: 4630500 | AE11: 1225000 | AF11: 1065750 | AG11: 3699500 | AH11: 9028250 | AI11: 1604750 | AJ11: 5243000 | AK11: 526750 | AL11: 1678250 | AM11: 894250 | AN11: 281750 | AO11: 9408000 | AP11: 0 | AQ11: 612500 | AR11: 122500 | AS11: 306250 | AT11: 122500 | AU11: 3209500 | AV11: 5573750 | AX11: 1874250 | AY11: 5512500 | AZ11: 931000 | BA11: 490000 | BB11: 1800750
A12: 43803 | B12: 43803.459 | C12: Auction 3. Period CAP2-PL | D12: T3PA | E12: 24.1 | F12: 21 | G12: 26 | H12: 23.98 | I12: 23.93 | J12: 4717500 | K12: 9654000 | L12: 102 | M12: 23 | N12: 5.1 | O12: 94647 | P12: 482700 | Q12: 711585 | R12: 524167 | S12: 495642 | T12: 2.05 | U12: 20 | V12: 9 | W12: 113691750 | X12: PL | AW12: 113691750
A13: 43802 | B13: 43802.459 | C13: Auction 3. Period CAP2-EU | D13: T3PA | E13: 24.41 | F13: 21 | G13: 30.01 | H13: 24.5 | I13: 24.37 | J13: 2744000 | K13: 4858000 | L13: 92 | M13: 32 | N13: 3.83 | O13: 52804 | P13: 202417 | Q13: 295921 | R13: 137200 | S13: 191560 | T13: 1.77 | U13: 24 | V13: 20 | W13: 66981040 | X13: EU | Y13: 1342550 | Z13: 2611870 | AA13: 3222120 | AB13: 183075 | AC13: 4613490 | AE13: 1220500 | AF13: 1061835 | AG13: 3685910 | AH13: 8995085 | AI13: 1598855 | AJ13: 5223740 | AK13: 524815 | AL13: 1672085 | AM13: 890965 | AN13: 280715 | AO13: 9373440 | AP13: 0 | AQ13: 610250 | AR13: 122050 | AS13: 305125 | AT13: 122050 | AU13: 3197710 | AV13: 5553275 | AX13: 1867365 | AY13: 5492250 | AZ13: 927580 | BA13: 488200 | BB13: 1794135
A14: 43801 | B14: 43801.459 | C14: Auction 3. Period CAP2-EU | D14: T3PA | E14: 24.62 | F14: 21 | G14: 27 | H14: 24.63 | I14: 24.62 | J14: 2744000 | K14: 4298500 | L14: 95 | M14: 43 | N14: 3.96 | O14: 45247 | P14: 179104 | Q14: 301607 | R14: 144421 | S14: 259953 | T14: 1.57 | U14: 24 | V14: 19 | W14: 67557280 | X14: EU | Y14: 1354100 | Z14: 2634340 | AA14: 3249840 | AB14: 184650 | AC14: 4653180 | AE14: 1231000 | AF14: 1070970 | AG14: 3717620 | AH14: 9072470 | AI14: 1612610 | AJ14: 5268680 | AK14: 529330 | AL14: 1686470 | AM14: 898630 | AN14: 283130 | AO14: 9454080 | AP14: 0 | AQ14: 615500 | AR14: 123100 | AS14: 307750 | AT14: 123100 | AU14: 3225220 | AV14: 5601050 | AX14: 1883430 | AY14: 5539500 | AZ14: 935560 | BA14: 492400 | BB14: 1809570
A15: 43798 | B15: 43798.459 | C15: Auction 3. Period DE | D15: T3PA | E15: 25.03 | F15: 21 | G15: 30 | H15: 24.94 | I15: 24.95 | J15: 2834500 | K15: 4833500 | L15: 75 | M15: 17 | N15: 3.75 | O15: 64447 | P15: 241675 | Q15: 363959 | R15: 257682 | S15: 365284 | T15: 1.71 | U15: 20 | V15: 11 | W15: 70947535 | X15: DE | AD15: 70947535
A16: 43797 | B16: 43797.459 | C16: Auction 3. Period CAP2-EU | D16: T3PA | E16: 24.91 | F16: 21 | G16: 30 | H16: 24.96 | I16: 24.95 | J16: 2744000 | K16: 3432000 | L16: 66 | M16: 47 | N16: 3.67 | O16: 52000 | P16: 190667 | Q16: 267948 | R16: 161412 | S16: 218847 | T16: 1.25 | U16: 18 | V16: 17 | W16: 68353040 | X16: EU | Y16: 1370050 | Z16: 2665370 | AA16: 3288120 | AB16: 186825 | AC16: 4707990 | AE16: 1245500 | AF16: 1083585 | AG16: 3761410 | AH16: 9179335 | AI16: 1631605 | AJ16: 5330740 | AK16: 535565 | AL16: 1706335 | AM16: 909215 | AN16: 286465 | AO16: 9565440 | AP16: 0 | AQ16: 622750 | AR16: 124550 | AS16: 311375 | AT16: 124550 | AU16: 3263210 | AV16: 5667025 | AX16: 1905615 | AY16: 5604750 | AZ16: 946580 | BA16: 498200 | BB16: 1830885
A17: 43795 | B17: 43795.459 | C17: Auction 3. Period CAP2-EU | D17: T3PA | E17: 24.29 | F17: 21 | G17: 28 | H17: 24.44 | I17: 24.28 | J17: 2744000 | K17: 4322000 | L17: 70 | M17: 33 | N17: 3.89 | O17: 61743 | P17: 240111 | Q17: 394392 | R17: 171500 | S17: 260578 | T17: 1.58 | U17: 18 | V17: 16 | W17: 66651760 | X17: EU | Y17: 1335950 | Z17: 2599030 | AA17: 3206280 | AB17: 182175 | AC17: 4590810 | AE17: 1214500 | AF17: 1056615 | AG17: 3667790 | AH17: 8950865 | AI17: 1590995 | AJ17: 5198060 | AK17: 522235 | AL17: 1663865 | AM17: 886585 | AN17: 279335 | AO17: 9327360 | AP17: 0 | AQ17: 607250 | AR17: 121450 | AS17: 303625 | AT17: 121450 | AU17: 3181990 | AV17: 5525975 | AX17: 1858185 | AY17: 5465250 | AZ17: 923020 | BA17: 485800 | BB17: 1785315
A18: 43794 | B18: 43794.459 | C18: Auction 3. Period CAP2-EU | D18: T3PA | E18: 24.52 | F18: 21 | G18: 29 | H18: 24.72 | I18: 24.49 | J18: 2744000 | K18: 4337500 | L18: 86 | M18: 32 | N18: 4.1 | O18: 50436 | P18: 206548 | Q18: 364494 | R18: 211077 | S18: 304430 | T18: 1.58 | U18: 21 | V18: 13 | W18: 67282880 | X18: EU | Y18: 1348600 | Z18: 2623640 | AA18: 3236640 | AB18: 183900 | AC18: 4634280 | AE18: 1226000 | AF18: 1066620 | AG18: 3702520 | AH18: 9035620 | AI18: 1606060 | AJ18: 5247280 | AK18: 527180 | AL18: 1679620 | AM18: 894980 | AN18: 281980 | AO18: 9415680 | AP18: 0 | AQ18: 613000 | AR18: 122600 | AS18: 306500 | AT18: 122600 | AU18: 3212120 | AV18: 5578300 | AX18: 1875780 | AY18: 5517000 | AZ18: 931760 | BA18: 490400 | BB18: 1802220
A19: 43791 | B19: 43791.459 | C19: Auction 3. Period DE | D19: T3PA | E19: 24.32 | F19: 21 | G19: 30.01 | H19: 24.38 | I19: 24.29 | J19: 2834500 | K19: 4141500 | L19: 84 | M19: 31 | N19: 4.2 | O19: 49304 | P19: 207075 | Q19: 334700 | R19: 166735 | S19: 290548 | T19: 1.46 | U19: 20 | V19: 17 | W19: 68935040 | X19: DE | AD19: 68935040
A20: 43790 | B20: 43790.459 | C20: Auction 3. Period CAP2-EU | D20: T3PA | E20: 23.96 | F20: 21 | G20: 30 | H20: 23.99 | I20: 23.95 | J20: 2744000 | K20: 4156500 | L20: 93 | M20: 41 | N20: 4.04 | O20: 44694 | P20: 180717 | Q20: 226243 | R20: 137200 | S20: 175491 | T20: 1.51 | U20: 23 | V20: 20 | W20: 65746240 | X20: EU | Y20: 1317800 | Z20: 2563720 | AA20: 3162720 | AB20: 179700 | AC20: 4528440 | AE20: 1198000 | AF20: 1042260 | AG20: 3617960 | AH20: 8829260 | AI20: 1569380 | AJ20: 5127440 | AK20: 515140 | AL20: 1641260 | AM20: 874540 | AN20: 275540 | AO20: 9200640 | AP20: 0 | AQ20: 599000 | AR20: 119800 | AS20: 299500 | AT20: 119800 | AU20: 3138760 | AV20: 5450900 | AX20: 1832940 | AY20: 5391000 | AZ20: 910480 | BA20: 479200 | BB20: 1761060
A21: 43789 | B21: 43789.459 | C21: Auction 3. Period CAP2-PL | D21: T3PA | E21: 23.34 | F21: 21 | G21: 30 | H21: 23.32 | I21: 23.22 | J21: 4714500 | K21: 8406000 | L21: 106 | M21: 25 | N21: 5.05 | O21: 79302 | P21: 400286 | Q21: 475960 | R21: 362654 | S21: 325295 | T21: 1.78 | U21: 21 | V21: 13 | W21: 110036430 | X21: PL | AW21: 110036430
A22: 43788 | B22: 43788.459 | C22: Auction 3. Period CAP2-EU | D22: T3PA | E22: 23.62 | F22: 23.21 | G22: 30 | H22: 23.67 | I22: 23.45 | J22: 2744000 | K22: 5216000 | L22: 96 | M22: 15 | N22: 4.36 | O22: 54333 | P22: 237091 | Q22: 308603 | R22: 228667 | S22: 274099 | T22: 1.9 | U22: 22 | V22: 12 | W22: 64813280 | X22: EU | Y22: 1299100 | Z22: 2527340 | AA22: 3117840 | AB22: 177150 | AC22: 4464180 | AE22: 1181000 | AF22: 1027470 | AG22: 3566620 | AH22: 8703970 | AI22: 1547110 | AJ22: 5054680 | AK22: 507830 | AL22: 1617970 | AM22: 862130 | AN22: 271630 | AO22: 9070080 | AP22: 0 | AQ22: 590500 | AR22: 118100 | AS22: 295250 | AT22: 118100 | AU22: 3094220 | AV22: 5373550 | AX22: 1806930 | AY22: 5314500 | AZ22: 897560 | BA22: 472400 | BB22: 1736070
A23: 43787 | B23: 43787.459 | C23: Auction 3. Period CAP2-EU | D23: T3PA | E23: 23.41 | F23: 21 | G23: 28 | H23: 23.39 | I23: 23.32 | J23: 2744000 | K23: 5689000 | L23: 107 | M23: 29 | N23: 4.12 | O23: 53168 | P23: 218808 | Q23: 336040 | R23: 182933 | S23: 219753 | T23: 2.07 | U23: 26 | V23: 15 | W23: 64237040 | X23: EU | Y23: 1287550 | Z23: 2504870 | AA23: 3090120 | AB23: 175575 | AC23: 4424490 | AE23: 1170500 | AF23: 1018335 | AG23: 3534910 | AH23: 8626585 | AI23: 1533355 | AJ23: 5009740 | AK23: 503315 | AL23: 1603585 | AM23: 854465 | AN23: 269215 | AO23: 8989440 | AP23: 0 | AQ23: 585250 | AR23: 117050 | AS23: 292625 | AT23: 117050 | AU23: 3066710 | AV23: 5325775 | AX23: 1790865 | AY23: 5267250 | AZ23: 889580 | BA23: 468200 | BB23: 1720635
A24: 43784 | B24: 43784.459 | C24: Auction 3. Period DE | D24: T3PA | E24: 23.41 | F24: 21 | G24: 30 | H24: 23.51 | I24: 23.38 | J24: 2834500 | K24: 4691000 | L24: 101 | M24: 40 | N24: 4.59 | O24: 46446 | P24: 213227 | Q24: 217251 | R24: 166735 | S24: 187014 | T24: 1.65 | U24: 22 | V24: 17 | W24: 66355645 | X24: DE | AD24: 66355645
A25: 43783 | B25: 43783.459 | C25: Auction 3. Period CAP2-EU | D25: T3PA | E25: 24.28 | F25: 21 | G25: 30 | H25: 24.45 | I25: 24.22 | J25: 2744000 | K25: 5342500 | L25: 97 | M25: 33 | N25: 4.04 | O25: 55077 | P25: 222604 | Q25: 348420 | R25: 130667 | S25: 156295 | T25: 1.95 | U25: 24 | V25: 21 | W25: 66624320 | X25: EU | Y25: 1335400 | Z25: 2597960 | AA25: 3204960 | AB25: 182100 | AC25: 4588920 | AE25: 1214000 | AF25: 1056180 | AG25: 3666280 | AH25: 8947180 | AI25: 1590340 | AJ25: 5195920 | AK25: 522020 | AL25: 1663180 | AM25: 886220 | AN25: 279220 | AO25: 9323520 | AP25: 0 | AQ25: 607000 | AR25: 121400 | AS25: 303500 | AT25: 121400 | AU25: 3180680 | AV25: 5523700 | AX25: 1857420 | AY25: 5463000 | AZ25: 922640 | BA25: 485600 | BB25: 1784580
A26: 43781 | B26: 43781.459 | C26: Auction 3. Period CAP2-EU | D26: T3PA | E26: 24.95 | F26: 21 | G26: 30 | H26: 25.02 | I26: 24.9 | J26: 2744000 | K26: 4525000 | L26: 93 | M26: 33 | N26: 4.43 | O26: 48656 | P26: 215476 | Q26: 258397 | R26: 161412 | S26: 195897 | T26: 1.65 | U26: 21 | V26: 17 | W26: 68462800 | X26: EU | Y26: 1372250 | Z26: 2669650 | AA26: 3293400 | AB26: 187125 | AC26: 4715550 | AE26: 1247500 | AF26: 1085325 | AG26: 3767450 | AH26: 9194075 | AI26: 1634225 | AJ26: 5339300 | AK26: 536425 | AL26: 1709075 | AM26: 910675 | AN26: 286925 | AO26: 9580800 | AP26: 0 | AQ26: 623750 | AR26: 124750 | AS26: 311875 | AT26: 124750 | AU26: 3268450 | AV26: 5676125 | AX26: 1908675 | AY26: 5613750 | AZ26: 948100 | BA26: 499000 | BB26: 1833825
A27: 43780 | B27: 43780.459 | C27: Auction 3. Period CAP2-EU | D27: T3PA | E27: 25.21 | F27: 21 | G27: 29 | H27: 25.37 | I27: 25.17 | J27: 2744000 | K27: 4884500 | L27: 88 | M27: 28 | N27: 4 | O27: 55506 | P27: 222023 | Q27: 351515 | R27: 196000 | S27: 259584 | T27: 1.78 | U27: 22 | V27: 14 | W27: 69176240 | X27: EU | Y27: 1386550 | Z27: 2697470 | AA27: 3327720 | AB27: 189075 | AC27: 4764690 | AE27: 1260500 | AF27: 1096635 | AG27: 3806710 | AH27: 9289885 | AI27: 1651255 | AJ27: 5394940 | AK27: 542015 | AL27: 1726885 | AM27: 920165 | AN27: 289915 | AO27: 9680640 | AP27: 0 | AQ27: 630250 | AR27: 126050 | AS27: 315125 | AT27: 126050 | AU27: 3302510 | AV27: 5735275 | AX27: 1928565 | AY27: 5672250 | AZ27: 957980 | BA27: 504200 | BB27: 1852935
A28: 43777 | B28: 43777.459 | C28: Auction 3. Period DE | D28: T3PA | E28: 24.62 | F28: 20.51 | G28: 30.01 | H28: 24.42 | I28: 24.55 | J28: 2834500 | K28: 6297500 | L28: 102 | M28: 26 | N28: 4.86 | O28: 61740 | P28: 299881 | Q28: 366294 | R28: 202464 | S28: 238237 | T28: 2.22 | U28: 21 | V28: 14 | W28: 69785390 | X28: DE | AD28: 69785390
A29: 43776 | B29: 43776.459 | C29: Auction 3. Period CAP2-EU | D29: T3PA | E29: 24.86 | F29: 21 | G29: 29 | H29: 24.92 | I29: 24.84 | J29: 2744000 | K29: 5027500 | L29: 95 | M29: 40 | N29: 4.13 | O29: 52921 | P29: 218587 | Q29: 346633 | R29: 144421 | S29: 228020 | T29: 1.83 | U29: 23 | V29: 19 | W29: 68215840 | X29: EU | Y29: 1367300 | Z29: 2660020 | AA29: 3281520 | AB29: 186450 | AC29: 4698540 | AE29: 1243000 | AF29: 1081410 | AG29: 3753860 | AH29: 9160910 | AI29: 1628330 | AJ29: 5320040 | AK29: 534490 | AL29: 1702910 | AM29: 907390 | AN29: 285890 | AO29: 9546240 | AP29: 0 | AQ29: 621500 | AR29: 124300 | AS29: 310750 | AT29: 124300 | AU29: 3256660 | AV29: 5655650 | AX29: 1901790 | AY29: 5593500 | AZ29: 944680 | BA29: 497200 | BB29: 1827210
A30: 43775 | B30: 43775.625 | C30: EUAA Auction CAP2-EU | D30: EAA3 | E30: 25.18 | F30: 24.1 | G30: 25.45 | H30: 24.86 | I30: 25 | J30: 884500 | K30: 3202500 | L30: 75 | M30: 10 | N30: 7.5 | O30: 42700 | P30: 320250 | Q30: 290402 | R30: 176900 | S30: 93504 | T30: 3.62 | U30: 10 | V30: 5 | W30: 22271710 | X30: EU | Y30: 491010 | Z30: 528780 | AA30: 163670 | AB30: 289570 | AC30: 264390 | AE30: 541370 | AF30: 12590 | AG30: 1007200 | AH30: 3336350 | AI30: 453240 | AJ30: 2480230 | AK30: 113310 | AL30: 201440 | AM30: 415470 | AN30: 579140 | AO30: 2958650 | AP30: 0 | AQ30: 37770 | AR30: 25180 | AS30: 88130 | AT30: 138490 | AU30: 717630 | AV30: 5741040 | AX30: 566550 | AY30: 314750 | AZ30: 717630 | BA30: 37770 | BB30: 50360
A31: 43775 | B31: 43775.459 | C31: Auction 3. Period CAP2-PL | D31: T3PA | E31: 25.1 | F31: 21 | G31: 29 | H31: 25.08 | I31: 25.07 | J31: 4714500 | K31: 8190500 | L31: 114 | M31: 41 | N31: 4.56 | O31: 71846 | P31: 327620 | Q31: 451769 | R31: 224500 | S31: 347953 | T31: 1.74 | U31: 25 | V31: 21 | W31: 118333950 | X31: PL | AW31: 118333950
A32: 43774 | B32: 43774.459 | C32: Auction 3. Period CAP2-EU | D32: T3PA | E32: 25.8 | F32: 25.5 | G32: 30 | H32: 25.88 | I32: 25.75 | J32: 2744000 | K32: 4482500 | L32: 75 | M32: 25 | N32: 3.41 | O32: 59767 | P32: 203750 | Q32: 238236 | R32: 161412 | S32: 193036 | T32: 1.63 | U32: 22 | V32: 17 | W32: 70795200 | X32: EU | Y32: 1419000 | Z32: 2760600 | AA32: 3405600 | AB32: 193500 | AC32: 4876200 | AE32: 1290000 | AF32: 1122300 | AG32: 3895800 | AH32: 9507300 | AI32: 1689900 | AJ32: 5521200 | AK32: 554700 | AL32: 1767300 | AM32: 941700 | AN32: 296700 | AO32: 9907200 | AP32: 0 | AQ32: 645000 | AR32: 129000 | AS32: 322500 | AT32: 129000 | AU32: 3379800 | AV32: 5869500 | AX32: 1973700 | AY32: 5805000 | AZ32: 980400 | BA32: 516000 | BB32: 1896300
A33: 43773 | B33: 43773.459 | C33: Auction 3. Period CAP2-EU | D33: T3PA | E33: 24.93 | F33: 21 | G33: 30 | H33: 24.99 | I33: 24.91 | J33: 2744000 | K33: 4806500 | L33: 68 | M33: 30 | N33: 3.09 | O33: 70684 | P33: 218477 | Q33: 314265 | R33: 152444 | S33: 201695 | T33: 1.75 | U33: 22 | V33: 18 | W33: 68407920 | X33: EU | Y33: 1371150 | Z33: 2667510 | AA33: 3290760 | AB33: 186975 | AC33: 4711770 | AE33: 1246500 | AF33: 1084455 | AG33: 3764430 | AH33: 9186705 | AI33: 1632915 | AJ33: 5335020 | AK33: 535995 | AL33: 1707705 | AM33: 909945 | AN33: 286695 | AO33: 9573120 | AP33: 0 | AQ33: 623250 | AR33: 124650 | AS33: 311625 | AT33: 124650 | AU33: 3265830 | AV33: 5671575 | AX33: 1907145 | AY33: 5609250 | AZ33: 947340 | BA33: 498600 | BB33: 1832355
A34: 43770 | B34: 43770.459 | C34: Auction 3. Period DE | D34: T3PA | E34: 25.71 | F34: 25.22 | G34: 30 | H34: 25.8 | I34: 25.61 | J34: 2834500 | K34: 5144000 | L34: 50 | M34: 15 | N34: 3.85 | O34: 102880 | P34: 395692 | Q34: 359214 | R34: 314944 | S34: 257829 | T34: 1.81 | U34: 13 | V34: 9 | W34: 72874995 | X34: DE | AD34: 72874995
A35: 43769 | B35: 43769.459 | C35: Auction 3. Period CAP2-EU | D35: T3PA | E35: 25.95 | F35: 25.6 | G35: 30 | H35: 26.2 | I35: 25.95 | J35: 2744000 | K35: 4333500 | L35: 61 | M35: 31 | N35: 3.39 | O35: 71041 | P35: 240750 | Q35: 326802 | R35: 182933 | S35: 232824 | T35: 1.58 | U35: 18 | V35: 15 | W35: 71206800 | X35: EU | Y35: 1427250 | Z35: 2776650 | AA35: 3425400 | AB35: 194625 | AC35: 4904550 | AE35: 1297500 | AF35: 1128825 | AG35: 3918450 | AH35: 9562575 | AI35: 1699725 | AJ35: 5553300 | AK35: 557925 | AL35: 1777575 | AM35: 947175 | AN35: 298425 | AO35: 9964800 | AP35: 0 | AQ35: 648750 | AR35: 129750 | AS35: 324375 | AT35: 129750 | AU35: 3399450 | AV35: 5903625 | AX35: 1985175 | AY35: 5838750 | AZ35: 986100 | BA35: 519000 | BB35: 1907325
A36: 43767 | B36: 43767.459 | C36: Auction 3. Period CAP2-EU | D36: T3PA | E36: 25.4 | F36: 21 | G36: 30 | H36: 25.37 | I36: 25.21 | J36: 2744000 | K36: 5253500 | L36: 95 | M36: 16 | N36: 3.96 | O36: 55300 | P36: 218896 | Q36: 292925 | R36: 228667 | S36: 254794 | T36: 1.91 | U36: 24 | V36: 12 | W36: 69697600 | X36: EU | Y36: 1397000 | Z36: 2717800 | AA36: 3352800 | AB36: 190500 | AC36: 4800600 | AE36: 1270000 | AF36: 1104900 | AG36: 3835400 | AH36: 9359900 | AI36: 1663700 | AJ36: 5435600 | AK36: 546100 | AL36: 1739900 | AM36: 927100 | AN36: 292100 | AO36: 9753600 | AP36: 0 | AQ36: 635000 | AR36: 127000 | AS36: 317500 | AT36: 127000 | AU36: 3327400 | AV36: 5778500 | AX36: 1943100 | AY36: 5715000 | AZ36: 965200 | BA36: 508000 | BB36: 1866900
A37: 43766 | B37: 43766.459 | C37: Auction 3. Period CAP2-EU | D37: T3PA | E37: 24.68 | F37: 21 | G37: 29 | H37: 24.78 | I37: 24.61 | J37: 2744000 | K37: 4270500 | L37: 94 | M37: 31 | N37: 4.09 | O37: 45431 | P37: 185674 | Q37: 286559 | R37: 171500 | S37: 281456 | T37: 1.56 | U37: 23 | V37: 16 | W37: 67721920 | X37: EU | Y37: 1357400 | Z37: 2640760 | AA37: 3257760 | AB37: 185100 | AC37: 4664520 | AE37: 1234000 | AF37: 1073580 | AG37: 3726680 | AH37: 9094580 | AI37: 1616540 | AJ37: 5281520 | AK37: 530620 | AL37: 1690580 | AM37: 900820 | AN37: 283820 | AO37: 9477120 | AP37: 0 | AQ37: 617000 | AR37: 123400 | AS37: 308500 | AT37: 123400 | AU37: 3233080 | AV37: 5614700 | AX37: 1888020 | AY37: 5553000 | AZ37: 937840 | BA37: 493600 | BB37: 1813980
A38: 43763 | B38: 43763.459 | C38: Auction 3. Period DE | D38: T3PA | E38: 24.86 | F38: 21 | G38: 29 | H38: 24.98 | I38: 24.91 | J38: 2834500 | K38: 4146000 | L38: 73 | M38: 48 | N38: 4.06 | O38: 56795 | P38: 230333 | Q38: 277507 | R38: 166735 | S38: 182748 | T38: 1.46 | U38: 18 | V38: 17 | W38: 70465670 | X38: DE | AD38: 70465670
A39: 43762 | B39: 43762.459 | C39: Auction 3. Period CAP2-EU | D39: T3PA | E39: 24.61 | F39: 21 | G39: 28 | H39: 24.59 | I39: 24.55 | J39: 2744500 | K39: 4239500 | L39: 87 | M39: 35 | N39: 3.78 | O39: 48730 | P39: 184326 | Q39: 226056 | R39: 144447 | S39: 194613 | T39: 1.54 | U39: 23 | V39: 19 | W39: 67542145 | X39: EU | Y39: 1353550 | Z39: 2633270 | AA39: 3248520 | AB39: 184575 | AC39: 4651290 | AE39: 1230500 | AF39: 1070535 | AG39: 3716110 | AH39: 9068785 | AI39: 1611955 | AJ39: 5266540 | AK39: 529115 | AL39: 1685785 | AM39: 898265 | AN39: 283015 | AO39: 9450240 | AP39: 12305 | AQ39: 615250 | AR39: 123050 | AS39: 307625 | AT39: 123050 | AU39: 3223910 | AV39: 5598775 | AX39: 1882665 | AY39: 5537250 | AZ39: 935180 | BA39: 492200 | BB39: 1808835
A40: 43761 | B40: 43761.459 | C40: Auction 3. Period CAP2-PL | D40: T3PA | E40: 25.09 | F40: 21 | G40: 35 | H40: 25.15 | I40: 25.01 | J40: 4714500 | K40: 7667000 | L40: 116 | M40: 34 | N40: 5.04 | O40: 66095 | P40: 333348 | Q40: 536107 | R40: 277324 | S40: 387581 | T40: 1.63 | U40: 23 | V40: 17 | W40: 118286805 | X40: PL | AW40: 118286805
...

Sheet ETS price EEX 2022 Spot Primary
C1: Public
A2: More information
K3: EEX Emissions market / Primary Market Auction
A4: References | F4: Prices | K4: Volumes | V4: Participants | X4: Revenue | Z4: Revenue
A5: Date | B5: Time | C5: Auction Name | D5: Contract | E5: Status | F5: Auction Price €/tCO2 | G5: Minimum Bid €/tCO2 | H5: Maximum Bid €/tCO2 | I5: Mean €/tCO2 | J5: Median €/tCO2 | K5: Auction Volume tCO2 | L5: Total Amount of Bids | M5: Number of bids submitted | N5: Number of successful bids | O5: Average number of bids per bidder | P5: Average bid size | Q5: Average volume bid per bidder | R5: Standard deviation of bid volume per bidder | S5: Average volume won per bidder | T5: Standard deviation of volume won per bidder | U5: Cover Ratio | V5: Total Number of Bidders | W5: Number of Successful Bidders | X5: Total Revenue € | Y5: Country | Z5: Austria (AT) | AA5: Belgium (BE) | AB5: Bulgaria (BG) | AC5: Cyprus (CY) | AD5: Czech Republic (CZ) | AE5: Germany (DE) | AF5: Denmark (DK) | AG5: Estonia (EE) | AH5: Greece (EL) | AI5: Spain (ES) | AJ5: Finland (FI) | AK5: France (FR) | AL5: Croatia (HR) | AM5: Hungary (HU) | AN5: Ireland (IE) | AO5: Innovation Fund (IF) | AP5: Iceland (IS) | AQ5: Italy (IT) | AR5: Liechtenstein (LI) | AS5: Lithuania (LT) | AT5: Luxembourg (LU) | AU5: Latvia (LV) | AV5: Modernisation Fund (MF) | AW5: Malta (MT) | AX5: Netherlands (NL) | AY5: Norway (NO) | AZ5: Poland (PL) | BA5: Portugal (PT) | BB5: Romania (RO) | BC5: Sweden (SE) | BD5: Slovenia (SI) | BE5: Slovakia (SK) | BF5: Northern Ireland (XI)
A6: 44914 | B6: 44914.459 | C6: Auction 4. Period CAP3 EU | D6: T3PA | E6: successful | F6: 84.1 | G6: 75 | H6: 95 | I6: 85.95 | J6: 85.24 | K6: 2568500 | L6: 3235500 | M6: 63 | N6: 57 | O6: 3.94 | P6: 51357 | Q6: 202219 | R6: 276989 | S6: 197577 | T6: 280314 | U6: 1.26 | V6: 16 | W6: 13 | X6: 216010850 | Y6: EU | Z6: 2186600 | AA6: 5340350 | AB6: 9251000 | AC6: 1051250 | AD6: 6223400 | AF6: 3490150 | AG6: 1976350 | AH6: 10470450 | AI6: 25776650 | AJ6: 4457300 | AK6: 15095950 | AL6: 1219450 | AM6: 5760850 | AN6: 0 | AO6: 26071000 | AP6: 0 | AQ6: 26575600 | AR6: 42050 | AS6: 168200 | AT6: 0 | AU6: 1471750 | AV6: 42975100 | AW6: 798950 | AX6: 8704350 | AY6: 1555850 | BA6: 5172150 | BB6: 3700400 | BC6: 1345600 | BD6: 2018400 | BE6: 3111700
A7: 44911 | B7: 44911.459 | C7: Auction 4. Period DE | D7: T3PA | E7: successful | F7: 83.41 | G7: 45 | H7: 92 | I7: 83.57 | J7: 83.7 | K7: 1865500 | L7: 4316500 | M7: 83 | N7: 51 | O7: 4.61 | P7: 52006 | Q7: 239806 | R7: 346218 | S7: 116594 | T7: 153157 | U7: 2.31 | V7: 18 | W7: 16 | X7: 155601355 | Y7: DE | AE7: 155601355
A8: 44910 | B8: 44910.459 | C8: Auction 4. Period CAP3 EU | D8: T3PA | E8: successful | F8: 86.16 | G8: 45 | H8: 92.01 | I8: 85.59 | J8: 86.15 | K8: 2510500 | L8: 4378500 | M8: 66 | N8: 31 | O8: 3.88 | P8: 66341 | Q8: 257559 | R8: 370674 | S8: 179321 | T8: 212582 | U8: 1.74 | V8: 17 | W8: 14 | X8: 216304680 | Y8: EU | Z8: 3187920 | AA8: 5471160 | AB8: 8788320 | AC8: 818520 | AD8: 5815800 | AF8: 2972520 | AG8: 2714040 | AH8: 10770000 | AI8: 26106480 | AJ8: 4221840 | AK8: 15250320 | AL8: 1163160 | AM8: 4954200 | AN8: 0 | AO8: 25331040 | AP8: 0 | AQ8: 26278800 | AR8: 0 | AS8: 861600 | AT8: 0 | AU8: 646200 | AV8: 43295400 | AW8: 301560 | AX8: 9348360 | AY8: 1809360 | BA8: 5428080 | BB8: 4264920 | BC8: 2283240 | BD8: 1378560 | BE8: 2843280
A9: 44908 | B9: 44908.46 | C9: Auction 4. Period CAP3 EU | D9: T3PA | E9: successful | F9: 89.01 | G9: 45 | H9: 95 | I9: 88.13 | J9: 89.02 | K9: 2510500 | L9: 4993500 | M9: 82 | N9: 42 | O9: 4.56 | P9: 60896 | Q9: 277417 | R9: 360612 | S9: 179321 | T9: 214991 | U9: 1.99 | V9: 18 | W9: 14 | X9: 223459605 | Y9: EU | Z9: 3293370 | AA9: 5652135 | AB9: 9079020 | AC9: 845595 | AD9: 6008175 | AF9: 3070845 | AG9: 2803815 | AH9: 11126250 | AI9: 26970030 | AJ9: 4361490 | AK9: 15754770 | AL9: 1201635 | AM9: 5118075 | AN9: 0 | AO9: 26168940 | AP9: 0 | AQ9: 27148050 | AR9: 0 | AS9: 890100 | AT9: 0 | AU9: 667575 | AV9: 44727525 | AW9: 311535 | AX9: 9657585 | AY9: 1869210 | BA9: 5607630 | BB9: 4405995 | BC9: 2358765 | BD9: 1424160 | BE9: 2937330
A10: 44907 | B10: 44907.459 | C10: Auction 4. Period CAP3 EU | D10: T3PA | E10: successful | F10: 88.35 | G10: 65 | H10: 95 | I10: 87.7 | J10: 87.99 | K10: 2510500 | L10: 5522500 | M10: 104 | N10: 39 | O10: 4.95 | P10: 53101 | Q10: 262976 | R10: 365700 | S10: 167367 | T10: 225472 | U10: 2.2 | V10: 21 | W10: 15 | X10: 221802675 | Y10: EU | Z10: 3268950 | AA10: 5610225 | AB10: 9011700 | AC10: 839325 | AD10: 5963625 | AF10: 3048075 | AG10: 2783025 | AH10: 11043750 | AI10: 26770050 | AJ10: 4329150 | AK10: 15637950 | AL10: 1192725 | AM10: 5080125 | AN10: 0 | AO10: 25974900 | AP10: 0 | AQ10: 26946750 | AR10: 0 | AS10: 883500 | AT10: 0 | AU10: 662625 | AV10: 44395875 | AW10: 309225 | AX10: 9585975 | AY10: 1855350 | BA10: 5566050 | BB10: 4373325 | BC10: 2341275 | BD10: 1413600 | BE10: 2915550
A11: 44904 | B11: 44904.459 | C11: Auction 4. Period DE | D11: T3PA | E11: successful | F11: 88.26 | G11: 45 | H11: 96 | I11: 87.14 | J11: 88.21 | K11: 1861500 | L11: 4285000 | M11: 76 | N11: 36 | O11: 4.47 | P11: 56382 | Q11: 252059 | R11: 386495 | S11: 132964 | T11: 262744 | U11: 2.3 | V11: 17 | W11: 14 | X11: 164295990 | Y11: DE | AE11: 164295990
A12: 44903 | B12: 44903.459 | C12: Auction 4. Period CAP3 EU | D12: T3PA | E12: successful | F12: 87.91 | G12: 45 | H12: 92 | I12: 86.72 | J12: 87.51 | K12: 2510500 | L12: 4895000 | M12: 92 | N12: 33 | O12: 4.6 | P12: 53207 | Q12: 244750 | R12: 360524 | S12: 167367 | T12: 219384 | U12: 1.95 | V12: 20 | W12: 15 | X12: 220698055 | Y12: EU | Z12: 3252670 | AA12: 5582285 | AB12: 8966820 | AC12: 835145 | AD12: 5933925 | AF12: 3032895 | AG12: 2769165 | AH12: 10988750 | AI12: 26636730 | AJ12: 4307590 | AK12: 15560070 | AL12: 1186785 | AM12: 5054825 | AN12: 0 | AO12: 25845540 | AP12: 0 | AQ12: 26812550 | AR12: 0 | AS12: 879100 | AT12: 0 | AU12: 659325 | AV12: 44174775 | AW12: 307685 | AX12: 9538235 | AY12: 1846110 | BA12: 5538330 | BB12: 4351545 | BC12: 2329615 | BD12: 1406560 | BE12: 2901030
A13: 44902 | B13: 44902.459 | C13: Auction 4. Period CAP3 PL | D13: T3PA | E13: successful | F13: 87 | G13: 70 | H13: 90 | I13: 87.46 | J13: 87.98 | K13: 3102500 | L13: 3691000 | M13: 72 | N13: 60 | O13: 3.79 | P13: 51264 | Q13: 194263 | R13: 296921 | S13: 172361 | T13: 299141 | U13: 1.19 | V13: 19 | W13: 18 | X13: 269917500 | Y13: PL | AZ13: 269917500
A14: 44901 | B14: 44901.459 | C14: Auction 4. Period CAP3 EU | D14: T3PA | E14: successful | F14: 86.48 | G14: 45 | H14: 89 | I14: 85.5 | J14: 86.34 | K14: 2510500 | L14: 5577500 | M14: 65 | N14: 29 | O14: 3.61 | P14: 85808 | Q14: 309861 | R14: 612950 | S14: 156906 | T14: 307654 | U14: 2.22 | V14: 18 | W14: 16 | X14: 217108040 | Y14: EU | Z14: 3199760 | AA14: 5491480 | AB14: 8820960 | AC14: 821560 | AD14: 5837400 | AF14: 2983560 | AG14: 2724120 | AH14: 10810000 | AI14: 26203440 | AJ14: 4237520 | AK14: 15306960 | AL14: 1167480 | AM14: 4972600 | AN14: 0 | AO14: 25425120 | AP14: 0 | AQ14: 26376400 | AR14: 0 | AS14: 864800 | AT14: 0 | AU14: 648600 | AV14: 43456200 | AW14: 302680 | AX14: 9383080 | AY14: 1816080 | BA14: 5448240 | BB14: 4280760 | BC14: 2291720 | BD14: 1383680 | BE14: 2853840
A15: 44900 | B15: 44900.459 | C15: Auction 4. Period CAP3 EU | D15: T3PA | E15: successful | F15: 85.69 | G15: 45 | H15: 88 | I15: 84.65 | J15: 85.56 | K15: 2510500 | L15: 5270000 | M15: 76 | N15: 32 | O15: 3.8 | P15: 69342 | Q15: 263500 | R15: 403820 | S15: 167367 | T15: 308706 | U15: 2.1 | V15: 20 | W15: 15 | X15: 215124745 | Y15: EU | Z15: 3170530 | AA15: 5441315 | AB15: 8740380 | AC15: 814055 | AD15: 5784075 | AF15: 2956305 | AG15: 2699235 | AH15: 10711250 | AI15: 25964070 | AJ15: 4198810 | AK15: 15167130 | AL15: 1156815 | AM15: 4927175 | AN15: 0 | AO15: 25192860 | AP15: 0 | AQ15: 26135450 | AR15: 0 | AS15: 856900 | AT15: 0 | AU15: 642675 | AV15: 43059225 | AW15: 299915 | AX15: 9297365 | AY15: 1799490 | BA15: 5398470 | BB15: 4241655 | BC15: 2270785 | BD15: 1371040 | BE15: 2827770
A16: 44897 | B16: 44897.459 | C16: Auction 4. Period DE | D16: T3PA | E16: successful | F16: 85.21 | G16: 45 | H16: 88.07 | I16: 84.23 | J16: 85.21 | K16: 1861500 | L16: 4229000 | M16: 69 | N16: 35 | O16: 3.63 | P16: 61290 | Q16: 222579 | R16: 358404 | S16: 132964 | T16: 215757 | U16: 2.27 | V16: 19 | W16: 14 | X16: 158618415 | Y16: DE | AE16: 158618415
A17: 44896 | B17: 44896.459 | C17: Auction 4. Period CAP3 EU | D17: T3PA | E17: successful | F17: 86.11 | G17: 45 | H17: 95 | I17: 85.06 | J17: 86.25 | K17: 2510500 | L17: 5094000 | M17: 73 | N17: 40 | O17: 3.48 | P17: 69781 | Q17: 242571 | R17: 347570 | S17: 147676 | T17: 209970 | U17: 2.03 | V17: 21 | W17: 17 | X17: 216179155 | Y17: EU | Z17: 3186070 | AA17: 5467985 | AB17: 8783220 | AC17: 818045 | AD17: 5812425 | AF17: 2970795 | AG17: 2712465 | AH17: 10763750 | AI17: 26091330 | AJ17: 4219390 | AK17: 15241470 | AL17: 1162485 | AM17: 4951325 | AN17: 0 | AO17: 25316340 | AP17: 0 | AQ17: 26263550 | AR17: 0 | AS17: 861100 | AT17: 0 | AU17: 645825 | AV17: 43270275 | AW17: 301385 | AX17: 9342935 | AY17: 1808310 | BA17: 5424930 | BB17: 4262445 | BC17: 2281915 | BD17: 1377760 | BE17: 2841630
A18: 44894 | B18: 44894.459 | C18: Auction 4. Period CAP3 EU | D18: T3PA | E18: successful | F18: 78.88 | G18: 60 | H18: 88 | I18: 78.42 | J18: 78.48 | K18: 2510500 | L18: 5626000 | M18: 94 | N18: 31 | O18: 4.27 | P18: 59851 | Q18: 255727 | R18: 344183 | S18: 167367 | T18: 204599 | U18: 2.24 | V18: 22 | W18: 15 | X18: 198028240 | Y18: EU | Z18: 2918560 | AA18: 5008880 | AB18: 8045760 | AC18: 749360 | AD18: 5324400 | AF18: 2721360 | AG18: 2484720 | AH18: 9860000 | AI18: 23900640 | AJ18: 3865120 | AK18: 13961760 | AL18: 1064880 | AM18: 4535600 | AN18: 0 | AO18: 23190720 | AP18: 0 | AQ18: 24058400 | AR18: 0 | AS18: 788800 | AT18: 0 | AU18: 591600 | AV18: 39637200 | AW18: 276080 | AX18: 8558480 | AY18: 1656480 | BA18: 4969440 | BB18: 3904560 | BC18: 2090320 | BD18: 1262080 | BE18: 2603040
A19: 44893 | B19: 44893.459 | C19: Auction 4. Period CAP3 EU | D19: T3PA | E19: successful | F19: 77.61 | G19: 45 | H19: 81 | I19: 76.8 | J19: 77.39 | K19: 2510500 | L19: 5072000 | M19: 65 | N19: 25 | O19: 3.61 | P19: 78031 | Q19: 281778 | R19: 385424 | S19: 209208 | T19: 257757 | U19: 2.02 | V19: 18 | W19: 12 | X19: 194839905 | Y19: EU | Z19: 2871570 | AA19: 4928235 | AB19: 7916220 | AC19: 737295 | AD19: 5238675 | AF19: 2677545 | AG19: 2444715 | AH19: 9701250 | AI19: 23515830 | AJ19: 3802890 | AK19: 13736970 | AL19: 1047735 | AM19: 4462575 | AN19: 0 | AO19: 22817340 | AP19: 0 | AQ19: 23671050 | AR19: 0 | AS19: 776100 | AT19: 0 | AU19: 582075 | AV19: 38999025 | AW19: 271635 | AX19: 8420685 | AY19: 1629810 | BA19: 4889430 | BB19: 3841695 | BC19: 2056665 | BD19: 1241760 | BE19: 2561130
A20: 44890 | B20: 44890.459 | C20: Auction 4. Period DE | D20: T3PA | E20: successful | F20: 79.36 | G20: 45 | H20: 82 | I20: 78.56 | J20: 79.11 | K20: 1861500 | L20: 3688000 | M20: 61 | N20: 23 | O20: 3.21 | P20: 60459 | Q20: 194105 | R20: 367077 | S20: 124100 | T20: 241286 | U20: 1.98 | V20: 19 | W20: 15 | X20: 147728640 | Y20: DE | AE20: 147728640
A21: 44889 | B21: 44889.459 | C21: Auction 4. Period CAP3 EU | D21: T3PA | E21: successful | F21: 76.64 | G21: 45 | H21: 84 | I21: 76.05 | J21: 76.19 | K21: 2510500 | L21: 5707000 | M21: 83 | N21: 26 | O21: 4.15 | P21: 68759 | Q21: 285350 | R21: 385430 | S21: 228227 | T21: 256325 | U21: 2.27 | V21: 20 | W21: 11 | X21: 192404720 | Y21: EU | Z21: 2835680 | AA21: 4866640 | AB21: 7817280 | AC21: 728080 | AD21: 5173200 | AF21: 2644080 | AG21: 2414160 | AH21: 9580000 | AI21: 23221920 | AJ21: 3755360 | AK21: 13565280 | AL21: 1034640 | AM21: 4406800 | AN21: 0 | AO21: 22532160 | AP21: 0 | AQ21: 23375200 | AR21: 0 | AS21: 766400 | AT21: 0 | AU21: 574800 | AV21: 38511600 | AW21: 268240 | AX21: 8315440 | AY21: 1609440 | BA21: 4828320 | BB21: 3793680 | BC21: 2030960 | BD21: 1226240 | BE21: 2529120
A22: 44888 | B22: 44888.459 | C22: Auction 4. Period CAP3 PL | D22: T3PA | E22: successful | F22: 74.08 | G22: 45 | H22: 86 | I22: 74.44 | J22: 73.9 | K22: 3101500 | L22: 7498500 | M22: 79 | N22: 34 | O22: 3.95 | P22: 94918 | Q22: 374925 | R22: 775599 | S22: 221536 | T22: 323935 | U22: 2.42 | V22: 20 | W22: 14 | X22: 229759120 | Y22: PL | AZ22: 229759120
A23: 44887 | B23: 44887.459 | C23: Auction 4. Period CAP3 EU | D23: T3PA | E23: successful | F23: 73.54 | G23: 45 | H23: 77.6 | I23: 72.93 | J23: 73.26 | K23: 2510500 | L23: 5360500 | M23: 76 | N23: 29 | O23: 3.8 | P23: 70533 | Q23: 268025 | R23: 380852 | S23: 167367 | T23: 242173 | U23: 2.14 | V23: 20 | W23: 15 | X23: 184622170 | Y23: EU | Z23: 2720980 | AA23: 4669790 | AB23: 7501080 | AC23: 698630 | AD23: 4963950 | AF23: 2537130 | AG23: 2316510 | AH23: 9192500 | AI23: 22282620 | AJ23: 3603460 | AK23: 13016580 | AL23: 992790 | AM23: 4228550 | AN23: 0 | AO23: 21620760 | AP23: 0 | AQ23: 22429700 | AR23: 0 | AS23: 735400 | AT23: 0 | AU23: 551550 | AV23: 36953850 | AW23: 257390 | AX23: 7979090 | AY23: 1544340 | BA23: 4633020 | BB23: 3640230 | BC23: 1948810 | BD23: 1176640 | BE23: 2426820
A24: 44886 | B24: 44886.459 | C24: Auction 4. Period CAP3 EU | D24: T3PA | E24: successful | F24: 73.36 | G24: 45 | H24: 75.9 | I24: 72.73 | J24: 73.16 | K24: 2510500 | L24: 5503000 | M24: 85 | N24: 32 | O24: 3.86 | P24: 64741 | Q24: 250136 | R24: 403422 | S24: 167367 | T24: 315875 | U24: 2.19 | V24: 22 | W24: 15 | X24: 184170280 | Y24: EU | Z24: 2714320 | AA24: 4658360 | AB24: 7482720 | AC24: 696920 | AD24: 4951800 | AF24: 2530920 | AG24: 2310840 | AH24: 9170000 | AI24: 22228080 | AJ24: 3594640 | AK24: 12984720 | AL24: 990360 | AM24: 4218200 | AN24: 0 | AO24: 21567840 | AP24: 0 | AQ24: 22374800 | AR24: 0 | AS24: 733600 | AT24: 0 | AU24: 550200 | AV24: 36863400 | AW24: 256760 | AX24: 7959560 | AY24: 1540560 | BA24: 4621680 | BB24: 3631320 | BC24: 1944040 | BD24: 1173760 | BE24: 2420880
A25: 44883 | B25: 44883.459 | C25: Auction 4. Period DE | D25: T3PA | E25: successful | F25: 72.22 | G25: 60 | H25: 76 | I25: 71.85 | J25: 72.22 | K25: 1861500 | L25: 4667000 | M25: 65 | N25: 33 | O25: 3.61 | P25: 71800 | Q25: 259278 | R25: 452179 | S25: 116344 | T25: 283459 | U25: 2.51 | V25: 18 | W25: 16 | X25: 134437530 | Y25: DE | AE25: 134437530
A26: 44882 | B26: 44882.459 | C26: Auction 4. Period CAP3 EU | D26: T3PA | E26: successful | F26: 73.31 | G26: 45 | H26: 79 | I26: 73.37 | J26: 73.71 | K26: 2510500 | L26: 4054500 | M26: 65 | N26: 50 | O26: 3.82 | P26: 62377 | Q26: 238500 | R26: 410980 | S26: 147676 | T26: 265935 | U26: 1.62 | V26: 17 | W26: 17 | X26: 184044755 | Y26: EU | Z26: 2712470 | AA26: 4655185 | AB26: 7477620 | AC26: 696445 | AD26: 4948425 | AF26: 2529195 | AG26: 2309265 | AH26: 9163750 | AI26: 22212930 | AJ26: 3592190 | AK26: 12975870 | AL26: 989685 | AM26: 4215325 | AN26: 0 | AO26: 21553140 | AP26: 0 | AQ26: 22359550 | AR26: 0 | AS26: 733100 | AT26: 0 | AU26: 549825 | AV26: 36838275 | AW26: 256585 | AX26: 7954135 | AY26: 1539510 | BA26: 4618530 | BB26: 3628845 | BC26: 1942715 | BD26: 1172960 | BE26: 2419230
A27: 44881 | B27: 44881.459 | C27: EUAA Auction CAP3 EU | D27: EAA3 | E27: successful | F27: 74.25 | G27: 72.5 | H27: 75.23 | I27: 74.34 | J27: 74.36 | K27: 602000 | L27: 954000 | M27: 35 | N27: 21 | O27: 5 | P27: 27257 | Q27: 136286 | R27: 195404 | S27: 120400 | T27: 127820 | U27: 1.58 | V27: 7 | W27: 5 | X27: 44698500 | Y27: EU | Z27: 1225125 | AA27: 1522125 | AB27: 556875 | AC27: 445500 | AD27: 556875 | AF27: 1485000 | AG27: 111375 | AH27: 2895750 | AI27: 8241750 | AJ27: 1113750 | AK27: 6199875 | AL27: 482625 | AM27: 594000 | AN27: 1002375 | AP27: 445500 | AQ27: 6756750 | AR27: 0 | AS27: 185625 | AT27: 222750 | AU27: 297000 | AW27: 297000 | AX27: 2413125 | AY27: 2376000 | BA27: 2079000 | BB27: 965250 | BC27: 2041875 | BD27: 37125 | BE27: 148500
A28: 44880 | B28: 44880.459 | C28: Auction 4. Period CAP3 EU | D28: T3PA | E28: successful | F28: 74.93 | G28: 45 | H28: 79 | I28: 74.76 | J28: 75.12 | K28: 2510500 | L28: 4354000 | M28: 69 | N28: 44 | O28: 4.06 | P28: 63101 | Q28: 256118 | R28: 388914 | S28: 167367 | T28: 259294 | U28: 1.73 | V28: 17 | W28: 15 | X28: 188111765 | Y28: EU | Z28: 2772410 | AA28: 4758055 | AB28: 7642860 | AC28: 711835 | AD28: 5057775 | AF28: 2585085 | AG28: 2360295 | AH28: 9366250 | AI28: 22703790 | AJ28: 3671570 | AK28: 13262610 | AL28: 1011555 | AM28: 4308475 | AN28: 0 | AO28: 22029420 | AP28: 0 | AQ28: 22853650 | AR28: 0 | AS28: 749300 | AT28: 0 | AU28: 561975 | AV28: 37652325 | AW28: 262255 | AX28: 8129905 | AY28: 1573530 | BA28: 4720590 | BB28: 3709035 | BC28: 1985645 | BD28: 1198880 | BE28: 2472690
A29: 44879 | B29: 44879.459 | C29: Auction 4. Period CAP3 EU | D29: T3PA | E29: successful | F29: 74.85 | G29: 67.48 | H29: 77.3 | I29: 74.69 | J29: 74.65 | K29: 2510500 | L29: 4926000 | M29: 79 | N29: 29 | O29: 3.95 | P29: 62354 | Q29: 246300 | R29: 423501 | S29: 167367 | T29: 333330 | U29: 1.96 | V29: 20 | W29: 15 | X29: 187910925 | Y29: EU | Z29: 2769450 | AA29: 4752975 | AB29: 7634700 | AC29: 711075 | AD29: 5052375 | AF29: 2582325 | AG29: 2357775 | AH29: 9356250 | AI29: 22679550 | AJ29: 3667650 | AK29: 13248450 | AL29: 1010475 | AM29: 4303875 | AN29: 0 | AO29: 22005900 | AP29: 0 | AQ29: 22829250 | AR29: 0 | AS29: 748500 | AT29: 0 | AU29: 561375 | AV29: 37612125 | AW29: 261975 | AX29: 8121225 | AY29: 1571850 | BA29: 4715550 | BB29: 3705075 | BC29: 1983525 | BD29: 1197600 | BE29: 2470050
A30: 44876 | B30: 44876.459 | C30: Auction 4. Period DE | D30: T3PA | E30: successful | F30: 73.33 | G30: 60 | H30: 75.75 | I30: 73.1 | J30: 73.29 | K30: 1861500 | L30: 4295000 | M30: 71 | N30: 35 | O30: 3.74 | P30: 60493 | Q30: 226053 | R30: 331727 | S30: 116344 | T30: 145222 | U30: 2.31 | V30: 19 | W30: 16 | X30: 136503795 | Y30: DE | AE30: 136503795
A31: 44875 | B31: 44875.459 | C31: Auction 4. Period CAP3 EU | D31: T3PA | E31: successful | F31: 71.62 | G31: 60 | H31: 77 | I31: 70.74 | J31: 70.7 | K31: 2510500 | L31: 5622000 | M31: 74 | N31: 14 | O31: 3.52 | P31: 75973 | Q31: 267714 | R31: 436486 | S31: 313813 | T31: 425868 | U31: 2.24 | V31: 21 | W31: 8 | X31: 179802010 | Y31: EU | Z31: 2649940 | AA31: 4547870 | AB31: 7305240 | AC31: 680390 | AD31: 4834350 | AF31: 2470890 | AG31: 2256030 | AH31: 8952500 | AI31: 21700860 | AJ31: 3509380 | AK31: 12676740 | AL31: 966870 | AM31: 4118150 | AN31: 0 | AO31: 21056280 | AP31: 0 | AQ31: 21844100 | AR31: 0 | AS31: 716200 | AT31: 0 | AU31: 537150 | AV31: 35989050 | AW31: 250670 | AX31: 7770770 | AY31: 1504020 | BA31: 4512060 | BB31: 3545190 | BC31: 1897930 | BD31: 1145920 | BE31: 2363460
A32: 44874 | B32: 44874.459 | C32: Auction 4. Period CAP3 PL | D32: T3PA | E32: successful | F32: 75.35 | G32: 68.02 | H32: 80 | I32: 75.53 | J32: 75.35 | K32: 3101500 | L32: 5108000 | M32: 76 | N32: 39 | O32: 4.47 | P32: 67211 | Q32: 300471 | R32: 468830 | S32: 206767 | T32: 361064 | U32: 1.65 | V32: 17 | W32: 15 | X32: 233698025 | Y32: PL | AZ32: 233698025
A33: 44873 | B33: 44873.459 | C33: Auction 4. Period CAP3 EU | D33: T3PA | E33: successful | F33: 76.02 | G33: 60 | H33: 80 | I33: 76.01 | J33: 76.13 | K33: 2510500 | L33: 4924000 | M33: 72 | N33: 41 | O33: 3.6 | P33: 68389 | Q33: 246200 | R33: 372981 | S33: 147676 | T33: 241130 | U33: 1.96 | V33: 20 | W33: 17 | X33: 190848210 | Y33: EU | Z33: 2812740 | AA33: 4827270 | AB33: 7754040 | AC33: 722190 | AD33: 5131350 | AF33: 2622690 | AG33: 2394630 | AH33: 9502500 | AI33: 23034060 | AJ33: 3724980 | AK33: 13455540 | AL33: 1026270 | AM33: 4371150 | AN33: 0 | AO33: 22349880 | AP33: 0 | AQ33: 23186100 | AR33: 0 | AS33: 760200 | AT33: 0 | AU33: 570150 | AV33: 38200050 | AW33: 266070 | AX33: 8248170 | AY33: 1596420 | BA33: 4789260 | BB33: 3762990 | BC33: 2014530 | BD33: 1216320 | BE33: 2508660
A34: 44872 | B34: 44872.46 | C34: Auction 4. Period CAP3 EU | D34: T3PA | E34: successful | F34: 76.75 | G34: 60 | H34: 79 | I34: 76.09 | J34: 76.28 | K34: 2510500 | L34: 6263500 | M34: 88 | N34: 23 | O34: 4.19 | P34: 71176 | Q34: 298262 | R34: 539582 | S34: 228227 | T34: 255269 | U34: 2.49 | V34: 21 | W34: 11 | X34: 192680875 | Y34: EU | Z34: 2839750 | AA34: 4873625 | AB34: 7828500 | AC34: 729125 | AD34: 5180625 | AF34: 2647875 | AG34: 2417625 | AH34: 9593750 | AI34: 23255250 | AJ34: 3760750 | AK34: 13584750 | AL34: 1036125 | AM34: 4413125 | AN34: 0 | AO34: 22564500 | AP34: 0 | AQ34: 23408750 | AR34: 0 | AS34: 767500 | AT34: 0 | AU34: 575625 | AV34: 38566875 | AW34: 268625 | AX34: 8327375 | AY34: 1611750 | BA34: 4835250 | BB34: 3799125 | BC34: 2033875 | BD34: 1228000 | BE34: 2532750
A35: 44869 | B35: 44869.459 | C35: Auction 4. Period DE | D35: T3PA | E35: successful | F35: 78.14 | G35: 60 | H35: 80.05 | I35: 77.17 | J35: 77.35 | K35: 1861500 | L35: 4360000 | M35: 71 | N35: 14 | O35: 3.55 | P35: 61408 | Q35: 218000 | R35: 340984 | S35: 232688 | T35: 234939 | U35: 2.34 | V35: 20 | W35: 8 | X35: 145457610 | Y35: DE | AE35: 145457610
A36: 44868 | B36: 44868.459 | C36: Auction 4. Period CAP3 EU | D36: T3PA | E36: successful | F36: 76.63 | G36: 45 | H36: 79 | I36: 75.49 | J36: 76.08 | K36: 2510500 | L36: 4429000 | M36: 68 | N36: 15 | O36: 3.58 | P36: 65132 | Q36: 233105 | R36: 271143 | S36: 278944 | T36: 252110 | U36: 1.76 | V36: 19 | W36: 9 | X36: 192379615 | Y36: EU | Z36: 2835310 | AA36: 4866005 | AB36: 7816260 | AC36: 727985 | AD36: 5172525 | AF36: 2643735 | AG36: 2413845 | AH36: 9578750 | AI36: 23218890 | AJ36: 3754870 | AK36: 13563510 | AL36: 1034505 | AM36: 4406225 | AN36: 0 | AO36: 22529220 | AP36: 0 | AQ36: 23372150 | AR36: 0 | AS36: 766300 | AT36: 0 | AU36: 574725 | AV36: 38506575 | AW36: 268205 | AX36: 8314355 | AY36: 1609230 | BA36: 4827690 | BB36: 3793185 | BC36: 2030695 | BD36: 1226080 | BE36: 2528790
A37: 44866 | B37: 44866.459 | C37: Auction 4. Period CAP3 EU | D37: T3PA | E37: successful | F37: 78.76 | G37: 45 | H37: 82 | I37: 78.46 | J37: 78.88 | K37: 2510500 | L37: 4376500 | M37: 63 | N37: 37 | O37: 3.71 | P37: 69468 | Q37: 257441 | R37: 373441 | S37: 147676 | T37: 217253 | U37: 1.74 | V37: 17 | W37: 17 | X37: 197726980 | Y37: EU | Z37: 2914120 | AA37: 5001260 | AB37: 8033520 | AC37: 748220 | AD37: 5316300 | AF37: 2717220 | AG37: 2480940 | AH37: 9845000 | AI37: 23864280 | AJ37: 3859240 | AK37: 13940520 | AL37: 1063260 | AM37: 4528700 | AN37: 0 | AO37: 23155440 | AP37: 0 | AQ37: 24021800 | AR37: 0 | AS37: 787600 | AT37: 0 | AU37: 590700 | AV37: 39576900 | AW37: 275660 | AX37: 8545460 | AY37: 1653960 | BA37: 4961880 | BB37: 3898620 | BC37: 2087140 | BD37: 1260160 | BE37: 2599080
A38: 44865 | B38: 44865.46 | C38: Auction 4. Period CAP3 EU | D38: T3PA | E38: successful | F38: 78.69 | G38: 45 | H38: 85 | I38: 77.89 | J38: 78.57 | K38: 2510500 | L38: 6271500 | M38: 64 | N38: 29 | O38: 3.76 | P38: 97992 | Q38: 368912 | R38: 745631 | S38: 209208 | T38: 284809 | U38: 2.5 | V38: 17 | W38: 12 | X38: 197551245 | Y38: EU | Z38: 2911530 | AA38: 4996815 | AB38: 8026380 | AC38: 747555 | AD38: 5311575 | AF38: 2714805 | AG38: 2478735 | AH38: 9836250 | AI38: 23843070 | AJ38: 3855810 | AK38: 13928130 | AL38: 1062315 | AM38: 4524675 | AN38: 0 | AO38: 23134860 | AP38: 0 | AQ38: 24000450 | AR38: 0 | AS38: 786900 | AT38: 0 | AU38: 590175 | AV38: 39541725 | AW38: 275415 | AX38: 8537865 | AY38: 1652490 | BA38: 4957470 | BB38: 3895155 | BC38: 2085285 | BD38: 1259040 | BE38: 2596770
A39: 44862 | B39: 44862.459 | C39: Auction 4. Period DE | D39: T3PA | E39: successful | F39: 80.76 | G39: 45 | H39: 88 | I39: 80.73 | J39: 81.14 | K39: 1861500 | L39: 4441000 | M39: 64 | N39: 47 | O39: 3.56 | P39: 69391 | Q39: 246722 | R39: 443497 | S39: 109500 | T39: 158299 | U39: 2.39 | V39: 18 | W39: 17 | X39: 150334740 | Y39: DE | AE39: 150334740
A40: 44861 | B40: 44861.459 | C40: Auction 4. Period CAP3 EU | D40: T3PA | E40: successful | F40: 77.1 | G40: 45 | H40: 82 | I40: 76.32 | J40: 76.56 | K40: 2510500 | L40: 4882000 | M40: 78 | N40: 25 | O40: 4.33 | P40: 62590 | Q40: 271222 | R40: 390819 | S40: 228227 | T40: 268231 | U40: 1.94 | V40: 18 | W40: 11 | X40: 193559550 | Y40: EU | Z40: 2852700 | AA40: 4895850 | AB40: 7864200 | AC40: 732450 | AD40: 5204250 | AF40: 2659950 | AG40: 2428650 | AH40: 9637500 | AI40: 23361300 | AJ40: 3777900 | AK40: 13646700 | AL40: 1040850 | AM40: 4433250 | AN40: 0 | AO40: 22667400 | AP40: 0 | AQ40: 23515500 | AR40: 0 | AS40: 771000 | AT40: 0 | AU40: 578250 | AV40: 38742750 | AW40: 269850 | AX40: 8365350 | AY40: 1619100 | BA40: 4857300 | BB40: 3816450 | BC40: 2043150 | BD40: 1233600 | BE40: 2544300
...
