Workbook

Sheet Mapping ETS to NACE All Levels
A1: nace_level | B1: nace_code | C1: nace_label_original | D1: nace_code_combined | E1: nace_label_combined | F1: mapped_uniq_ets_cnt | G1: combined_ets_activities | H1: cleaning_action | I1: ets_activity_code | J1: ets_activity_name_original | K1: ets_activity_code_combined | L1: ets_activity_name_combined | M1: mapped_uniq_nace_cnt | N1: mapping_quality | O1: exclusivity_note
A2: =_xlfn.XLOOKUP(C2,'NACE Rev. All Levels'!$C:$C,'NACE Rev. All Levels'!A:A) -> 3 | B2: =_xlfn.XLOOKUP(C2,'NACE Rev. All Levels'!$C:$C,'NACE Rev. All Levels'!B:B) -> 171 | C2: Manufacture of pulp, paper and paperboard | D2: {=_xlfn.TEXTJOIN(", ",TRUE,_xlfn.UNIQUE(_xlfn._xlws.FILTER(B:B,E:E=E2)))} -> 171 | E2: Manufacture of pulp, paper and paperboard | F2: {=COUNTA(_xlfn.UNIQUE(_xlfn._xlws.FILTER(L:L,E:E=E2)))} -> 1 | G2: Production of pulp, paper and cardboard | H2: Combine ETS activities | I2: =_xlfn.XLOOKUP(J2,'ETS activities'!B:B,'ETS activities'!A:A) -> 35 | J2: Production of pulp | K2: {=_xlfn.TEXTJOIN(", ",TRUE,_xlfn.UNIQUE(_xlfn._xlws.FILTER(I:I,L:L=L2)))} -> 35, 36 | L2: Production of pulp, paper and cardboard | M2: {=COUNTA(_xlfn.UNIQUE(_xlfn._xlws.FILTER(E:E,L:L=L2)))} -> 1 | N2: broad combined | O2: Same NACE level-3 code intentionally reused; aggregate ETS rows to this NACE code before regression
A3: =_xlfn.XLOOKUP(C3,'NACE Rev. All Levels'!$C:$C,'NACE Rev. All Levels'!A:A) -> 3 | B3: =_xlfn.XLOOKUP(C3,'NACE Rev. All Levels'!$C:$C,'NACE Rev. All Levels'!B:B) -> 171 | C3: Manufacture of pulp, paper and paperboard | D3: {=_xlfn.TEXTJOIN(", ",TRUE,_xlfn.UNIQUE(_xlfn._xlws.FILTER(B:B,E:E=E3)))} -> 171 | E3: Manufacture of pulp, paper and paperboard | F3: {=COUNTA(_xlfn.UNIQUE(_xlfn._xlws.FILTER(L:L,E:E=E3)))} -> 1 | G3: Production of pulp, paper and cardboard | H3: Combine ETS activities | I3: =_xlfn.XLOOKUP(J3,'ETS activities'!B:B,'ETS activities'!A:A) -> 36 | J3: Production of paper or cardboard | K3: {=_xlfn.TEXTJOIN(", ",TRUE,_xlfn.UNIQUE(_xlfn._xlws.FILTER(I:I,L:L=L3)))} -> 35, 36 | L3: Production of pulp, paper and cardboard | M3: {=COUNTA(_xlfn.UNIQUE(_xlfn._xlws.FILTER(E:E,L:L=L3)))} -> 1 | N3: broad combined | O3: Same NACE level-3 code intentionally reused; aggregate ETS rows to this NACE code before regression
A4: =_xlfn.XLOOKUP(C4,'NACE Rev. All Levels'!$C:$C,'NACE Rev. All Levels'!A:A) -> 3 | B4: =_xlfn.XLOOKUP(C4,'NACE Rev. All Levels'!$C:$C,'NACE Rev. All Levels'!B:B) -> 191 | C4: Manufacture of coke oven products | D4: {=_xlfn.TEXTJOIN(", ",TRUE,_xlfn.UNIQUE(_xlfn._xlws.FILTER(B:B,E:E=E4)))} -> 191 | E4: Manufacture of coke oven products | F4: {=COUNTA(_xlfn.UNIQUE(_xlfn._xlws.FILTER(L:L,E:E=E4)))} -> 1 | H4: None | I4: =_xlfn.XLOOKUP(J4,'ETS activities'!B:B,'ETS activities'!A:A) -> 22 | J4: Production of coke | K4: {=_xlfn.TEXTJOIN(", ",TRUE,_xlfn.UNIQUE(_xlfn._xlws.FILTER(I:I,L:L=L4)))} -> 22 | L4: Production of coke | M4: {=COUNTA(_xlfn.UNIQUE(_xlfn._xlws.FILTER(E:E,L:L=L4)))} -> 1 | N4: exact | O4: Exclusive NACE level-1-3 code; no selected parent/child overlap
A5: =_xlfn.XLOOKUP(C5,'NACE Rev. All Levels'!$C:$C,'NACE Rev. All Levels'!A:A) -> 3 | B5: =_xlfn.XLOOKUP(C5,'NACE Rev. All Levels'!$C:$C,'NACE Rev. All Levels'!B:B) -> 192 | C5: Manufacture of refined petroleum products | D5: {=_xlfn.TEXTJOIN(", ",TRUE,_xlfn.UNIQUE(_xlfn._xlws.FILTER(B:B,E:E=E5)))} -> 192 | E5: Manufacture of refined petroleum products | F5: {=COUNTA(_xlfn.UNIQUE(_xlfn._xlws.FILTER(L:L,E:E=E5)))} -> 1 | H5: None | I5: =_xlfn.XLOOKUP(J5,'ETS activities'!B:B,'ETS activities'!A:A) -> 21 | J5: Refining of mineral oil | K5: {=_xlfn.TEXTJOIN(", ",TRUE,_xlfn.UNIQUE(_xlfn._xlws.FILTER(I:I,L:L=L5)))} -> 21 | L5: Refining of mineral oil | M5: {=COUNTA(_xlfn.UNIQUE(_xlfn._xlws.FILTER(E:E,L:L=L5)))} -> 1 | N5: exact | O5: Exclusive NACE level-1-3 code; no selected parent/child overlap
A6: =_xlfn.XLOOKUP(C6,'NACE Rev. All Levels'!$C:$C,'NACE Rev. All Levels'!A:A) -> 3 | B6: =_xlfn.XLOOKUP(C6,'NACE Rev. All Levels'!$C:$C,'NACE Rev. All Levels'!B:B) -> 201 | C6: Manufacture of basic chemicals, fertilisers and nitrogen compounds, plastics and synthetic rubber in primary forms | D6: {=_xlfn.TEXTJOIN(", ",TRUE,_xlfn.UNIQUE(_xlfn._xlws.FILTER(B:B,E:E=E6)))} -> 201 | E6: Manufacture of basic chemicals, fertilisers and nitrogen compounds, plastics and synthetic rubber in primary forms | F6: {=COUNTA(_xlfn.UNIQUE(_xlfn._xlws.FILTER(L:L,E:E=E6)))} -> 1 | G6: Production of carbon black, nitric acid, adipic acid, glyoxal and glyoxylic acid, ammonia, bulk chemicals, hydrogen and synthesis gas, soda ash and sodium bicarbonate | H6: Combine ETS activities | I6: =_xlfn.XLOOKUP(J6,'ETS activities'!B:B,'ETS activities'!A:A) -> 37 | J6: Production of carbon black | K6: {=_xlfn.TEXTJOIN(", ",TRUE,_xlfn.UNIQUE(_xlfn._xlws.FILTER(I:I,L:L=L6)))} -> 37, 38, 39, 40, 41, 42, 43, 44 | L6: Production of carbon black, nitric acid, adipic acid, glyoxal and glyoxylic acid, ammonia, bulk chemicals, hydrogen and synthesis gas, soda ash and sodium bicarbonate | M6: {=COUNTA(_xlfn.UNIQUE(_xlfn._xlws.FILTER(E:E,L:L=L6)))} -> 1 | N6: broad combined | O6: Same NACE level-3 code intentionally reused; aggregate ETS rows to this NACE code before regression
A7: =_xlfn.XLOOKUP(C7,'NACE Rev. All Levels'!$C:$C,'NACE Rev. All Levels'!A:A) -> 3 | B7: =_xlfn.XLOOKUP(C7,'NACE Rev. All Levels'!$C:$C,'NACE Rev. All Levels'!B:B) -> 201 | C7: Manufacture of basic chemicals, fertilisers and nitrogen compounds, plastics and synthetic rubber in primary forms | D7: {=_xlfn.TEXTJOIN(", ",TRUE,_xlfn.UNIQUE(_xlfn._xlws.FILTER(B:B,E:E=E7)))} -> 201 | E7: Manufacture of basic chemicals, fertilisers and nitrogen compounds, plastics and synthetic rubber in primary forms | F7: {=COUNTA(_xlfn.UNIQUE(_xlfn._xlws.FILTER(L:L,E:E=E7)))} -> 1 | G7: Production of carbon black, nitric acid, adipic acid, glyoxal and glyoxylic acid, ammonia, bulk chemicals, hydrogen and synthesis gas, soda ash and sodium bicarbonate | H7: Combine ETS activities | I7: =_xlfn.XLOOKUP(J7,'ETS activities'!B:B,'ETS activities'!A:A) -> 38 | J7: Production of nitric acid | K7: {=_xlfn.TEXTJOIN(", ",TRUE,_xlfn.UNIQUE(_xlfn._xlws.FILTER(I:I,L:L=L7)))} -> 37, 38, 39, 40, 41, 42, 43, 44 | L7: Production of carbon black, nitric acid, adipic acid, glyoxal and glyoxylic acid, ammonia, bulk chemicals, hydrogen and synthesis gas, soda ash and sodium bicarbonate | M7: {=COUNTA(_xlfn.UNIQUE(_xlfn._xlws.FILTER(E:E,L:L=L7)))} -> 1 | N7: broad combined | O7: Same NACE level-3 code intentionally reused; aggregate ETS rows to this NACE code before regression
A8: =_xlfn.XLOOKUP(C8,'NACE Rev. All Levels'!$C:$C,'NACE Rev. All Levels'!A:A) -> 3 | B8: =_xlfn.XLOOKUP(C8,'NACE Rev. All Levels'!$C:$C,'NACE Rev. All Levels'!B:B) -> 201 | C8: Manufacture of basic chemicals, fertilisers and nitrogen compounds, plastics and synthetic rubber in primary forms | D8: {=_xlfn.TEXTJOIN(", ",TRUE,_xlfn.UNIQUE(_xlfn._xlws.FILTER(B:B,E:E=E8)))} -> 201 | E8: Manufacture of basic chemicals, fertilisers and nitrogen compounds, plastics and synthetic rubber in primary forms | F8: {=COUNTA(_xlfn.UNIQUE(_xlfn._xlws.FILTER(L:L,E:E=E8)))} -> 1 | G8: Production of carbon black, nitric acid, adipic acid, glyoxal and glyoxylic acid, ammonia, bulk chemicals, hydrogen and synthesis gas, soda ash and sodium bicarbonate | H8: Combine ETS activities | I8: =_xlfn.XLOOKUP(J8,'ETS activities'!B:B,'ETS activities'!A:A) -> 39 | J8: Production of adipic acid | K8: {=_xlfn.TEXTJOIN(", ",TRUE,_xlfn.UNIQUE(_xlfn._xlws.FILTER(I:I,L:L=L8)))} -> 37, 38, 39, 40, 41, 42, 43, 44 | L8: Production of carbon black, nitric acid, adipic acid, glyoxal and glyoxylic acid, ammonia, bulk chemicals, hydrogen and synthesis gas, soda ash and sodium bicarbonate | M8: {=COUNTA(_xlfn.UNIQUE(_xlfn._xlws.FILTER(E:E,L:L=L8)))} -> 1 | N8: broad combined | O8: Same NACE level-3 code intentionally reused; aggregate ETS rows to this NACE code before regression
A9: =_xlfn.XLOOKUP(C9,'NACE Rev. All Levels'!$C:$C,'NACE Rev. All Levels'!A:A) -> 3 | B9: =_xlfn.XLOOKUP(C9,'NACE Rev. All Levels'!$C:$C,'NACE Rev. All Levels'!B:B) -> 201 | C9: Manufacture of basic chemicals, fertilisers and nitrogen compounds, plastics and synthetic rubber in primary forms | D9: {=_xlfn.TEXTJOIN(", ",TRUE,_xlfn.UNIQUE(_xlfn._xlws.FILTER(B:B,E:E=E9)))} -> 201 | E9: Manufacture of basic chemicals, fertilisers and nitrogen compounds, plastics and synthetic rubber in primary forms | F9: {=COUNTA(_xlfn.UNIQUE(_xlfn._xlws.FILTER(L:L,E:E=E9)))} -> 1 | G9: Production of carbon black, nitric acid, adipic acid, glyoxal and glyoxylic acid, ammonia, bulk chemicals, hydrogen and synthesis gas, soda ash and sodium bicarbonate | H9: Combine ETS activities | I9: =_xlfn.XLOOKUP(J9,'ETS activities'!B:B,'ETS activities'!A:A) -> 40 | J9: Production of glyoxal and glyoxylic acid | K9: {=_xlfn.TEXTJOIN(", ",TRUE,_xlfn.UNIQUE(_xlfn._xlws.FILTER(I:I,L:L=L9)))} -> 37, 38, 39, 40, 41, 42, 43, 44 | L9: Production of carbon black, nitric acid, adipic acid, glyoxal and glyoxylic acid, ammonia, bulk chemicals, hydrogen and synthesis gas, soda ash and sodium bicarbonate | M9: {=COUNTA(_xlfn.UNIQUE(_xlfn._xlws.FILTER(E:E,L:L=L9)))} -> 1 | N9: broad combined | O9: Same NACE level-3 code intentionally reused; aggregate ETS rows to this NACE code before regression
A10: =_xlfn.XLOOKUP(C10,'NACE Rev. All Levels'!$C:$C,'NACE Rev. All Levels'!A:A) -> 3 | B10: =_xlfn.XLOOKUP(C10,'NACE Rev. All Levels'!$C:$C,'NACE Rev. All Levels'!B:B) -> 201 | C10: Manufacture of basic chemicals, fertilisers and nitrogen compounds, plastics and synthetic rubber in primary forms | D10: {=_xlfn.TEXTJOIN(", ",TRUE,_xlfn.UNIQUE(_xlfn._xlws.FILTER(B:B,E:E=E10)))} -> 201 | E10: Manufacture of basic chemicals, fertilisers and nitrogen compounds, plastics and synthetic rubber in primary forms | F10: {=COUNTA(_xlfn.UNIQUE(_xlfn._xlws.FILTER(L:L,E:E=E10)))} -> 1 | G10: Production of carbon black, nitric acid, adipic acid, glyoxal and glyoxylic acid, ammonia, bulk chemicals, hydrogen and synthesis gas, soda ash and sodium bicarbonate | H10: Combine ETS activities | I10: =_xlfn.XLOOKUP(J10,'ETS activities'!B:B,'ETS activities'!A:A) -> 41 | J10: Production of ammonia | K10: {=_xlfn.TEXTJOIN(", ",TRUE,_xlfn.UNIQUE(_xlfn._xlws.FILTER(I:I,L:L=L10)))} -> 37, 38, 39, 40, 41, 42, 43, 44 | L10: Production of carbon black, nitric acid, adipic acid, glyoxal and glyoxylic acid, ammonia, bulk chemicals, hydrogen and synthesis gas, soda ash and sodium bicarbonate | M10: {=COUNTA(_xlfn.UNIQUE(_xlfn._xlws.FILTER(E:E,L:L=L10)))} -> 1 | N10: broad combined | O10: Same NACE level-3 code intentionally reused; aggregate ETS rows to this NACE code before regression
A11: =_xlfn.XLOOKUP(C11,'NACE Rev. All Levels'!$C:$C,'NACE Rev. All Levels'!A:A) -> 3 | B11: =_xlfn.XLOOKUP(C11,'NACE Rev. All Levels'!$C:$C,'NACE Rev. All Levels'!B:B) -> 201 | C11: Manufacture of basic chemicals, fertilisers and nitrogen compounds, plastics and synthetic rubber in primary forms | D11: {=_xlfn.TEXTJOIN(", ",TRUE,_xlfn.UNIQUE(_xlfn._xlws.FILTER(B:B,E:E=E11)))} -> 201 | E11: Manufacture of basic chemicals, fertilisers and nitrogen compounds, plastics and synthetic rubber in primary forms | F11: {=COUNTA(_xlfn.UNIQUE(_xlfn._xlws.FILTER(L:L,E:E=E11)))} -> 1 | G11: Production of carbon black, nitric acid, adipic acid, glyoxal and glyoxylic acid, ammonia, bulk chemicals, hydrogen and synthesis gas, soda ash and sodium bicarbonate | H11: Combine ETS activities | I11: =_xlfn.XLOOKUP(J11,'ETS activities'!B:B,'ETS activities'!A:A) -> 42 | J11: Production of bulk chemicals | K11: {=_xlfn.TEXTJOIN(", ",TRUE,_xlfn.UNIQUE(_xlfn._xlws.FILTER(I:I,L:L=L11)))} -> 37, 38, 39, 40, 41, 42, 43, 44 | L11: Production of carbon black, nitric acid, adipic acid, glyoxal and glyoxylic acid, ammonia, bulk chemicals, hydrogen and synthesis gas, soda ash and sodium bicarbonate | M11: {=COUNTA(_xlfn.UNIQUE(_xlfn._xlws.FILTER(E:E,L:L=L11)))} -> 1 | N11: broad combined | O11: Same NACE level-3 code intentionally reused; aggregate ETS rows to this NACE code before regression
A12: =_xlfn.XLOOKUP(C12,'NACE Rev. All Levels'!$C:$C,'NACE Rev. All Levels'!A:A) -> 3 | B12: =_xlfn.XLOOKUP(C12,'NACE Rev. All Levels'!$C:$C,'NACE Rev. All Levels'!B:B) -> 201 | C12: Manufacture of basic chemicals, fertilisers and nitrogen compounds, plastics and synthetic rubber in primary forms | D12: {=_xlfn.TEXTJOIN(", ",TRUE,_xlfn.UNIQUE(_xlfn._xlws.FILTER(B:B,E:E=E12)))} -> 201 | E12: Manufacture of basic chemicals, fertilisers and nitrogen compounds, plastics and synthetic rubber in primary forms | F12: {=COUNTA(_xlfn.UNIQUE(_xlfn._xlws.FILTER(L:L,E:E=E12)))} -> 1 | G12: Production of carbon black, nitric acid, adipic acid, glyoxal and glyoxylic acid, ammonia, bulk chemicals, hydrogen and synthesis gas, soda ash and sodium bicarbonate | H12: Combine ETS activities | I12: =_xlfn.XLOOKUP(J12,'ETS activities'!B:B,'ETS activities'!A:A) -> 43 | J12: Production of hydrogen and synthesis gas | K12: {=_xlfn.TEXTJOIN(", ",TRUE,_xlfn.UNIQUE(_xlfn._xlws.FILTER(I:I,L:L=L12)))} -> 37, 38, 39, 40, 41, 42, 43, 44 | L12: Production of carbon black, nitric acid, adipic acid, glyoxal and glyoxylic acid, ammonia, bulk chemicals, hydrogen and synthesis gas, soda ash and sodium bicarbonate | M12: {=COUNTA(_xlfn.UNIQUE(_xlfn._xlws.FILTER(E:E,L:L=L12)))} -> 1 | N12: broad combined | O12: Same NACE level-3 code intentionally reused; aggregate ETS rows to this NACE code before regression
A13: =_xlfn.XLOOKUP(C13,'NACE Rev. All Levels'!$C:$C,'NACE Rev. All Levels'!A:A) -> 3 | B13: =_xlfn.XLOOKUP(C13,'NACE Rev. All Levels'!$C:$C,'NACE Rev. All Levels'!B:B) -> 201 | C13: Manufacture of basic chemicals, fertilisers and nitrogen compounds, plastics and synthetic rubber in primary forms | D13: {=_xlfn.TEXTJOIN(", ",TRUE,_xlfn.UNIQUE(_xlfn._xlws.FILTER(B:B,E:E=E13)))} -> 201 | E13: Manufacture of basic chemicals, fertilisers and nitrogen compounds, plastics and synthetic rubber in primary forms | F13: {=COUNTA(_xlfn.UNIQUE(_xlfn._xlws.FILTER(L:L,E:E=E13)))} -> 1 | G13: Production of carbon black, nitric acid, adipic acid, glyoxal and glyoxylic acid, ammonia, bulk chemicals, hydrogen and synthesis gas, soda ash and sodium bicarbonate | H13: Combine ETS activities | I13: =_xlfn.XLOOKUP(J13,'ETS activities'!B:B,'ETS activities'!A:A) -> 44 | J13: Production of soda ash and sodium bicarbonate | K13: {=_xlfn.TEXTJOIN(", ",TRUE,_xlfn.UNIQUE(_xlfn._xlws.FILTER(I:I,L:L=L13)))} -> 37, 38, 39, 40, 41, 42, 43, 44 | L13: Production of carbon black, nitric acid, adipic acid, glyoxal and glyoxylic acid, ammonia, bulk chemicals, hydrogen and synthesis gas, soda ash and sodium bicarbonate | M13: {=COUNTA(_xlfn.UNIQUE(_xlfn._xlws.FILTER(E:E,L:L=L13)))} -> 1 | N13: broad combined | O13: Same NACE level-3 code intentionally reused; aggregate ETS rows to this NACE code before regression
A14: =_xlfn.XLOOKUP(C14,'NACE Rev. All Levels'!$C:$C,'NACE Rev. All Levels'!A:A) -> 3 | B14: =_xlfn.XLOOKUP(C14,'NACE Rev. All Levels'!$C:$C,'NACE Rev. All Levels'!B:B) -> 231 | C14: Manufacture of glass and glass products | D14: {=_xlfn.TEXTJOIN(", ",TRUE,_xlfn.UNIQUE(_xlfn._xlws.FILTER(B:B,E:E=E14)))} -> 231 | E14: Manufacture of glass and glass products | F14: {=COUNTA(_xlfn.UNIQUE(_xlfn._xlws.FILTER(L:L,E:E=E14)))} -> 1 | H14: None | I14: =_xlfn.XLOOKUP(J14,'ETS activities'!B:B,'ETS activities'!A:A) -> 31 | J14: Manufacture of glass | K14: {=_xlfn.TEXTJOIN(", ",TRUE,_xlfn.UNIQUE(_xlfn._xlws.FILTER(I:I,L:L=L14)))} -> 31 | L14: Manufacture of glass | M14: {=COUNTA(_xlfn.UNIQUE(_xlfn._xlws.FILTER(E:E,L:L=L14)))} -> 1 | N14: good | O14: Exclusive NACE level-1-3 code; no selected parent/child overlap
A15: =_xlfn.XLOOKUP(C15,'NACE Rev. All Levels'!$C:$C,'NACE Rev. All Levels'!A:A) -> 3 | B15: =_xlfn.XLOOKUP(C15,'NACE Rev. All Levels'!$C:$C,'NACE Rev. All Levels'!B:B) -> 232 | C15: Manufacture of refractory products | D15: {=_xlfn.TEXTJOIN(", ",TRUE,_xlfn.UNIQUE(_xlfn._xlws.FILTER(B:B,E:E=E15)))} -> 232, 233, 234 | E15: Manufacture of refractory products, clay building materials, other porcelain and ceramic products | F15: {=COUNTA(_xlfn.UNIQUE(_xlfn._xlws.FILTER(L:L,E:E=E15)))} -> 1 | H15: Combine NACE cat | I15: =_xlfn.XLOOKUP(J15,'ETS activities'!B:B,'ETS activities'!A:A) -> 32 | J15: Manufacture of ceramics | K15: {=_xlfn.TEXTJOIN(", ",TRUE,_xlfn.UNIQUE(_xlfn._xlws.FILTER(I:I,L:L=L15)))} -> 32 | L15: Manufacture of ceramics | M15: {=COUNTA(_xlfn.UNIQUE(_xlfn._xlws.FILTER(E:E,L:L=L15)))} -> 1 | N15: good | O15: ETS activity is broader than selected NACE level-3 categories; sum NACE rows before regression
A16: =_xlfn.XLOOKUP(C16,'NACE Rev. All Levels'!$C:$C,'NACE Rev. All Levels'!A:A) -> 3 | B16: =_xlfn.XLOOKUP(C16,'NACE Rev. All Levels'!$C:$C,'NACE Rev. All Levels'!B:B) -> 233 | C16: Manufacture of clay building materials | D16: {=_xlfn.TEXTJOIN(", ",TRUE,_xlfn.UNIQUE(_xlfn._xlws.FILTER(B:B,E:E=E16)))} -> 232, 233, 234 | E16: Manufacture of refractory products, clay building materials, other porcelain and ceramic products | F16: {=COUNTA(_xlfn.UNIQUE(_xlfn._xlws.FILTER(L:L,E:E=E16)))} -> 1 | H16: Combine NACE cat | I16: =_xlfn.XLOOKUP(J16,'ETS activities'!B:B,'ETS activities'!A:A) -> 32 | J16: Manufacture of ceramics | K16: {=_xlfn.TEXTJOIN(", ",TRUE,_xlfn.UNIQUE(_xlfn._xlws.FILTER(I:I,L:L=L16)))} -> 32 | L16: Manufacture of ceramics | M16: {=COUNTA(_xlfn.UNIQUE(_xlfn._xlws.FILTER(E:E,L:L=L16)))} -> 1 | N16: good | O16: ETS activity is broader than selected NACE level-3 categories; sum NACE rows before regression
A17: =_xlfn.XLOOKUP(C17,'NACE Rev. All Levels'!$C:$C,'NACE Rev. All Levels'!A:A) -> 3 | B17: =_xlfn.XLOOKUP(C17,'NACE Rev. All Levels'!$C:$C,'NACE Rev. All Levels'!B:B) -> 234 | C17: Manufacture of other porcelain and ceramic products | D17: {=_xlfn.TEXTJOIN(", ",TRUE,_xlfn.UNIQUE(_xlfn._xlws.FILTER(B:B,E:E=E17)))} -> 232, 233, 234 | E17: Manufacture of refractory products, clay building materials, other porcelain and ceramic products | F17: {=COUNTA(_xlfn.UNIQUE(_xlfn._xlws.FILTER(L:L,E:E=E17)))} -> 1 | H17: Combine NACE cat | I17: =_xlfn.XLOOKUP(J17,'ETS activities'!B:B,'ETS activities'!A:A) -> 32 | J17: Manufacture of ceramics | K17: {=_xlfn.TEXTJOIN(", ",TRUE,_xlfn.UNIQUE(_xlfn._xlws.FILTER(I:I,L:L=L17)))} -> 32 | L17: Manufacture of ceramics | M17: {=COUNTA(_xlfn.UNIQUE(_xlfn._xlws.FILTER(E:E,L:L=L17)))} -> 1 | N17: good | O17: ETS activity is broader than selected NACE level-3 categories; sum NACE rows before regression
A18: =_xlfn.XLOOKUP(C18,'NACE Rev. All Levels'!$C:$C,'NACE Rev. All Levels'!A:A) -> 3 | B18: =_xlfn.XLOOKUP(C18,'NACE Rev. All Levels'!$C:$C,'NACE Rev. All Levels'!B:B) -> 235 | C18: Manufacture of cement, lime and plaster | D18: {=_xlfn.TEXTJOIN(", ",TRUE,_xlfn.UNIQUE(_xlfn._xlws.FILTER(B:B,E:E=E18)))} -> 235 | E18: Manufacture of cement, lime and plaster | F18: {=COUNTA(_xlfn.UNIQUE(_xlfn._xlws.FILTER(L:L,E:E=E18)))} -> 1 | G18: Production of cement clinker and lime | H18: Combine ETS activities | I18: =_xlfn.XLOOKUP(J18,'ETS activities'!B:B,'ETS activities'!A:A) -> 29 | J18: Production of cement clinker | K18: {=_xlfn.TEXTJOIN(", ",TRUE,_xlfn.UNIQUE(_xlfn._xlws.FILTER(I:I,L:L=L18)))} -> 29, 30 | L18: Production of cement clinker and lime | M18: {=COUNTA(_xlfn.UNIQUE(_xlfn._xlws.FILTER(E:E,L:L=L18)))} -> 1 | N18: broad combined | O18: Same NACE level-3 code intentionally reused; aggregate ETS rows to this NACE code before regression
A19: =_xlfn.XLOOKUP(C19,'NACE Rev. All Levels'!$C:$C,'NACE Rev. All Levels'!A:A) -> 3 | B19: =_xlfn.XLOOKUP(C19,'NACE Rev. All Levels'!$C:$C,'NACE Rev. All Levels'!B:B) -> 235 | C19: Manufacture of cement, lime and plaster | D19: {=_xlfn.TEXTJOIN(", ",TRUE,_xlfn.UNIQUE(_xlfn._xlws.FILTER(B:B,E:E=E19)))} -> 235 | E19: Manufacture of cement, lime and plaster | F19: {=COUNTA(_xlfn.UNIQUE(_xlfn._xlws.FILTER(L:L,E:E=E19)))} -> 1 | G19: Production of cement clinker and lime | H19: Combine ETS activities | I19: =_xlfn.XLOOKUP(J19,'ETS activities'!B:B,'ETS activities'!A:A) -> 30 | J19: Production of lime, or calcination of dolomite/magnesite | K19: {=_xlfn.TEXTJOIN(", ",TRUE,_xlfn.UNIQUE(_xlfn._xlws.FILTER(I:I,L:L=L19)))} -> 29, 30 | L19: Production of cement clinker and lime | M19: {=COUNTA(_xlfn.UNIQUE(_xlfn._xlws.FILTER(E:E,L:L=L19)))} -> 1 | N19: broad combined | O19: Same NACE level-3 code intentionally reused; aggregate ETS rows to this NACE code before regression
A20: =_xlfn.XLOOKUP(C20,'NACE Rev. All Levels'!$C:$C,'NACE Rev. All Levels'!A:A) -> 3 | B20: =_xlfn.XLOOKUP(C20,'NACE Rev. All Levels'!$C:$C,'NACE Rev. All Levels'!B:B) -> 236 | C20: Manufacture of articles of concrete, cement and plaster | D20: {=_xlfn.TEXTJOIN(", ",TRUE,_xlfn.UNIQUE(_xlfn._xlws.FILTER(B:B,E:E=E20)))} -> 236 | E20: Manufacture of articles of concrete, cement and plaster | F20: {=COUNTA(_xlfn.UNIQUE(_xlfn._xlws.FILTER(L:L,E:E=E20)))} -> 1 | H20: None | I20: =_xlfn.XLOOKUP(J20,'ETS activities'!B:B,'ETS activities'!A:A) -> 34 | J20: Production or processing of gypsum or plasterboard | K20: {=_xlfn.TEXTJOIN(", ",TRUE,_xlfn.UNIQUE(_xlfn._xlws.FILTER(I:I,L:L=L20)))} -> 34 | L20: Production or processing of gypsum or plasterboard | M20: {=COUNTA(_xlfn.UNIQUE(_xlfn._xlws.FILTER(E:E,L:L=L20)))} -> 1 | N20: approximate | O20: Exclusive NACE level-1-3 code; no selected parent/child overlap
A21: =_xlfn.XLOOKUP(C21,'NACE Rev. All Levels'!$C:$C,'NACE Rev. All Levels'!A:A) -> 3 | B21: =_xlfn.XLOOKUP(C21,'NACE Rev. All Levels'!$C:$C,'NACE Rev. All Levels'!B:B) -> 239 | C21: Manufacture of abrasive products and non-metallic mineral products n.e.c. | D21: {=_xlfn.TEXTJOIN(", ",TRUE,_xlfn.UNIQUE(_xlfn._xlws.FILTER(B:B,E:E=E21)))} -> 239 | E21: Manufacture of abrasive products and non-metallic mineral products n.e.c. | F21: {=COUNTA(_xlfn.UNIQUE(_xlfn._xlws.FILTER(L:L,E:E=E21)))} -> 1 | H21: None | I21: =_xlfn.XLOOKUP(J21,'ETS activities'!B:B,'ETS activities'!A:A) -> 33 | J21: Manufacture of mineral wool | K21: {=_xlfn.TEXTJOIN(", ",TRUE,_xlfn.UNIQUE(_xlfn._xlws.FILTER(I:I,L:L=L21)))} -> 33 | L21: Manufacture of mineral wool | M21: {=COUNTA(_xlfn.UNIQUE(_xlfn._xlws.FILTER(E:E,L:L=L21)))} -> 1 | N21: approximate | O21: Exclusive NACE level-1-3 code; no selected parent/child overlap
A22: =_xlfn.XLOOKUP(C22,'NACE Rev. All Levels'!$C:$C,'NACE Rev. All Levels'!A:A) -> 3 | B22: =_xlfn.XLOOKUP(C22,'NACE Rev. All Levels'!$C:$C,'NACE Rev. All Levels'!B:B) -> 241 | C22: Manufacture of basic iron and steel and of ferro-alloys | D22: {=_xlfn.TEXTJOIN(", ",TRUE,_xlfn.UNIQUE(_xlfn._xlws.FILTER(B:B,E:E=E22)))} -> 241 | E22: Manufacture of basic iron and steel and of ferro-alloys | F22: {=COUNTA(_xlfn.UNIQUE(_xlfn._xlws.FILTER(L:L,E:E=E22)))} -> 1 | G22: Metal ore roasting/sintering and production of pig iron/steel | H22: Combine ETS activities | I22: =_xlfn.XLOOKUP(J22,'ETS activities'!B:B,'ETS activities'!A:A) -> 23 | J22: Metal ore roasting or sintering | K22: {=_xlfn.TEXTJOIN(", ",TRUE,_xlfn.UNIQUE(_xlfn._xlws.FILTER(I:I,L:L=L22)))} -> 23, 24 | L22: Metal ore roasting/sintering and production of pig iron/steel | M22: {=COUNTA(_xlfn.UNIQUE(_xlfn._xlws.FILTER(E:E,L:L=L22)))} -> 1 | N22: good | O22: Same NACE level-3 code intentionally reused; aggregate ETS rows to this NACE code before regression
A23: =_xlfn.XLOOKUP(C23,'NACE Rev. All Levels'!$C:$C,'NACE Rev. All Levels'!A:A) -> 3 | B23: =_xlfn.XLOOKUP(C23,'NACE Rev. All Levels'!$C:$C,'NACE Rev. All Levels'!B:B) -> 241 | C23: Manufacture of basic iron and steel and of ferro-alloys | D23: {=_xlfn.TEXTJOIN(", ",TRUE,_xlfn.UNIQUE(_xlfn._xlws.FILTER(B:B,E:E=E23)))} -> 241 | E23: Manufacture of basic iron and steel and of ferro-alloys | F23: {=COUNTA(_xlfn.UNIQUE(_xlfn._xlws.FILTER(L:L,E:E=E23)))} -> 1 | G23: Metal ore roasting/sintering and production of pig iron/steel | H23: Combine ETS activities | I23: =_xlfn.XLOOKUP(J23,'ETS activities'!B:B,'ETS activities'!A:A) -> 24 | J23: Production of pig iron or steel | K23: {=_xlfn.TEXTJOIN(", ",TRUE,_xlfn.UNIQUE(_xlfn._xlws.FILTER(I:I,L:L=L23)))} -> 23, 24 | L23: Metal ore roasting/sintering and production of pig iron/steel | M23: {=COUNTA(_xlfn.UNIQUE(_xlfn._xlws.FILTER(E:E,L:L=L23)))} -> 1 | N23: good | O23: Same NACE level-3 code intentionally reused; aggregate ETS rows to this NACE code before regression
A24: =_xlfn.XLOOKUP(C24,'NACE Rev. All Levels'!$C:$C,'NACE Rev. All Levels'!A:A) -> 3 | B24: =_xlfn.XLOOKUP(C24,'NACE Rev. All Levels'!$C:$C,'NACE Rev. All Levels'!B:B) -> 242 | C24: Manufacture of tubes, pipes, hollow profiles and related fittings, of steel | D24: {=_xlfn.TEXTJOIN(", ",TRUE,_xlfn.UNIQUE(_xlfn._xlws.FILTER(B:B,E:E=E24)))} -> 242, 243 | E24: Manufacture of tubes, pipes, hollow profiles and related fittings, of steel, other products of first processing of steel | F24: {=COUNTA(_xlfn.UNIQUE(_xlfn._xlws.FILTER(L:L,E:E=E24)))} -> 1 | H24: Combine NACE cat | I24: =_xlfn.XLOOKUP(J24,'ETS activities'!B:B,'ETS activities'!A:A) -> 25 | J24: Production or processing of ferrous metals | K24: {=_xlfn.TEXTJOIN(", ",TRUE,_xlfn.UNIQUE(_xlfn._xlws.FILTER(I:I,L:L=L24)))} -> 25 | L24: Production or processing of ferrous metals | M24: {=COUNTA(_xlfn.UNIQUE(_xlfn._xlws.FILTER(E:E,L:L=L24)))} -> 1 | N24: good | O24: ETS activity is broader than selected NACE level-3 categories; sum NACE rows before regression; NACE 245 Casting of metals omitted because SBS level 3 cannot split ferrous and non-ferrous casting without overlap
A25: =_xlfn.XLOOKUP(C25,'NACE Rev. All Levels'!$C:$C,'NACE Rev. All Levels'!A:A) -> 3 | B25: =_xlfn.XLOOKUP(C25,'NACE Rev. All Levels'!$C:$C,'NACE Rev. All Levels'!B:B) -> 243 | C25: Manufacture of other products of first processing of steel | D25: {=_xlfn.TEXTJOIN(", ",TRUE,_xlfn.UNIQUE(_xlfn._xlws.FILTER(B:B,E:E=E25)))} -> 242, 243 | E25: Manufacture of tubes, pipes, hollow profiles and related fittings, of steel, other products of first processing of steel | F25: {=COUNTA(_xlfn.UNIQUE(_xlfn._xlws.FILTER(L:L,E:E=E25)))} -> 1 | H25: Combine NACE cat | I25: =_xlfn.XLOOKUP(J25,'ETS activities'!B:B,'ETS activities'!A:A) -> 25 | J25: Production or processing of ferrous metals | K25: {=_xlfn.TEXTJOIN(", ",TRUE,_xlfn.UNIQUE(_xlfn._xlws.FILTER(I:I,L:L=L25)))} -> 25 | L25: Production or processing of ferrous metals | M25: {=COUNTA(_xlfn.UNIQUE(_xlfn._xlws.FILTER(E:E,L:L=L25)))} -> 1 | N25: good | O25: ETS activity is broader than selected NACE level-3 categories; sum NACE rows before regression; NACE 245 Casting of metals omitted because SBS level 3 cannot split ferrous and non-ferrous casting without overlap
A26: =_xlfn.XLOOKUP(C26,'NACE Rev. All Levels'!$C:$C,'NACE Rev. All Levels'!A:A) -> 3 | B26: =_xlfn.XLOOKUP(C26,'NACE Rev. All Levels'!$C:$C,'NACE Rev. All Levels'!B:B) -> 244 | C26: Manufacture of basic precious and other non-ferrous metals | D26: {=_xlfn.TEXTJOIN(", ",TRUE,_xlfn.UNIQUE(_xlfn._xlws.FILTER(B:B,E:E=E26)))} -> 244 | E26: Manufacture of basic precious and other non-ferrous metals | F26: {=COUNTA(_xlfn.UNIQUE(_xlfn._xlws.FILTER(L:L,E:E=E26)))} -> 1 | G26: Production of primary aluminium, secondary aluminium and other non-ferrous metals | H26: Combine ETS activities | I26: =_xlfn.XLOOKUP(J26,'ETS activities'!B:B,'ETS activities'!A:A) -> 28 | J26: Production or processing of non-ferrous metals | K26: {=_xlfn.TEXTJOIN(", ",TRUE,_xlfn.UNIQUE(_xlfn._xlws.FILTER(I:I,L:L=L26)))} -> 28, 26, 27 | L26: Production of primary aluminium, secondary aluminium and other non-ferrous metals | M26: {=COUNTA(_xlfn.UNIQUE(_xlfn._xlws.FILTER(E:E,L:L=L26)))} -> 1 | N26: broad combined | O26: Same NACE level-3 code intentionally reused; aggregate ETS rows to this NACE code before regression; NACE 245 Casting of metals omitted because SBS level 3 cannot split ferrous and non-ferrous casting without overlap
A27: =_xlfn.XLOOKUP(C27,'NACE Rev. All Levels'!$C:$C,'NACE Rev. All Levels'!A:A) -> 3 | B27: =_xlfn.XLOOKUP(C27,'NACE Rev. All Levels'!$C:$C,'NACE Rev. All Levels'!B:B) -> 244 | C27: Manufacture of basic precious and other non-ferrous metals | D27: {=_xlfn.TEXTJOIN(", ",TRUE,_xlfn.UNIQUE(_xlfn._xlws.FILTER(B:B,E:E=E27)))} -> 244 | E27: Manufacture of basic precious and other non-ferrous metals | F27: {=COUNTA(_xlfn.UNIQUE(_xlfn._xlws.FILTER(L:L,E:E=E27)))} -> 1 | G27: Production of primary aluminium, secondary aluminium and other non-ferrous metals | H27: Combine ETS activities | I27: =_xlfn.XLOOKUP(J27,'ETS activities'!B:B,'ETS activities'!A:A) -> 26 | J27: Production of primary aluminium | K27: {=_xlfn.TEXTJOIN(", ",TRUE,_xlfn.UNIQUE(_xlfn._xlws.FILTER(I:I,L:L=L27)))} -> 28, 26, 27 | L27: Production of primary aluminium, secondary aluminium and other non-ferrous metals | M27: {=COUNTA(_xlfn.UNIQUE(_xlfn._xlws.FILTER(E:E,L:L=L27)))} -> 1 | N27: broad combined | O27: Same NACE level-3 code intentionally reused; aggregate ETS rows to this NACE code before regression
A28: =_xlfn.XLOOKUP(C28,'NACE Rev. All Levels'!$C:$C,'NACE Rev. All Levels'!A:A) -> 3 | B28: =_xlfn.XLOOKUP(C28,'NACE Rev. All Levels'!$C:$C,'NACE Rev. All Levels'!B:B) -> 244 | C28: Manufacture of basic precious and other non-ferrous metals | D28: {=_xlfn.TEXTJOIN(", ",TRUE,_xlfn.UNIQUE(_xlfn._xlws.FILTER(B:B,E:E=E28)))} -> 244 | E28: Manufacture of basic precious and other non-ferrous metals | F28: {=COUNTA(_xlfn.UNIQUE(_xlfn._xlws.FILTER(L:L,E:E=E28)))} -> 1 | G28: Production of primary aluminium, secondary aluminium and other non-ferrous metals | H28: Combine ETS activities | I28: =_xlfn.XLOOKUP(J28,'ETS activities'!B:B,'ETS activities'!A:A) -> 27 | J28: Production of secondary aluminium | K28: {=_xlfn.TEXTJOIN(", ",TRUE,_xlfn.UNIQUE(_xlfn._xlws.FILTER(I:I,L:L=L28)))} -> 28, 26, 27 | L28: Production of primary aluminium, secondary aluminium and other non-ferrous metals | M28: {=COUNTA(_xlfn.UNIQUE(_xlfn._xlws.FILTER(E:E,L:L=L28)))} -> 1 | N28: broad combined | O28: Same NACE level-3 code intentionally reused; aggregate ETS rows to this NACE code before regression
A29: =_xlfn.XLOOKUP(C29,'NACE Rev. All Levels'!$C:$C,'NACE Rev. All Levels'!A:A) -> 2 | B29: =_xlfn.XLOOKUP(C29,'NACE Rev. All Levels'!$C:$C,'NACE Rev. All Levels'!B:B) -> 35 | C29: Electricity, gas, steam and air conditioning supply | D29: {=_xlfn.TEXTJOIN(", ",TRUE,_xlfn.UNIQUE(_xlfn._xlws.FILTER(B:B,E:E=E29)))} -> 35 | E29: Electricity, gas, steam and air conditioning supply | F29: {=COUNTA(_xlfn.UNIQUE(_xlfn._xlws.FILTER(L:L,E:E=E29)))} -> 1 | H29: None | I29: =_xlfn.XLOOKUP(J29,'ETS activities'!B:B,'ETS activities'!A:A) -> 20 | J29: Combustion of fuels | K29: {=_xlfn.TEXTJOIN(", ",TRUE,_xlfn.UNIQUE(_xlfn._xlws.FILTER(I:I,L:L=L29)))} -> 20 | L29: Combustion of fuels | M29: {=COUNTA(_xlfn.UNIQUE(_xlfn._xlws.FILTER(E:E,L:L=L29)))} -> 1 | N29: approximate | O29: Exclusive NACE level-1-3 code; no selected parent/child overlap
A30: =_xlfn.XLOOKUP(C30,'NACE Rev. All Levels'!$C:$C,'NACE Rev. All Levels'!A:A) -> 2 | B30: =_xlfn.XLOOKUP(C30,'NACE Rev. All Levels'!$C:$C,'NACE Rev. All Levels'!B:B) -> 39 | C30: Remediation activities and other waste management services | D30: {=_xlfn.TEXTJOIN(", ",TRUE,_xlfn.UNIQUE(_xlfn._xlws.FILTER(B:B,E:E=E30)))} -> 39 | E30: Remediation activities and other waste management services | F30: {=COUNTA(_xlfn.UNIQUE(_xlfn._xlws.FILTER(L:L,E:E=E30)))} -> 1 | H30: None | I30: =_xlfn.XLOOKUP(J30,'ETS activities'!B:B,'ETS activities'!A:A) -> 45 | J30: Capture of greenhouse gases under Directive 2009/31/EC | K30: {=_xlfn.TEXTJOIN(", ",TRUE,_xlfn.UNIQUE(_xlfn._xlws.FILTER(I:I,L:L=L30)))} -> 45 | L30: Capture of greenhouse gases under Directive 2009/31/EC | M30: {=COUNTA(_xlfn.UNIQUE(_xlfn._xlws.FILTER(E:E,L:L=L30)))} -> 1 | N30: approximate | O30: Exclusive NACE level-1-3 code; no selected parent/child overlap
A31: =_xlfn.XLOOKUP(C31,'NACE Rev. All Levels'!$C:$C,'NACE Rev. All Levels'!A:A) -> 3 | B31: =_xlfn.XLOOKUP(C31,'NACE Rev. All Levels'!$C:$C,'NACE Rev. All Levels'!B:B) -> 501 | C31: Sea and coastal passenger water transport | D31: {=_xlfn.TEXTJOIN(", ",TRUE,_xlfn.UNIQUE(_xlfn._xlws.FILTER(B:B,E:E=E31)))} -> 501, 502 | E31: Sea and coastal passenger water transport, Sea and coastal freight water transport | F31: {=COUNTA(_xlfn.UNIQUE(_xlfn._xlws.FILTER(L:L,E:E=E31)))} -> 1 | H31: Combine NACE cat | I31: =_xlfn.XLOOKUP(J31,'ETS activities'!B:B,'ETS activities'!A:A) -> 50 | J31: Maritime Transport | K31: {=_xlfn.TEXTJOIN(", ",TRUE,_xlfn.UNIQUE(_xlfn._xlws.FILTER(I:I,L:L=L31)))} -> 50 | L31: Maritime Transport | M31: {=COUNTA(_xlfn.UNIQUE(_xlfn._xlws.FILTER(E:E,L:L=L31)))} -> 1 | N31: good | O31: ETS activity is broader than selected NACE level-3 categories; sum NACE rows before regression
A32: =_xlfn.XLOOKUP(C32,'NACE Rev. All Levels'!$C:$C,'NACE Rev. All Levels'!A:A) -> 3 | B32: =_xlfn.XLOOKUP(C32,'NACE Rev. All Levels'!$C:$C,'NACE Rev. All Levels'!B:B) -> 502 | C32: Sea and coastal freight water transport | D32: {=_xlfn.TEXTJOIN(", ",TRUE,_xlfn.UNIQUE(_xlfn._xlws.FILTER(B:B,E:E=E32)))} -> 501, 502 | E32: Sea and coastal passenger water transport, Sea and coastal freight water transport | F32: {=COUNTA(_xlfn.UNIQUE(_xlfn._xlws.FILTER(L:L,E:E=E32)))} -> 1 | H32: Combine NACE cat | I32: =_xlfn.XLOOKUP(J32,'ETS activities'!B:B,'ETS activities'!A:A) -> 50 | J32: Maritime Transport | K32: {=_xlfn.TEXTJOIN(", ",TRUE,_xlfn.UNIQUE(_xlfn._xlws.FILTER(I:I,L:L=L32)))} -> 50 | L32: Maritime Transport | M32: {=COUNTA(_xlfn.UNIQUE(_xlfn._xlws.FILTER(E:E,L:L=L32)))} -> 1 | N32: good | O32: ETS activity is broader than selected NACE level-3 categories; sum NACE rows before regression
A33: =_xlfn.XLOOKUP(C33,'NACE Rev. All Levels'!$C:$C,'NACE Rev. All Levels'!A:A) -> 3 | B33: =_xlfn.XLOOKUP(C33,'NACE Rev. All Levels'!$C:$C,'NACE Rev. All Levels'!B:B) -> 511 | C33: Passenger air transport | D33: {=_xlfn.TEXTJOIN(", ",TRUE,_xlfn.UNIQUE(_xlfn._xlws.FILTER(B:B,E:E=E33)))} -> 511, 512 | E33: Passenger air transport, Freight air transport and space transport | F33: {=COUNTA(_xlfn.UNIQUE(_xlfn._xlws.FILTER(L:L,E:E=E33)))} -> 1 | H33: Combine NACE cat | I33: =_xlfn.XLOOKUP(J33,'ETS activities'!B:B,'ETS activities'!A:A) -> 10 | J33: Aviation | K33: {=_xlfn.TEXTJOIN(", ",TRUE,_xlfn.UNIQUE(_xlfn._xlws.FILTER(I:I,L:L=L33)))} -> 10 | L33: Aviation | M33: {=COUNTA(_xlfn.UNIQUE(_xlfn._xlws.FILTER(E:E,L:L=L33)))} -> 1 | N33: good | O33: ETS activity is broader than selected NACE level-3 categories; sum NACE rows before regression
A34: =_xlfn.XLOOKUP(C34,'NACE Rev. All Levels'!$C:$C,'NACE Rev. All Levels'!A:A) -> 3 | B34: =_xlfn.XLOOKUP(C34,'NACE Rev. All Levels'!$C:$C,'NACE Rev. All Levels'!B:B) -> 512 | C34: Freight air transport and space transport | D34: {=_xlfn.TEXTJOIN(", ",TRUE,_xlfn.UNIQUE(_xlfn._xlws.FILTER(B:B,E:E=E34)))} -> 511, 512 | E34: Passenger air transport, Freight air transport and space transport | F34: {=COUNTA(_xlfn.UNIQUE(_xlfn._xlws.FILTER(L:L,E:E=E34)))} -> 1 | H34: Combine NACE cat | I34: =_xlfn.XLOOKUP(J34,'ETS activities'!B:B,'ETS activities'!A:A) -> 10 | J34: Aviation | K34: {=_xlfn.TEXTJOIN(", ",TRUE,_xlfn.UNIQUE(_xlfn._xlws.FILTER(I:I,L:L=L34)))} -> 10 | L34: Aviation | M34: {=COUNTA(_xlfn.UNIQUE(_xlfn._xlws.FILTER(E:E,L:L=L34)))} -> 1 | N34: good | O34: ETS activity is broader than selected NACE level-3 categories; sum NACE rows before regression
F35: {=COUNTA(_xlfn.UNIQUE(_xlfn._xlws.FILTER(L:L,E:E=E35)))} -> 4 | H35: Exclude | I35: =_xlfn.XLOOKUP(J35,'ETS activities'!B:B,'ETS activities'!A:A) -> 20-99 | J35: All stationary installations | K35: {=_xlfn.TEXTJOIN(", ",TRUE,_xlfn.UNIQUE(_xlfn._xlws.FILTER(I:I,L:L=L35)))} -> 20-99 | L35: All stationary installations | M35: {=COUNTA(_xlfn.UNIQUE(_xlfn._xlws.FILTER(E:E,L:L=L35)))} -> 1 | N35: not_mapped | O35: Not used for regression mapping
F36: {=COUNTA(_xlfn.UNIQUE(_xlfn._xlws.FILTER(L:L,E:E=E36)))} -> 4 | H36: Exclude | I36: =_xlfn.XLOOKUP(J36,'ETS activities'!B:B,'ETS activities'!A:A) -> 21-99 | J36: All industrial installations (excl. combustion) | K36: {=_xlfn.TEXTJOIN(", ",TRUE,_xlfn.UNIQUE(_xlfn._xlws.FILTER(I:I,L:L=L36)))} -> 21-99 | L36: All industrial installations (excl. combustion) | M36: {=COUNTA(_xlfn.UNIQUE(_xlfn._xlws.FILTER(E:E,L:L=L36)))} -> 1 | N36: not_mapped | O36: Not used for regression mapping
F37: {=COUNTA(_xlfn.UNIQUE(_xlfn._xlws.FILTER(L:L,E:E=E37)))} -> 4 | H37: Exclude | I37: =_xlfn.XLOOKUP(J37,'ETS activities'!B:B,'ETS activities'!A:A) -> 99 | J37: Other activity opted-in under Art. 24 | K37: {=_xlfn.TEXTJOIN(", ",TRUE,_xlfn.UNIQUE(_xlfn._xlws.FILTER(I:I,L:L=L37)))} -> 99 | L37: Other activity opted-in under Art. 24 | M37: {=COUNTA(_xlfn.UNIQUE(_xlfn._xlws.FILTER(E:E,L:L=L37)))} -> 1 | N37: not_mapped | O37: Not used for regression mapping

Sheet NACE Rev. All Levels
A1: level | B1: ID | C1: name_clean | D1: label_original | E1: parent_code | F1: uri | K1: {=COUNTA(_xlfn.UNIQUE(_xlfn._xlws.FILTER(C:C,A:A=3)))} -> 272
A2: 2 | B2: 01 | C2: =IF(A2=1,RIGHT(D2,LEN(D2)-2),IF(A2=2,RIGHT(D2,LEN(D2)-3),IF(A2=3,RIGHT(D2,LEN(D2)-5),RIGHT(D2,LEN(D2)-6)))) -> Crop and animal production, hunting and related service activities | D2: 01 Crop and animal production, hunting and related service activities | E2: A | F2: http://data.europa.eu/ux2/nace2/01
A3: 3 | B3: 011 | C3: =IF(A3=1,RIGHT(D3,LEN(D3)-2),IF(A3=2,RIGHT(D3,LEN(D3)-3),IF(A3=3,RIGHT(D3,LEN(D3)-5),RIGHT(D3,LEN(D3)-6)))) -> Growing of non-perennial crops | D3: 01.1 Growing of non-perennial crops | E3: 01 | F3: http://data.europa.eu/ux2/nace2/011
A4: 4 | B4: 0111 | C4: =IF(A4=1,RIGHT(D4,LEN(D4)-2),IF(A4=2,RIGHT(D4,LEN(D4)-3),IF(A4=3,RIGHT(D4,LEN(D4)-5),RIGHT(D4,LEN(D4)-6)))) -> Growing of cereals (except rice), leguminous crops and oil seeds | D4: 01.11 Growing of cereals (except rice), leguminous crops and oil seeds | E4: 011 | F4: http://data.europa.eu/ux2/nace2/0111
A5: 4 | B5: 0112 | C5: =IF(A5=1,RIGHT(D5,LEN(D5)-2),IF(A5=2,RIGHT(D5,LEN(D5)-3),IF(A5=3,RIGHT(D5,LEN(D5)-5),RIGHT(D5,LEN(D5)-6)))) -> Growing of rice | D5: 01.12 Growing of rice | E5: 011 | F5: http://data.europa.eu/ux2/nace2/0112
A6: 4 | B6: 0113 | C6: =IF(A6=1,RIGHT(D6,LEN(D6)-2),IF(A6=2,RIGHT(D6,LEN(D6)-3),IF(A6=3,RIGHT(D6,LEN(D6)-5),RIGHT(D6,LEN(D6)-6)))) -> Growing of vegetables and melons, roots and tubers | D6: 01.13 Growing of vegetables and melons, roots and tubers | E6: 011 | F6: http://data.europa.eu/ux2/nace2/0113
A7: 4 | B7: 0114 | C7: =IF(A7=1,RIGHT(D7,LEN(D7)-2),IF(A7=2,RIGHT(D7,LEN(D7)-3),IF(A7=3,RIGHT(D7,LEN(D7)-5),RIGHT(D7,LEN(D7)-6)))) -> Growing of sugar cane | D7: 01.14 Growing of sugar cane | E7: 011 | F7: http://data.europa.eu/ux2/nace2/0114
A8: 4 | B8: 0115 | C8: =IF(A8=1,RIGHT(D8,LEN(D8)-2),IF(A8=2,RIGHT(D8,LEN(D8)-3),IF(A8=3,RIGHT(D8,LEN(D8)-5),RIGHT(D8,LEN(D8)-6)))) -> Growing of tobacco | D8: 01.15 Growing of tobacco | E8: 011 | F8: http://data.europa.eu/ux2/nace2/0115
A9: 4 | B9: 0116 | C9: =IF(A9=1,RIGHT(D9,LEN(D9)-2),IF(A9=2,RIGHT(D9,LEN(D9)-3),IF(A9=3,RIGHT(D9,LEN(D9)-5),RIGHT(D9,LEN(D9)-6)))) -> Growing of fibre crops | D9: 01.16 Growing of fibre crops | E9: 011 | F9: http://data.europa.eu/ux2/nace2/0116
A10: 4 | B10: 0119 | C10: =IF(A10=1,RIGHT(D10,LEN(D10)-2),IF(A10=2,RIGHT(D10,LEN(D10)-3),IF(A10=3,RIGHT(D10,LEN(D10)-5),RIGHT(D10,LEN(D10)-6)))) -> Growing of other non-perennial crops | D10: 01.19 Growing of other non-perennial crops | E10: 011 | F10: http://data.europa.eu/ux2/nace2/0119
A11: 3 | B11: 012 | C11: =IF(A11=1,RIGHT(D11,LEN(D11)-2),IF(A11=2,RIGHT(D11,LEN(D11)-3),IF(A11=3,RIGHT(D11,LEN(D11)-5),RIGHT(D11,LEN(D11)-6)))) -> Growing of perennial crops | D11: 01.2 Growing of perennial crops | E11: 01 | F11: http://data.europa.eu/ux2/nace2/012
A12: 4 | B12: 0121 | C12: =IF(A12=1,RIGHT(D12,LEN(D12)-2),IF(A12=2,RIGHT(D12,LEN(D12)-3),IF(A12=3,RIGHT(D12,LEN(D12)-5),RIGHT(D12,LEN(D12)-6)))) -> Growing of grapes | D12: 01.21 Growing of grapes | E12: 012 | F12: http://data.europa.eu/ux2/nace2/0121
A13: 4 | B13: 0122 | C13: =IF(A13=1,RIGHT(D13,LEN(D13)-2),IF(A13=2,RIGHT(D13,LEN(D13)-3),IF(A13=3,RIGHT(D13,LEN(D13)-5),RIGHT(D13,LEN(D13)-6)))) -> Growing of tropical and subtropical fruits | D13: 01.22 Growing of tropical and subtropical fruits | E13: 012 | F13: http://data.europa.eu/ux2/nace2/0122
... A280: 4 | B280: 2441 | C280: =IF(A280=1,RIGHT(D280,LEN(D280)-2),IF(A280=2,RIGHT(D280,LEN(D280)-3),IF(A280=3,RIGHT(D280,LEN(D280)-5),RIGHT(D280,LEN(D280)-6)))) -> Precious metals production | D280: 24.41 Precious metals production | E280: 244 | F280: http://data.europa.eu/ux2/nace2/2441
A281: 4 | B281: 2442 | C281: Aluminium production | D281: 24.42 Aluminium production | E281: 244 | F281: http://data.europa.eu/ux2/nace2/2442
A282: 4 | B282: 2443 | C282: =IF(A282=1,RIGHT(D282,LEN(D282)-2),IF(A282=2,RIGHT(D282,LEN(D282)-3),IF(A282=3,RIGHT(D282,LEN(D282)-5),RIGHT(D282,LEN(D282)-6)))) -> Lead, zinc and tin production | D282: 24.43 Lead, zinc and tin production | E282: 244 | F282: http://data.europa.eu/ux2/nace2/2443
A283: 4 | B283: 2444 | C283: =IF(A283=1,RIGHT(D283,LEN(D283)-2),IF(A283=2,RIGHT(D283,LEN(D283)-3),IF(A283=3,RIGHT(D283,LEN(D283)-5),RIGHT(D283,LEN(D283)-6)))) -> Copper production | D283: 24.44 Copper production | E283: 244 | F283: http://data.europa.eu/ux2/nace2/2444
A284: 4 | B284: 2445 | C284: =IF(A284=1,RIGHT(D284,LEN(D284)-2),IF(A284=2,RIGHT(D284,LEN(D284)-3),IF(A284=3,RIGHT(D284,LEN(D284)-5),RIGHT(D284,LEN(D284)-6)))) -> Other non-ferrous metal production | D284: 24.45 Other non-ferrous metal production | E284: 244 | F284: http://data.europa.eu/ux2/nace2/2445
A285: 4 | B285: 2446 | C285: =IF(A285=1,RIGHT(D285,LEN(D285)-2),IF(A285=2,RIGHT(D285,LEN(D285)-3),IF(A285=3,RIGHT(D285,LEN(D285)-5),RIGHT(D285,LEN(D285)-6)))) -> Processing of nuclear fuel | D285: 24.46 Processing of nuclear fuel | E285: 244 | F285: http://data.europa.eu/ux2/nace2/2446
A286: 3 | B286: 245 | C286: =IF(A286=1,RIGHT(D286,LEN(D286)-2),IF(A286=2,RIGHT(D286,LEN(D286)-3),IF(A286=3,RIGHT(D286,LEN(D286)-5),RIGHT(D286,LEN(D286)-6)))) -> Casting of metals | D286: 24.5 Casting of metals | E286: 24 | F286: http://data.europa.eu/ux2/nace2/245
A287: 4 | B287: 2451 | C287: =IF(A287=1,RIGHT(D287,LEN(D287)-2),IF(A287=2,RIGHT(D287,LEN(D287)-3),IF(A287=3,RIGHT(D287,LEN(D287)-5),RIGHT(D287,LEN(D287)-6)))) -> Casting of iron | D287: 24.51 Casting of iron | E287: 245 | F287: http://data.europa.eu/ux2/nace2/2451
A288: 4 | B288: 2452 | C288: =IF(A288=1,RIGHT(D288,LEN(D288)-2),IF(A288=2,RIGHT(D288,LEN(D288)-3),IF(A288=3,RIGHT(D288,LEN(D288)-5),RIGHT(D288,LEN(D288)-6)))) -> Casting of steel | D288: 24.52 Casting of steel | E288: 245 | F288: http://data.europa.eu/ux2/nace2/2452
A289: 4 | B289: 2453 | C289: =IF(A289=1,RIGHT(D289,LEN(D289)-2),IF(A289=2,RIGHT(D289,LEN(D289)-3),IF(A289=3,RIGHT(D289,LEN(D289)-5),RIGHT(D289,LEN(D289)-6)))) -> Casting of light metals | D289: 24.53 Casting of light metals | E289: 245 | F289: http://data.europa.eu/ux2/nace2/2453
A290: 4 | B290: 2454 | C290: =IF(A290=1,RIGHT(D290,LEN(D290)-2),IF(A290=2,RIGHT(D290,LEN(D290)-3),IF(A290=3,RIGHT(D290,LEN(D290)-5),RIGHT(D290,LEN(D290)-6)))) -> Casting of other non-ferrous metals | D290: 24.54 Casting of other non-ferrous metals | E290: 245 | F290: http://data.europa.eu/ux2/nace2/2454
A291: 2 | B291: 25 | C291: =IF(A291=1,RIGHT(D291,LEN(D291)-2),IF(A291=2,RIGHT(D291,LEN(D291)-3),IF(A291=3,RIGHT(D291,LEN(D291)-5),RIGHT(D291,LEN(D291)-6)))) -> Manufacture of fabricated metal products, except machinery and equipment | D291: 25 Manufacture of fabricated metal products, except machinery and equipment | E291: C | F291: http://data.europa.eu/ux2/nace2/25
A292: 3 | B292: 251 | C292: =IF(A292=1,RIGHT(D292,LEN(D292)-2),IF(A292=2,RIGHT(D292,LEN(D292)-3),IF(A292=3,RIGHT(D292,LEN(D292)-5),RIGHT(D292,LEN(D292)-6)))) -> Manufacture of structural metal products | D292: 25.1 Manufacture of structural metal products | E292: 25 | F292: http://data.europa.eu/ux2/nace2/251
A293: 4 | B293: 2511 | C293: =IF(A293=1,RIGHT(D293,LEN(D293)-2),IF(A293=2,RIGHT(D293,LEN(D293)-3),IF(A293=3,RIGHT(D293,LEN(D293)-5),RIGHT(D293,LEN(D293)-6)))) -> Manufacture of metal structures and parts of structures | D293: 25.11 Manufacture of metal structures and parts of structures | E293: 251 | F293: http://data.europa.eu/ux2/nace2/2511
... A976: 4 | B976: 9900 | C976: =IF(A976=1,RIGHT(D976,LEN(D976)-2),IF(A976=2,RIGHT(D976,LEN(D976)-3),IF(A976=3,RIGHT(D976,LEN(D976)-5),RIGHT(D976,LEN(D976)-6)))) -> Activities of extraterritorial organisations and bodies | D976: 99.00 Activities of extraterritorial organisations and bodies | E976: 990 | F976: http://data.europa.eu/ux2/nace2/9900
A977: 1 | B977: A | C977: =IF(A977=1,RIGHT(D977,LEN(D977)-2),IF(A977=2,RIGHT(D977,LEN(D977)-3),IF(A977=3,RIGHT(D977,LEN(D977)-5),RIGHT(D977,LEN(D977)-6)))) -> AGRICULTURE, FORESTRY AND FISHING | D977: A AGRICULTURE, FORESTRY AND FISHING | F977: http://data.europa.eu/ux2/nace2/A
A978: 1 | B978: B | C978: =IF(A978=1,RIGHT(D978,LEN(D978)-2),IF(A978=2,RIGHT(D978,LEN(D978)-3),IF(A978=3,RIGHT(D978,LEN(D978)-5),RIGHT(D978,LEN(D978)-6)))) -> MINING AND QUARRYING | D978: B MINING AND QUARRYING | F978: http://data.europa.eu/ux2/nace2/B
A979: 1 | B979: C | C979: =IF(A979=1,RIGHT(D979,LEN(D979)-2),IF(A979=2,RIGHT(D979,LEN(D979)-3),IF(A979=3,RIGHT(D979,LEN(D979)-5),RIGHT(D979,LEN(D979)-6)))) -> MANUFACTURING | D979: C MANUFACTURING | F979: http://data.europa.eu/ux2/nace2/C
A980: 1 | B980: D | C980: =IF(A980=1,RIGHT(D980,LEN(D980)-2),IF(A980=2,RIGHT(D980,LEN(D980)-3),IF(A980=3,RIGHT(D980,LEN(D980)-5),RIGHT(D980,LEN(D980)-6)))) -> ELECTRICITY, GAS, STEAM AND AIR CONDITIONING SUPPLY | D980: D ELECTRICITY, GAS, STEAM AND AIR CONDITIONING SUPPLY | F980: http://data.europa.eu/ux2/nace2/D
A981: 1 | B981: E | C981: =IF(A981=1,RIGHT(D981,LEN(D981)-2),IF(A981=2,RIGHT(D981,LEN(D981)-3),IF(A981=3,RIGHT(D981,LEN(D981)-5),RIGHT(D981,LEN(D981)-6)))) -> WATER SUPPLY; SEWERAGE, WASTE MANAGEMENT AND REMEDIATION ACTIVITIES | D981: E WATER SUPPLY; SEWERAGE, WASTE MANAGEMENT AND REMEDIATION ACTIVITIES | F981: http://data.europa.eu/ux2/nace2/E
A982: 1 | B982: F | C982: =IF(A982=1,RIGHT(D982,LEN(D982)-2),IF(A982=2,RIGHT(D982,LEN(D982)-3),IF(A982=3,RIGHT(D982,LEN(D982)-5),RIGHT(D982,LEN(D982)-6)))) -> CONSTRUCTION | D982: F CONSTRUCTION | F982: http://data.europa.eu/ux2/nace2/F
A983: 1 | B983: G | C983: =IF(A983=1,RIGHT(D983,LEN(D983)-2),IF(A983=2,RIGHT(D983,LEN(D983)-3),IF(A983=3,RIGHT(D983,LEN(D983)-5),RIGHT(D983,LEN(D983)-6)))) -> WHOLESALE AND RETAIL TRADE; REPAIR OF MOTOR VEHICLES AND MOTORCYCLES | D983: G WHOLESALE AND RETAIL TRADE; REPAIR OF MOTOR VEHICLES AND MOTORCYCLES | F983: http://data.europa.eu/ux2/nace2/G
A984: 1 | B984: H | C984: =IF(A984=1,RIGHT(D984,LEN(D984)-2),IF(A984=2,RIGHT(D984,LEN(D984)-3),IF(A984=3,RIGHT(D984,LEN(D984)-5),RIGHT(D984,LEN(D984)-6)))) -> TRANSPORTATION AND STORAGE | D984: H TRANSPORTATION AND STORAGE | F984: http://data.europa.eu/ux2/nace2/H
A985: 1 | B985: I | C985: =IF(A985=1,RIGHT(D985,LEN(D985)-2),IF(A985=2,RIGHT(D985,LEN(D985)-3),IF(A985=3,RIGHT(D985,LEN(D985)-5),RIGHT(D985,LEN(D985)-6)))) -> ACCOMMODATION AND FOOD SERVICE ACTIVITIES | D985: I ACCOMMODATION AND FOOD SERVICE ACTIVITIES | F985: http://data.europa.eu/ux2/nace2/I
A986: 1 | B986: J | C986: =IF(A986=1,RIGHT(D986,LEN(D986)-2),IF(A986=2,RIGHT(D986,LEN(D986)-3),IF(A986=3,RIGHT(D986,LEN(D986)-5),RIGHT(D986,LEN(D986)-6)))) -> INFORMATION AND COMMUNICATION | D986: J INFORMATION AND COMMUNICATION | F986: http://data.europa.eu/ux2/nace2/J
A987: 1 | B987: K | C987: =IF(A987=1,RIGHT(D987,LEN(D987)-2),IF(A987=2,RIGHT(D987,LEN(D987)-3),IF(A987=3,RIGHT(D987,LEN(D987)-5),RIGHT(D987,LEN(D987)-6)))) -> FINANCIAL AND INSURANCE ACTIVITIES | D987: K FINANCIAL AND INSURANCE ACTIVITIES | F987: http://data.europa.eu/ux2/nace2/K
A988: 1 | B988: L | C988: =IF(A988=1,RIGHT(D988,LEN(D988)-2),IF(A988=2,RIGHT(D988,LEN(D988)-3),IF(A988=3,RIGHT(D988,LEN(D988)-5),RIGHT(D988,LEN(D988)-6)))) -> REAL ESTATE ACTIVITIES | D988: L REAL ESTATE ACTIVITIES | F988: http://data.europa.eu/ux2/nace2/L
...

Sheet ETS activities
A1: ets_activity_code | B1: ets_activity_name | C1: mapped
A2: 10 | B2: Aviation | C2: =_xlfn.IFNA(IF(_xlfn.XLOOKUP(A2,#REF!,#REF!)<>"",1,0),0) -> #REF!
A3: 20 | B3: Combustion of fuels | C3: =_xlfn.IFNA(IF(_xlfn.XLOOKUP(A3,#REF!,#REF!)<>"",1,0),0) -> #REF!
A4: 20-99 | B4: All stationary installations | C4: =_xlfn.IFNA(IF(_xlfn.XLOOKUP(A4,#REF!,#REF!)<>"",1,0),0) -> #REF!
A5: 21 | B5: Refining of mineral oil | C5: =_xlfn.IFNA(IF(_xlfn.XLOOKUP(A5,#REF!,#REF!)<>"",1,0),0) -> #REF!
A6: 21-99 | B6: All industrial installations (excl. combustion) | C6: =_xlfn.IFNA(IF(_xlfn.XLOOKUP(A6,#REF!,#REF!)<>"",1,0),0) -> #REF!
A7: 22 | B7: Production of coke | C7: =_xlfn.IFNA(IF(_xlfn.XLOOKUP(A7,#REF!,#REF!)<>"",1,0),0) -> #REF!
A8: 23 | B8: Metal ore roasting or sintering | C8: =_xlfn.IFNA(IF(_xlfn.XLOOKUP(A8,#REF!,#REF!)<>"",1,0),0) -> #REF!
A9: 24 | B9: Production of pig iron or steel | C9: =_xlfn.IFNA(IF(_xlfn.XLOOKUP(A9,#REF!,#REF!)<>"",1,0),0) -> #REF!
A10: 25 | B10: Production or processing of ferrous metals | C10: =_xlfn.IFNA(IF(_xlfn.XLOOKUP(A10,#REF!,#REF!)<>"",1,0),0) -> #REF!
A11: 26 | B11: Production of primary aluminium | C11: =_xlfn.IFNA(IF(_xlfn.XLOOKUP(A11,#REF!,#REF!)<>"",1,0),0) -> #REF!
A12: 27 | B12: Production of secondary aluminium | C12: =_xlfn.IFNA(IF(_xlfn.XLOOKUP(A12,#REF!,#REF!)<>"",1,0),0) -> #REF!
A13: 28 | B13: Production or processing of non-ferrous metals | C13: =_xlfn.IFNA(IF(_xlfn.XLOOKUP(A13,#REF!,#REF!)<>"",1,0),0) -> #REF!
... A32: 99 | B32: Other activity opted-in under Art. 24 | C32: =_xlfn.IFNA(IF(_xlfn.XLOOKUP(A32,#REF!,#REF!)<>"",1,0),0) -> #REF!

Sheet NACE Rev. 2 Level 3
A1: ID | B1: Label | C1: is_ets_activity | D1: Original
A2: =LEFT(D2,4) -> 01.1 | B2: =SUBSTITUTE(SUBSTITUTE(D2,A2&" ",""),RIGHT(D2,5),"") -> Growing of non-perennial crops | C2: =ISNUMBER(MATCH(A2, #REF!, 0)) -> FALSE | D2: 01.1 Growing of non-perennial crops (en)
A3: =LEFT(D3,4) -> 01.2 | B3: =SUBSTITUTE(SUBSTITUTE(D3,A3&" ",""),RIGHT(D3,5),"") -> Growing of perennial crops | C3: =ISNUMBER(MATCH(A3, #REF!, 0)) -> FALSE | D3: 01.2 Growing of perennial crops (en)
A4: =LEFT(D4,4) -> 01.3 | B4: =SUBSTITUTE(SUBSTITUTE(D4,A4&" ",""),RIGHT(D4,5),"") -> Plant propagation | C4: =ISNUMBER(MATCH(A4, #REF!, 0)) -> FALSE | D4: 01.3 Plant propagation (en)
A5: =LEFT(D5,4) -> 01.4 | B5: =SUBSTITUTE(SUBSTITUTE(D5,A5&" ",""),RIGHT(D5,5),"") -> Animal production | C5: =ISNUMBER(MATCH(A5, #REF!, 0)) -> FALSE | D5: 01.4 Animal production (en)
A6: =LEFT(D6,4) -> 01.5 | B6: =SUBSTITUTE(SUBSTITUTE(D6,A6&" ",""),RIGHT(D6,5),"") -> Mixed farming | C6: =ISNUMBER(MATCH(A6, #REF!, 0)) -> FALSE | D6: 01.5 Mixed farming (en)
A7: =LEFT(D7,4) -> 01.6 | B7: =SUBSTITUTE(SUBSTITUTE(D7,A7&" ",""),RIGHT(D7,5),"") -> Support activities to agriculture and post-harvest crop activities | C7: =ISNUMBER(MATCH(A7, #REF!, 0)) -> FALSE | D7: 01.6 Support activities to agriculture and post-harvest crop activities (en)
A8: =LEFT(D8,4) -> 01.7 | B8: =SUBSTITUTE(SUBSTITUTE(D8,A8&" ",""),RIGHT(D8,5),"") -> Hunting, trapping and related service activities | C8: =ISNUMBER(MATCH(A8, #REF!, 0)) -> FALSE | D8: 01.7 Hunting, trapping and related service activities (en)
A9: =LEFT(D9,4) -> 02.1 | B9: =SUBSTITUTE(SUBSTITUTE(D9,A9&" ",""),RIGHT(D9,5),"") -> Silviculture and other forestry activities | C9: =ISNUMBER(MATCH(A9, #REF!, 0)) -> FALSE | D9: 02.1 Silviculture and other forestry activities (en)
A10: =LEFT(D10,4) -> 02.2 | B10: =SUBSTITUTE(SUBSTITUTE(D10,A10&" ",""),RIGHT(D10,5),"") -> Logging | C10: =ISNUMBER(MATCH(A10, #REF!, 0)) -> FALSE | D10: 02.2 Logging (en)
A11: =LEFT(D11,4) -> 02.3 | B11: =SUBSTITUTE(SUBSTITUTE(D11,A11&" ",""),RIGHT(D11,5),"") -> Gathering of wild growing non-wood products | C11: =ISNUMBER(MATCH(A11, #REF!, 0)) -> FALSE | D11: 02.3 Gathering of wild growing non-wood products (en)
A12: =LEFT(D12,4) -> 02.4 | B12: =SUBSTITUTE(SUBSTITUTE(D12,A12&" ",""),RIGHT(D12,5),"") -> Support services to forestry | C12: =ISNUMBER(MATCH(A12, #REF!, 0)) -> FALSE | D12: 02.4 Support services to forestry (en)
A13: =LEFT(D13,4) -> 03.1 | B13: =SUBSTITUTE(SUBSTITUTE(D13,A13&" ",""),RIGHT(D13,5),"") -> Fishing | C13: =ISNUMBER(MATCH(A13, #REF!, 0)) -> FALSE | D13: 03.1 Fishing (en)
... A273: =LEFT(D273,4) -> 99.0 | B273: =SUBSTITUTE(SUBSTITUTE(D273,A273&" ",""),RIGHT(D273,5),"") -> Activities of extraterritorial organisations and bodies | C273: =ISNUMBER(MATCH(A273, #REF!, 0)) -> FALSE | D273: 99.0 Activities of extraterritorial organisations and bodies (en)
